Workbook

Sheet Ranking
A1: PJA TOUR 2026 — Race to Dunas Ranking
A2: Fórmula por ronda: pts = MAX(0, 25 − toPar) × multiplicador (1.0 standard · 1.5 Grande Final)
A3: Regra 2026: Top-14 melhores rondas no ano. DT conta para todos PJA · Aquapor só os 2 primeiros · GG Main R2+R3 · GF×1.5. Torneios decorridos até 2026-04-28.
E4: 1º Drive Tour Madeira — Palheiro | F4: 1º Drive Tour Tejo — Montado | G4: 1º Drive Tour Norte — Estela | H4: 1º Drive Tour Sul — Laguna | I4: 1º Aquapor — Morgado | J4: 2º Drive Tour Sul — Vila Sol | K4: 2º Drive Tour Madeira — Santo da Serra | L4: Greatgolf Junior Open (Main 3R, Sub 16+) | M4: Greatgolf Junior Open U14 | N4: Greatgolf Junior Open U12 | O4: 3º Drive Tour Norte — Vale Pisão | P4: 3º Drive Tour Madeira — Palheiro | Q4: 2º Aquapor — Quinta do Peru | R4: 1º Drive Tour Açores — Terceira | S4: 3º Drive Tour Tejo — Sto. Estêvão | T4: 3º Drive Tour Sul — Quinta do Vale | U4: 2º Drive Tour Açores — Terceira | V4: 4º Drive Tour Madeira — Porto Santo | W4: 4º Drive Tour Tejo — Lisbon SC | X4: 4º Drive Tour Norte — Ponte de Lima | Y4: PJA Aroeira Masters 2026 | Z4: Top 14 voltas
A5: Pos | B5: Jogador | C5: FedCode | D5: Escalão | E5: dt1_madeira_palheiro | F5: dt1_tejo_montado | G5: dt1_norte_estela | H5: dt1_sul_laguna | I5: aq1_morgado | J5: dt2_sul_vilasol | K5: dt2_madeira_sds | L5: gg_main | M5: gg_u14 | N5: gg_u12 | O5: dt3_norte_valepisao | P5: dt3_madeira_palheiro | Q5: aq2_qtaperu | R5: dt1_acores | S5: dt3_tejo_se | T5: dt3_sul_qvale | U5: dt2_acores | V5: dt4_madeira_porto_santo | W5: dt4_tejo_lisbon | X5: dt4_norte_pdl | Y5: pja_aroeira_masters | Z5: Top 14
A6: =RANK(Z6,$Z$6:$Z$30) | B6: Manuel Goulartt Medeiros | C6: 52884 | D6: Sub 12 | E6: ='dt1_madeira_palheiro'!AB15 | F6: 0 | G6: 0 | H6: 0 | I6: 0 | J6: 0 | K6: ='dt2_madeira_sds'!AB24 | L6: 0 | M6: 0 | N6: ='gg_u12'!AX16 | O6: 0 | P6: ='dt3_madeira_palheiro'!AB13 | Q6: 0 | R6: 0 | S6: 0 | T6: 0 | U6: 0 | V6: ='dt4_madeira_porto_santo'!AB16 | W6: 0 | X6: 0 | Y6: ='pja_aroeira_masters'!AX32 | Z6: =IFERROR(LARGE(AA6:AH6,1),0)+IFERROR(LARGE(AA6:AH6,2),0)+IFERROR(LARGE(AA6:AH6,3),0)+IFERROR(LARGE(AA6:AH6,4),0)+IFERROR(LARGE(AA6:AH6,5),0)+IFERROR(LARGE(AA6:AH6,6),0)+IFERROR(LARGE(AA6:AH6,7),0)+IFERROR(LARGE(AA6:AH6,8),0)+IFERROR(LARGE(AA6:AH6,9),0)+IFERROR(LARGE(AA6:AH6,10),0)+IFERROR(LARGE(AA6:AH6,11),0)+IFERROR(LARGE(AA6:AH6,12),0)+IFERROR(LARGE(AA6:AH6,13),0)+IFERROR(LARGE(AA6:AH6,14),0) | AA6: ='dt1_madeira_palheiro'!AA15 | AB6: ='dt2_madeira_sds'!AA24 | AC6: ='gg_u12'!AA16 | AD6: ='gg_u12'!AW16 | AE6: ='dt3_madeira_palheiro'!AA13 | AF6: ='dt4_madeira_porto_santo'!AA16 | AG6: ='pja_aroeira_masters'!AA32 | AH6: ='pja_aroeira_masters'!AW32
A7: =RANK(Z7,$Z$6:$Z$30) | B7: Ricardo Castro Ferreira | C7: 49085 | D7: Sub 12 | E7: 0 | F7: ='dt1_tejo_montado'!AB14 | G7: 0 | H7: 0 | I7: 0 | J7: 0 | K7: 0 | L7: 0 | M7: 0 | N7: ='gg_u12'!AX13 | O7: 0 | P7: 0 | Q7: 0 | R7: 0 | S7: ='dt3_tejo_se'!AX16 | T7: 0 | U7: 0 | V7: 0 | W7: ='dt4_tejo_lisbon'!AB19 | X7: 0 | Y7: ='pja_aroeira_masters'!AX16 | Z7: =IFERROR(LARGE(AA7:AH7,1),0)+IFERROR(LARGE(AA7:AH7,2),0)+IFERROR(LARGE(AA7:AH7,3),0)+IFERROR(LARGE(AA7:AH7,4),0)+IFERROR(LARGE(AA7:AH7,5),0)+IFERROR(LARGE(AA7:AH7,6),0)+IFERROR(LARGE(AA7:AH7,7),0)+IFERROR(LARGE(AA7:AH7,8),0)+IFERROR(LARGE(AA7:AH7,9),0)+IFERROR(LARGE(AA7:AH7,10),0)+IFERROR(LARGE(AA7:AH7,11),0)+IFERROR(LARGE(AA7:AH7,12),0)+IFERROR(LARGE(AA7:AH7,13),0)+IFERROR(LARGE(AA7:AH7,14),0) | AA7: ='dt1_tejo_montado'!AA14 | AB7: ='gg_u12'!AA13 | AC7: ='gg_u12'!AW13 | AD7: ='dt3_tejo_se'!AA16 | AE7: ='dt3_tejo_se'!AW16 | AF7: ='dt4_tejo_lisbon'!AA19 | AG7: ='pja_aroeira_masters'!AA16 | AH7: ='pja_aroeira_masters'!AW16
A8: =RANK(Z8,$Z$6:$Z$30) | B8: Nuno Palmares Jr. | C8: 49124 | D8: Sub 14 | E8: 0 | F8: ='dt1_tejo_montado'!AB15 | G8: 0 | H8: 0 | I8: 0 | J8: 0 | K8: 0 | L8: 0 | M8: ='gg_u14'!AX13 | N8: 0 | O8: 0 | P8: 0 | Q8: =IF((E8+F8+G8+H8+J8+K8+O8+P8+R8+S8+T8+U8+V8+W8+X8)>0,0,'aq2_qtaperu'!AX30) | R8: 0 | S8: ='dt3_tejo_se'!AX14 | T8: 0 | U8: 0 | V8: 0 | W8: ='dt4_tejo_lisbon'!AB13 | X8: 0 | Y8: ='pja_aroeira_masters'!AX13 | Z8: =IFERROR(LARGE(AA8:AJ8,1),0)+IFERROR(LARGE(AA8:AJ8,2),0)+IFERROR(LARGE(AA8:AJ8,3),0)+IFERROR(LARGE(AA8:AJ8,4),0)+IFERROR(LARGE(AA8:AJ8,5),0)+IFERROR(LARGE(AA8:AJ8,6),0)+IFERROR(LARGE(AA8:AJ8,7),0)+IFERROR(LARGE(AA8:AJ8,8),0)+IFERROR(LARGE(AA8:AJ8,9),0)+IFERROR(LARGE(AA8:AJ8,10),0)+IFERROR(LARGE(AA8:AJ8,11),0)+IFERROR(LARGE(AA8:AJ8,12),0)+IFERROR(LARGE(AA8:AJ8,13),0)+IFERROR(LARGE(AA8:AJ8,14),0) | AA8: ='dt1_tejo_montado'!AA15 | AB8: ='gg_u14'!AA13 | AC8: ='gg_u14'!AW13 | AD8: =IF((E8+F8+G8+H8+J8+K8+O8+P8+R8+S8+T8+U8+V8+W8+X8)>0,0,'aq2_qtaperu'!AA30) | AE8: =IF((E8+F8+G8+H8+J8+K8+O8+P8+R8+S8+T8+U8+V8+W8+X8)>0,0,'aq2_qtaperu'!AW30) | AF8: ='dt3_tejo_se'!AA14 | AG8: ='dt3_tejo_se'!AW14 | AH8: ='dt4_tejo_lisbon'!AA13 | AI8: ='pja_aroeira_masters'!AA13 | AJ8: ='pja_aroeira_masters'!AW13
A9: =RANK(Z9,$Z$6:$Z$30) | B9: João Rocha | C9: 48297 | D9: Sub 14 | E9: 0 | F9: ='dt1_tejo_montado'!AB17 | G9: 0 | H9: 0 | I9: =IF((E9+F9+G9+H9+J9+K9+O9+P9+R9+S9+T9+U9+V9+W9+X9)>0,0,'aq1_morgado'!AX57) | J9: 0 | K9: 0 | L9: 0 | M9: ='gg_u14'!AX14 | N9: 0 | O9: 0 | P9: 0 | Q9: =IF((E9+F9+G9+H9+J9+K9+O9+P9+R9+S9+T9+U9+V9+W9+X9)>0,0,'aq2_qtaperu'!AX82) | R9: 0 | S9: ='dt3_tejo_se'!AX15 | T9: 0 | U9: 0 | V9: 0 | W9: 0 | X9: 0 | Y9: ='pja_aroeira_masters'!AX25 | Z9: =IFERROR(LARGE(AA9:AK9,1),0)+IFERROR(LARGE(AA9:AK9,2),0)+IFERROR(LARGE(AA9:AK9,3),0)+IFERROR(LARGE(AA9:AK9,4),0)+IFERROR(LARGE(AA9:AK9,5),0)+IFERROR(LARGE(AA9:AK9,6),0)+IFERROR(LARGE(AA9:AK9,7),0)+IFERROR(LARGE(AA9:AK9,8),0)+IFERROR(LARGE(AA9:AK9,9),0)+IFERROR(LARGE(AA9:AK9,10),0)+IFERROR(LARGE(AA9:AK9,11),0)+IFERROR(LARGE(AA9:AK9,12),0)+IFERROR(LARGE(AA9:AK9,13),0)+IFERROR(LARGE(AA9:AK9,14),0) | AA9: ='dt1_tejo_montado'!AA17 | AB9: =IF((E9+F9+G9+H9+J9+K9+O9+P9+R9+S9+T9+U9+V9+W9+X9)>0,0,'aq1_morgado'!AA57) | AC9: =IF((E9+F9+G9+H9+J9+K9+O9+P9+R9+S9+T9+U9+V9+W9+X9)>0,0,'aq1_morgado'!AW57) | AD9: ='gg_u14'!AA14 | AE9: ='gg_u14'!AW14 | AF9: =IF((E9+F9+G9+H9+J9+K9+O9+P9+R9+S9+T9+U9+V9+W9+X9)>0,0,'aq2_qtaperu'!AA82) | AG9: =IF((E9+F9+G9+H9+J9+K9+O9+P9+R9+S9+T9+U9+V9+W9+X9)>0,0,'aq2_qtaperu'!AW82) | AH9: ='dt3_tejo_se'!AA15 | AI9: ='dt3_tejo_se'!AW15 | AJ9: ='pja_aroeira_masters'!AA25 | AK9: ='pja_aroeira_masters'!AW25
A10: =RANK(Z10,$Z$6:$Z$30) | B10: Pedro Costa Alemão | C10: 46706 | D10: Sub 16 | E10: 0 | F10: ='dt1_tejo_montado'!AB18 | G10: 0 | H10: 0 | I10: =IF((E10+F10+G10+H10+J10+K10+O10+P10+R10+S10+T10+U10+V10+W10+X10)>0,0,'aq1_morgado'!AX55) | J10: 0 | K10: 0 | L10: ='gg_main'!BT22 | M10: 0 | N10: 0 | O10: 0 | P10: 0 | Q10: =IF((E10+F10+G10+H10+J10+K10+O10+P10+R10+S10+T10+U10+V10+W10+X10)>0,0,'aq2_qtaperu'!AX48) | R10: 0 | S10: ='dt3_tejo_se'!AX13 | T10: 0 | U10: 0 | V10: 0 | W10: ='dt4_tejo_lisbon'!AB15 | X10: 0 | Y10: ='pja_aroeira_masters'!AX14 | Z10: =IFERROR(LARGE(AA10:AL10,1),0)+IFERROR(LARGE(AA10:AL10,2),0)+IFERROR(LARGE(AA10:AL10,3),0)+IFERROR(LARGE(AA10:AL10,4),0)+IFERROR(LARGE(AA10:AL10,5),0)+IFERROR(LARGE(AA10:AL10,6),0)+IFERROR(LARGE(AA10:AL10,7),0)+IFERROR(LARGE(AA10:AL10,8),0)+IFERROR(LARGE(AA10:AL10,9),0)+IFERROR(LARGE(AA10:AL10,10),0)+IFERROR(LARGE(AA10:AL10,11),0)+IFERROR(LARGE(AA10:AL10,12),0)+IFERROR(LARGE(AA10:AL10,13),0)+IFERROR(LARGE(AA10:AL10,14),0) | AA10: ='dt1_tejo_montado'!AA18 | AB10: =IF((E10+F10+G10+H10+J10+K10+O10+P10+R10+S10+T10+U10+V10+W10+X10)>0,0,'aq1_morgado'!AA55) | AC10: =IF((E10+F10+G10+H10+J10+K10+O10+P10+R10+S10+T10+U10+V10+W10+X10)>0,0,'aq1_morgado'!AW55) | AD10: ='gg_main'!AW22 | AE10: ='gg_main'!BS22 | AF10: =IF((E10+F10+G10+H10+J10+K10+O10+P10+R10+S10+T10+U10+V10+W10+X10)>0,0,'aq2_qtaperu'!AA48) | AG10: =IF((E10+F10+G10+H10+J10+K10+O10+P10+R10+S10+T10+U10+V10+W10+X10)>0,0,'aq2_qtaperu'!AW48) | AH10: ='dt3_tejo_se'!AA13 | AI10: ='dt3_tejo_se'!AW13 | AJ10: ='dt4_tejo_lisbon'!AA15 | AK10: ='pja_aroeira_masters'!AA14 | AL10: ='pja_aroeira_masters'!AW14
A11: =RANK(Z11,$Z$6:$Z$30) | B11: Diogo Sequeira | C11: 56654 | D11: Sub 16 | E11: 0 | F11: ='dt1_tejo_montado'!AB19 | G11: 0 | H11: 0 | I11: =IF((E11+F11+G11+H11+J11+K11+O11+P11+R11+S11+T11+U11+V11+W11+X11)>0,0,'aq1_morgado'!AX62) | J11: 0 | K11: 0 | L11: ='gg_main'!BT34 | M11: 0 | N11: 0 | O11: 0 | P11: 0 | Q11: =IF((E11+F11+G11+H11+J11+K11+O11+P11+R11+S11+T11+U11+V11+W11+X11)>0,0,'aq2_qtaperu'!AX97) | R11: 0 | S11: 0 | T11: 0 | U11: 0 | V11: 0 | W11: ='dt4_tejo_lisbon'!AB41 | X11: 0 | Y11: 0 | Z11: =IFERROR(LARGE(AA11:AH11,1),0)+IFERROR(LARGE(AA11:AH11,2),0)+IFERROR(LARGE(AA11:AH11,3),0)+IFERROR(LARGE(AA11:AH11,4),0)+IFERROR(LARGE(AA11:AH11,5),0)+IFERROR(LARGE(AA11:AH11,6),0)+IFERROR(LARGE(AA11:AH11,7),0)+IFERROR(LARGE(AA11:AH11,8),0)+IFERROR(LARGE(AA11:AH11,9),0)+IFERROR(LARGE(AA11:AH11,10),0)+IFERROR(LARGE(AA11:AH11,11),0)+IFERROR(LARGE(AA11:AH11,12),0)+IFERROR(LARGE(AA11:AH11,13),0)+IFERROR(LARGE(AA11:AH11,14),0) | AA11: ='dt1_tejo_montado'!AA19 | AB11: =IF((E11+F11+G11+H11+J11+K11+O11+P11+R11+S11+T11+U11+V11+W11+X11)>0,0,'aq1_morgado'!AA62) | AC11: =IF((E11+F11+G11+H11+J11+K11+O11+P11+R11+S11+T11+U11+V11+W11+X11)>0,0,'aq1_morgado'!AW62) | AD11: ='gg_main'!AW34 | AE11: ='gg_main'!BS34 | AF11: =IF((E11+F11+G11+H11+J11+K11+O11+P11+R11+S11+T11+U11+V11+W11+X11)>0,0,'aq2_qtaperu'!AA97) | AG11: =IF((E11+F11+G11+H11+J11+K11+O11+P11+R11+S11+T11+U11+V11+W11+X11)>0,0,'aq2_qtaperu'!AW97) | AH11: ='dt4_tejo_lisbon'!AA41
A12: =RANK(Z12,$Z$6:$Z$30) | B12: Angelina Gao | C12: 51523 | D12: Sub 16 | E12: 0 | F12: ='dt1_tejo_montado'!AB20 | G12: 0 | H12: 0 | I12: =IF((E12+F12+G12+H12+J12+K12+O12+P12+R12+S12+T12+U12+V12+W12+X12)>0,0,'aq1_morgado'!AX41) | J12: 0 | K12: 0 | L12: ='gg_main'!BT23 | M12: 0 | N12: 0 | O12: 0 | P12: 0 | Q12: =IF((E12+F12+G12+H12+J12+K12+O12+P12+R12+S12+T12+U12+V12+W12+X12)>0,0,'aq2_qtaperu'!AX54) | R12: 0 | S12: ='dt3_tejo_se'!AX18 | T12: 0 | U12: 0 | V12: 0 | W12: ='dt4_tejo_lisbon'!AB22 | X12: 0 | Y12: ='pja_aroeira_masters'!AX29 | Z12: =IFERROR(LARGE(AA12:AL12,1),0)+IFERROR(LARGE(AA12:AL12,2),0)+IFERROR(LARGE(AA12:AL12,3),0)+IFERROR(LARGE(AA12:AL12,4),0)+IFERROR(LARGE(AA12:AL12,5),0)+IFERROR(LARGE(AA12:AL12,6),0)+IFERROR(LARGE(AA12:AL12,7),0)+IFERROR(LARGE(AA12:AL12,8),0)+IFERROR(LARGE(AA12:AL12,9),0)+IFERROR(LARGE(AA12:AL12,10),0)+IFERROR(LARGE(AA12:AL12,11),0)+IFERROR(LARGE(AA12:AL12,12),0)+IFERROR(LARGE(AA12:AL12,13),0)+IFERROR(LARGE(AA12:AL12,14),0) | AA12: ='dt1_tejo_montado'!AA20 | AB12: =IF((E12+F12+G12+H12+J12+K12+O12+P12+R12+S12+T12+U12+V12+W12+X12)>0,0,'aq1_morgado'!AA41) | AC12: =IF((E12+F12+G12+H12+J12+K12+O12+P12+R12+S12+T12+U12+V12+W12+X12)>0,0,'aq1_morgado'!AW41) | AD12: ='gg_main'!AW23 | AE12: ='gg_main'!BS23 | AF12: =IF((E12+F12+G12+H12+J12+K12+O12+P12+R12+S12+T12+U12+V12+W12+X12)>0,0,'aq2_qtaperu'!AA54) | AG12: =IF((E12+F12+G12+H12+J12+K12+O12+P12+R12+S12+T12+U12+V12+W12+X12)>0,0,'aq2_qtaperu'!AW54) | AH12: ='dt3_tejo_se'!AA18 | AI12: ='dt3_tejo_se'!AW18 | AJ12: ='dt4_tejo_lisbon'!AA22 | AK12: ='pja_aroeira_masters'!AA29 | AL12: ='pja_aroeira_masters'!AW29
A13: =RANK(Z13,$Z$6:$Z$30) | B13: William Gao | C13: 51524 | D13: Sub 14 | E13: 0 | F13: ='dt1_tejo_montado'!AB21 | G13: 0 | H13: 0 | I13: =IF((E13+F13+G13+H13+J13+K13+O13+P13+R13+S13+T13+U13+V13+W13+X13)>0,0,'aq1_morgado'!AX78) | J13: 0 | K13: 0 | L13: 0 | M13: ='gg_u14'!AX18 | N13: 0 | O13: 0 | P13: 0 | Q13: =IF((E13+F13+G13+H13+J13+K13+O13+P13+R13+S13+T13+U13+V13+W13+X13)>0,0,'aq2_qtaperu'!AX93) | R13: 0 | S13: ='dt3_tejo_se'!AX23 | T13: 0 | U13: 0 | V13: 0 | W13: ='dt4_tejo_lisbon'!AB21 | X13: 0 | Y13: ='pja_aroeira_masters'!AX20 | Z13: =IFERROR(LARGE(AA13:AL13,1),0)+IFERROR(LARGE(AA13:AL13,2),0)+IFERROR(LARGE(AA13:AL13,3),0)+IFERROR(LARGE(AA13:AL13,4),0)+IFERROR(LARGE(AA13:AL13,5),0)+IFERROR(LARGE(AA13:AL13,6),0)+IFERROR(LARGE(AA13:AL13,7),0)+IFERROR(LARGE(AA13:AL13,8),0)+IFERROR(LARGE(AA13:AL13,9),0)+IFERROR(LARGE(AA13:AL13,10),0)+IFERROR(LARGE(AA13:AL13,11),0)+IFERROR(LARGE(AA13:AL13,12),0)+IFERROR(LARGE(AA13:AL13,13),0)+IFERROR(LARGE(AA13:AL13,14),0) | AA13: ='dt1_tejo_montado'!AA21 | AB13: =IF((E13+F13+G13+H13+J13+K13+O13+P13+R13+S13+T13+U13+V13+W13+X13)>0,0,'aq1_morgado'!AA78) | AC13: =IF((E13+F13+G13+H13+J13+K13+O13+P13+R13+S13+T13+U13+V13+W13+X13)>0,0,'aq1_morgado'!AW78) | AD13: ='gg_u14'!AA18 | AE13: ='gg_u14'!AW18 | AF13: =IF((E13+F13+G13+H13+J13+K13+O13+P13+R13+S13+T13+U13+V13+W13+X13)>0,0,'aq2_qtaperu'!AA93) | AG13: =IF((E13+F13+G13+H13+J13+K13+O13+P13+R13+S13+T13+U13+V13+W13+X13)>0,0,'aq2_qtaperu'!AW93) | AH13: ='dt3_tejo_se'!AA23 | AI13: ='dt3_tejo_se'!AW23 | AJ13: ='dt4_tejo_lisbon'!AA21 | AK13: ='pja_aroeira_masters'!AA20 | AL13: ='pja_aroeira_masters'!AW20
A14: =RANK(Z14,$Z$6:$Z$30) | B14: Madalena Figueiredo | C14: 52011 | D14: Sub 16 | E14: 0 | F14: ='dt1_tejo_montado'!AB23 | G14: 0 | H14: 0 | I14: =IF((E14+F14+G14+H14+J14+K14+O14+P14+R14+S14+T14+U14+V14+W14+X14)>0,0,'aq1_morgado'!AX83) | J14: 0 | K14: 0 | L14: ='gg_main'!BT36 | M14: 0 | N14: 0 | O14: 0 | P14: 0 | Q14: 0 | R14: 0 | S14: ='dt3_tejo_se'!AX27 | T14: 0 | U14: 0 | V14: 0 | W14: ='dt4_tejo_lisbon'!AB34 | X14: 0 | Y14: ='pja_aroeira_masters'!AX19 | Z14: =IFERROR(LARGE(AA14:AJ14,1),0)+IFERROR(LARGE(AA14:AJ14,2),0)+IFERROR(LARGE(AA14:AJ14,3),0)+IFERROR(LARGE(AA14:AJ14,4),0)+IFERROR(LARGE(AA14:AJ14,5),0)+IFERROR(LARGE(AA14:AJ14,6),0)+IFERROR(LARGE(AA14:AJ14,7),0)+IFERROR(LARGE(AA14:AJ14,8),0)+IFERROR(LARGE(AA14:AJ14,9),0)+IFERROR(LARGE(AA14:AJ14,10),0)+IFERROR(LARGE(AA14:AJ14,11),0)+IFERROR(LARGE(AA14:AJ14,12),0)+IFERROR(LARGE(AA14:AJ14,13),0)+IFERROR(LARGE(AA14:AJ14,14),0) | AA14: ='dt1_tejo_montado'!AA23 | AB14: =IF((E14+F14+G14+H14+J14+K14+O14+P14+R14+S14+T14+U14+V14+W14+X14)>0,0,'aq1_morgado'!AA83) | AC14: =IF((E14+F14+G14+H14+J14+K14+O14+P14+R14+S14+T14+U14+V14+W14+X14)>0,0,'aq1_morgado'!AW83) | AD14: ='gg_main'!AW36 | AE14: ='gg_main'!BS36 | AF14: ='dt3_tejo_se'!AA27 | AG14: ='dt3_tejo_se'!AW27 | AH14: ='dt4_tejo_lisbon'!AA34 | AI14: ='pja_aroeira_masters'!AA19 | AJ14: ='pja_aroeira_masters'!AW19
A15: =RANK(Z15,$Z$6:$Z$30) | B15: Martim Sousa de Morais | C15: 41609 | D15: Sub 23 | E15: 0 | F15: ='dt1_tejo_montado'!AB25 | G15: 0 | H15: 0 | I15: =IF((E15+F15+G15+H15+J15+K15+O15+P15+R15+S15+T15+U15+V15+W15+X15)>0,0,'aq1_morgado'!AX56) | J15: 0 | K15: 0 | L15: 0 | M15: 0 | N15: 0 | O15: 0 | P15: 0 | Q15: =IF((E15+F15+G15+H15+J15+K15+O15+P15+R15+S15+T15+U15+V15+W15+X15)>0,0,'aq2_qtaperu'!AX25) | R15: 0 | S15: ='dt3_tejo_se'!AX21 | T15: 0 | U15: 0 | V15: 0 | W15: 0 | X15: 0 | Y15: 0 | Z15: =IFERROR(LARGE(AA15:AG15,1),0)+IFERROR(LARGE(AA15:AG15,2),0)+IFERROR(LARGE(AA15:AG15,3),0)+IFERROR(LARGE(AA15:AG15,4),0)+IFERROR(LARGE(AA15:AG15,5),0)+IFERROR(LARGE(AA15:AG15,6),0)+IFERROR(LARGE(AA15:AG15,7),0)+IFERROR(LARGE(AA15:AG15,8),0)+IFERROR(LARGE(AA15:AG15,9),0)+IFERROR(LARGE(AA15:AG15,10),0)+IFERROR(LARGE(AA15:AG15,11),0)+IFERROR(LARGE(AA15:AG15,12),0)+IFERROR(LARGE(AA15:AG15,13),0)+IFERROR(LARGE(AA15:AG15,14),0) | AA15: ='dt1_tejo_montado'!AA25 | AB15: =IF((E15+F15+G15+H15+J15+K15+O15+P15+R15+S15+T15+U15+V15+W15+X15)>0,0,'aq1_morgado'!AA56) | AC15: =IF((E15+F15+G15+H15+J15+K15+O15+P15+R15+S15+T15+U15+V15+W15+X15)>0,0,'aq1_morgado'!AW56) | AD15: =IF((E15+F15+G15+H15+J15+K15+O15+P15+R15+S15+T15+U15+V15+W15+X15)>0,0,'aq2_qtaperu'!AA25) | AE15: =IF((E15+F15+G15+H15+J15+K15+O15+P15+R15+S15+T15+U15+V15+W15+X15)>0,0,'aq2_qtaperu'!AW25) | AF15: ='dt3_tejo_se'!AA21 | AG15: ='dt3_tejo_se'!AW21
A16: =RANK(Z16,$Z$6:$Z$30) | B16: Clara Trindade | C16: 45812 | D16: Sub 16 | E16: 0 | F16: ='dt1_tejo_montado'!AB27 | G16: 0 | H16: 0 | I16: =IF((E16+F16+G16+H16+J16+K16+O16+P16+R16+S16+T16+U16+V16+W16+X16)>0,0,'aq1_morgado'!AX87) | J16: 0 | K16: 0 | L16: 0 | M16: 0 | N16: 0 | O16: 0 | P16: 0 | Q16: =IF((E16+F16+G16+H16+J16+K16+O16+P16+R16+S16+T16+U16+V16+W16+X16)>0,0,'aq2_qtaperu'!AX85) | R16: 0 | S16: ='dt3_tejo_se'!AX25 | T16: 0 | U16: 0 | V16: 0 | W16: ='dt4_tejo_lisbon'!AB37 | X16: 0 | Y16: 0 | Z16: =IFERROR(LARGE(AA16:AH16,1),0)+IFERROR(LARGE(AA16:AH16,2),0)+IFERROR(LARGE(AA16:AH16,3),0)+IFERROR(LARGE(AA16:AH16,4),0)+IFERROR(LARGE(AA16:AH16,5),0)+IFERROR(LARGE(AA16:AH16,6),0)+IFERROR(LARGE(AA16:AH16,7),0)+IFERROR(LARGE(AA16:AH16,8),0)+IFERROR(LARGE(AA16:AH16,9),0)+IFERROR(LARGE(AA16:AH16,10),0)+IFERROR(LARGE(AA16:AH16,11),0)+IFERROR(LARGE(AA16:AH16,12),0)+IFERROR(LARGE(AA16:AH16,13),0)+IFERROR(LARGE(AA16:AH16,14),0) | AA16: ='dt1_tejo_montado'!AA27 | AB16: =IF((E16+F16+G16+H16+J16+K16+O16+P16+R16+S16+T16+U16+V16+W16+X16)>0,0,'aq1_morgado'!AA87) | AC16: =IF((E16+F16+G16+H16+J16+K16+O16+P16+R16+S16+T16+U16+V16+W16+X16)>0,0,'aq1_morgado'!AW87) | AD16: =IF((E16+F16+G16+H16+J16+K16+O16+P16+R16+S16+T16+U16+V16+W16+X16)>0,0,'aq2_qtaperu'!AA85) | AE16: =IF((E16+F16+G16+H16+J16+K16+O16+P16+R16+S16+T16+U16+V16+W16+X16)>0,0,'aq2_qtaperu'!AW85) | AF16: ='dt3_tejo_se'!AA25 | AG16: ='dt3_tejo_se'!AW25 | AH16: ='dt4_tejo_lisbon'!AA37
A17: =RANK(Z17,$Z$6:$Z$30) | B17: Rafael Gonçales Benesi | C17: 54774 | D17: Sub 16 | E17: 0 | F17: ='dt1_tejo_montado'!AB29 | G17: 0 | H17: 0 | I17: 0 | J17: 0 | K17: 0 | L17: 0 | M17: 0 | N17: 0 | O17: 0 | P17: 0 | Q17: =IF((E17+F17+G17+H17+J17+K17+O17+P17+R17+S17+T17+U17+V17+W17+X17)>0,0,'aq2_qtaperu'!AX92) | R17: 0 | S17: ='dt3_tejo_se'!AX20 | T17: 0 | U17: 0 | V17: 0 | W17: 0 | X17: 0 | Y17: ='pja_aroeira_masters'!AX26 | Z17: =IFERROR(LARGE(AA17:AG17,1),0)+IFERROR(LARGE(AA17:AG17,2),0)+IFERROR(LARGE(AA17:AG17,3),0)+IFERROR(LARGE(AA17:AG17,4),0)+IFERROR(LARGE(AA17:AG17,5),0)+IFERROR(LARGE(AA17:AG17,6),0)+IFERROR(LARGE(AA17:AG17,7),0)+IFERROR(LARGE(AA17:AG17,8),0)+IFERROR(LARGE(AA17:AG17,9),0)+IFERROR(LARGE(AA17:AG17,10),0)+IFERROR(LARGE(AA17:AG17,11),0)+IFERROR(LARGE(AA17:AG17,12),0)+IFERROR(LARGE(AA17:AG17,13),0)+IFERROR(LARGE(AA17:AG17,14),0) | AA17: ='dt1_tejo_montado'!AA29 | AB17: =IF((E17+F17+G17+H17+J17+K17+O17+P17+R17+S17+T17+U17+V17+W17+X17)>0,0,'aq2_qtaperu'!AA92) | AC17: =IF((E17+F17+G17+H17+J17+K17+O17+P17+R17+S17+T17+U17+V17+W17+X17)>0,0,'aq2_qtaperu'!AW92) | AD17: ='dt3_tejo_se'!AA20 | AE17: ='dt3_tejo_se'!AW20 | AF17: ='pja_aroeira_masters'!AA26 | AG17: ='pja_aroeira_masters'!AW26
A18: =RANK(Z18,$Z$6:$Z$30) | B18: Ryan Dantas | C18: 45439 | D18: Sub 16 | E18: 0 | F18: ='dt1_tejo_montado'!AB37 | G18: 0 | H18: 0 | I18: 0 | J18: 0 | K18: 0 | L18: ='gg_main'!BT27 | M18: 0 | N18: 0 | O18: 0 | P18: 0 | Q18: =IF((E18+F18+G18+H18+J18+K18+O18+P18+R18+S18+T18+U18+V18+W18+X18)>0,0,'aq2_qtaperu'!AX79) | R18: 0 | S18: 0 | T18: 0 | U18: 0 | V18: 0 | W18: 0 | X18: 0 | Y18: ='pja_aroeira_masters'!AX28 | Z18: =IFERROR(LARGE(AA18:AG18,1),0)+IFERROR(LARGE(AA18:AG18,2),0)+IFERROR(LARGE(AA18:AG18,3),0)+IFERROR(LARGE(AA18:AG18,4),0)+IFERROR(LARGE(AA18:AG18,5),0)+IFERROR(LARGE(AA18:AG18,6),0)+IFERROR(LARGE(AA18:AG18,7),0)+IFERROR(LARGE(AA18:AG18,8),0)+IFERROR(LARGE(AA18:AG18,9),0)+IFERROR(LARGE(AA18:AG18,10),0)+IFERROR(LARGE(AA18:AG18,11),0)+IFERROR(LARGE(AA18:AG18,12),0)+IFERROR(LARGE(AA18:AG18,13),0)+IFERROR(LARGE(AA18:AG18,14),0) | AA18: ='dt1_tejo_montado'!AA37 | AB18: ='gg_main'!AW27 | AC18: ='gg_main'!BS27 | AD18: =IF((E18+F18+G18+H18+J18+K18+O18+P18+R18+S18+T18+U18+V18+W18+X18)>0,0,'aq2_qtaperu'!AA79) | AE18: =IF((E18+F18+G18+H18+J18+K18+O18+P18+R18+S18+T18+U18+V18+W18+X18)>0,0,'aq2_qtaperu'!AW79) | AF18: ='pja_aroeira_masters'!AA28 | AG18: ='pja_aroeira_masters'!AW28
A19: =RANK(Z19,$Z$6:$Z$30) | B19: Santiago Dias | C19: 42908 | D19: Sub 14 | E19: 0 | F19: 0 | G19: ='dt1_norte_estela'!AB14 | H19: 0 | I19: =IF((E19+F19+G19+H19+J19+K19+O19+P19+R19+S19+T19+U19+V19+W19+X19)>0,0,'aq1_morgado'!AX48) | J19: 0 | K19: 0 | L19: ='gg_main'!BT18 | M19: 0 | N19: 0 | O19: ='dt3_norte_valepisao'!AX13 | P19: 0 | Q19: =IF((E19+F19+G19+H19+J19+K19+O19+P19+R19+S19+T19+U19+V19+W19+X19)>0,0,'aq2_qtaperu'!AX21) | R19: 0 | S19: 0 | T19: 0 | U19: 0 | V19: 0 | W19: 0 | X19: 0 | Y19: 0 | Z19: =IFERROR(LARGE(AA19:AI19,1),0)+IFERROR(LARGE(AA19:AI19,2),0)+IFERROR(LARGE(AA19:AI19,3),0)+IFERROR(LARGE(AA19:AI19,4),0)+IFERROR(LARGE(AA19:AI19,5),0)+IFERROR(LARGE(AA19:AI19,6),0)+IFERROR(LARGE(AA19:AI19,7),0)+IFERROR(LARGE(AA19:AI19,8),0)+IFERROR(LARGE(AA19:AI19,9),0)+IFERROR(LARGE(AA19:AI19,10),0)+IFERROR(LARGE(AA19:AI19,11),0)+IFERROR(LARGE(AA19:AI19,12),0)+IFERROR(LARGE(AA19:AI19,13),0)+IFERROR(LARGE(AA19:AI19,14),0) | AA19: ='dt1_norte_estela'!AA14 | AB19: =IF((E19+F19+G19+H19+J19+K19+O19+P19+R19+S19+T19+U19+V19+W19+X19)>0,0,'aq1_morgado'!AA48) | AC19: =IF((E19+F19+G19+H19+J19+K19+O19+P19+R19+S19+T19+U19+V19+W19+X19)>0,0,'aq1_morgado'!AW48) | AD19: ='gg_main'!AW18 | AE19: ='gg_main'!BS18 | AF19: ='dt3_norte_valepisao'!AA13 | AG19: ='dt3_norte_valepisao'!AW13 | AH19: =IF((E19+F19+G19+H19+J19+K19+O19+P19+R19+S19+T19+U19+V19+W19+X19)>0,0,'aq2_qtaperu'!AA21) | AI19: =IF((E19+F19+G19+H19+J19+K19+O19+P19+R19+S19+T19+U19+V19+W19+X19)>0,0,'aq2_qtaperu'!AW21)
A20: =RANK(Z20,$Z$6:$Z$30) | B20: Rodrigo Sousa Correia | C20: 44934 | D20: Sub 16 | E20: 0 | F20: 0 | G20: 0 | H20: ='dt1_sul_laguna'!AB13 | I20: =IF((E20+F20+G20+H20+J20+K20+O20+P20+R20+S20+T20+U20+V20+W20+X20)>0,0,'aq1_morgado'!AX30) | J20: 0 | K20: 0 | L20: ='gg_main'!BT24 | M20: 0 | N20: 0 | O20: 0 | P20: 0 | Q20: =IF((E20+F20+G20+H20+J20+K20+O20+P20+R20+S20+T20+U20+V20+W20+X20)>0,0,'aq2_qtaperu'!AX51) | R20: 0 | S20: 0 | T20: ='dt3_sul_qvale'!AB14 | U20: 0 | V20: 0 | W20: 0 | X20: 0 | Y20: ='pja_aroeira_masters'!AX22 | Z20: =IFERROR(LARGE(AA20:AJ20,1),0)+IFERROR(LARGE(AA20:AJ20,2),0)+IFERROR(LARGE(AA20:AJ20,3),0)+IFERROR(LARGE(AA20:AJ20,4),0)+IFERROR(LARGE(AA20:AJ20,5),0)+IFERROR(LARGE(AA20:AJ20,6),0)+IFERROR(LARGE(AA20:AJ20,7),0)+IFERROR(LARGE(AA20:AJ20,8),0)+IFERROR(LARGE(AA20:AJ20,9),0)+IFERROR(LARGE(AA20:AJ20,10),0)+IFERROR(LARGE(AA20:AJ20,11),0)+IFERROR(LARGE(AA20:AJ20,12),0)+IFERROR(LARGE(AA20:AJ20,13),0)+IFERROR(LARGE(AA20:AJ20,14),0) | AA20: ='dt1_sul_laguna'!AA13 | AB20: =IF((E20+F20+G20+H20+J20+K20+O20+P20+R20+S20+T20+U20+V20+W20+X20)>0,0,'aq1_morgado'!AA30) | AC20: =IF((E20+F20+G20+H20+J20+K20+O20+P20+R20+S20+T20+U20+V20+W20+X20)>0,0,'aq1_morgado'!AW30) | AD20: ='gg_main'!AW24 | AE20: ='gg_main'!BS24 | AF20: =IF((E20+F20+G20+H20+J20+K20+O20+P20+R20+S20+T20+U20+V20+W20+X20)>0,0,'aq2_qtaperu'!AA51) | AG20: =IF((E20+F20+G20+H20+J20+K20+O20+P20+R20+S20+T20+U20+V20+W20+X20)>0,0,'aq2_qtaperu'!AW51) | AH20: ='dt3_sul_qvale'!AA14 | AI20: ='pja_aroeira_masters'!AA22 | AJ20: ='pja_aroeira_masters'!AW22
A21: =RANK(Z21,$Z$6:$Z$30) | B21: Sabrina Ribeiro Crisóstomo | C21: 48971 | D21: Sub 12 | E21: 0 | F21: 0 | G21: 0 | H21: ='dt1_sul_laguna'!AB22 | I21: =IF((E21+F21+G21+H21+J21+K21+O21+P21+R21+S21+T21+U21+V21+W21+X21)>0,0,'aq1_morgado'!AX88) | J21: ='dt2_sul_vilasol'!AB26 | K21: 0 | L21: 0 | M21: 0 | N21: 0 | O21: 0 | P21: 0 | Q21: =IF((E21+F21+G21+H21+J21+K21+O21+P21+R21+S21+T21+U21+V21+W21+X21)>0,0,'aq2_qtaperu'!AX57) | R21: 0 | S21: 0 | T21: ='dt3_sul_qvale'!AB20 | U21: 0 | V21: 0 | W21: 0 | X21: 0 | Y21: ='pja_aroeira_masters'!AX27 | Z21: =IFERROR(LARGE(AA21:AI21,1),0)+IFERROR(LARGE(AA21:AI21,2),0)+IFERROR(LARGE(AA21:AI21,3),0)+IFERROR(LARGE(AA21:AI21,4),0)+IFERROR(LARGE(AA21:AI21,5),0)+IFERROR(LARGE(AA21:AI21,6),0)+IFERROR(LARGE(AA21:AI21,7),0)+IFERROR(LARGE(AA21:AI21,8),0)+IFERROR(LARGE(AA21:AI21,9),0)+IFERROR(LARGE(AA21:AI21,10),0)+IFERROR(LARGE(AA21:AI21,11),0)+IFERROR(LARGE(AA21:AI21,12),0)+IFERROR(LARGE(AA21:AI21,13),0)+IFERROR(LARGE(AA21:AI21,14),0) | AA21: ='dt1_sul_laguna'!AA22 | AB21: =IF((E21+F21+G21+H21+J21+K21+O21+P21+R21+S21+T21+U21+V21+W21+X21)>0,0,'aq1_morgado'!AA88) | AC21: =IF((E21+F21+G21+H21+J21+K21+O21+P21+R21+S21+T21+U21+V21+W21+X21)>0,0,'aq1_morgado'!AW88) | AD21: ='dt2_sul_vilasol'!AA26 | AE21: =IF((E21+F21+G21+H21+J21+K21+O21+P21+R21+S21+T21+U21+V21+W21+X21)>0,0,'aq2_qtaperu'!AA57) | AF21: =IF((E21+F21+G21+H21+J21+K21+O21+P21+R21+S21+T21+U21+V21+W21+X21)>0,0,'aq2_qtaperu'!AW57) | AG21: ='dt3_sul_qvale'!AA20 | AH21: ='pja_aroeira_masters'!AA27 | AI21: ='pja_aroeira_masters'!AW27
A22: =RANK(Z22,$Z$6:$Z$30) | B22: Tomás Lima Pinto | C22: 46037 | D22: Sub 14 | E22: 0 | F22: 0 | G22: 0 | H22: ='dt1_sul_laguna'!AB25 | I22: 0 | J22: 0 | K22: 0 | L22: 0 | M22: ='gg_u14'!AX15 | N22: 0 | O22: 0 | P22: 0 | Q22: =IF((E22+F22+G22+H22+J22+K22+O22+P22+R22+S22+T22+U22+V22+W22+X22)>0,0,'aq2_qtaperu'!AX81) | R22: 0 | S22: 0 | T22: 0 | U22: 0 | V22: 0 | W22: 0 | X22: 0 | Y22: ='pja_aroeira_masters'!AX24 | Z22: =IFERROR(LARGE(AA22:AG22,1),0)+IFERROR(LARGE(AA22:AG22,2),0)+IFERROR(LARGE(AA22:AG22,3),0)+IFERROR(LARGE(AA22:AG22,4),0)+IFERROR(LARGE(AA22:AG22,5),0)+IFERROR(LARGE(AA22:AG22,6),0)+IFERROR(LARGE(AA22:AG22,7),0)+IFERROR(LARGE(AA22:AG22,8),0)+IFERROR(LARGE(AA22:AG22,9),0)+IFERROR(LARGE(AA22:AG22,10),0)+IFERROR(LARGE(AA22:AG22,11),0)+IFERROR(LARGE(AA22:AG22,12),0)+IFERROR(LARGE(AA22:AG22,13),0)+IFERROR(LARGE(AA22:AG22,14),0) | AA22: ='dt1_sul_laguna'!AA25 | AB22: ='gg_u14'!AA15 | AC22: ='gg_u14'!AW15 | AD22: =IF((E22+F22+G22+H22+J22+K22+O22+P22+R22+S22+T22+U22+V22+W22+X22)>0,0,'aq2_qtaperu'!AA81) | AE22: =IF((E22+F22+G22+H22+J22+K22+O22+P22+R22+S22+T22+U22+V22+W22+X22)>0,0,'aq2_qtaperu'!AW81) | AF22: ='pja_aroeira_masters'!AA24 | AG22: ='pja_aroeira_masters'!AW24
A23: =RANK(Z23,$Z$6:$Z$30) | B23: Rodrigo Faria Constantino | C23: 45278 | D23: Sub 23 | E23: 0 | F23: 0 | G23: 0 | H23: 0 | I23: =IF((E23+F23+G23+H23+J23+K23+O23+P23+R23+S23+T23+U23+V23+W23+X23)>0,0,'aq1_morgado'!AX21) | J23: 0 | K23: 0 | L23: 0 | M23: 0 | N23: 0 | O23: 0 | P23: 0 | Q23: =IF((E23+F23+G23+H23+J23+K23+O23+P23+R23+S23+T23+U23+V23+W23+X23)>0,0,'aq2_qtaperu'!AX35) | R23: 0 | S23: 0 | T23: 0 | U23: 0 | V23: 0 | W23: 0 | X23: 0 | Y23: ='pja_aroeira_masters'!AX21 | Z23: =IFERROR(LARGE(AA23:AF23,1),0)+IFERROR(LARGE(AA23:AF23,2),0)+IFERROR(LARGE(AA23:AF23,3),0)+IFERROR(LARGE(AA23:AF23,4),0)+IFERROR(LARGE(AA23:AF23,5),0)+IFERROR(LARGE(AA23:AF23,6),0)+IFERROR(LARGE(AA23:AF23,7),0)+IFERROR(LARGE(AA23:AF23,8),0)+IFERROR(LARGE(AA23:AF23,9),0)+IFERROR(LARGE(AA23:AF23,10),0)+IFERROR(LARGE(AA23:AF23,11),0)+IFERROR(LARGE(AA23:AF23,12),0)+IFERROR(LARGE(AA23:AF23,13),0)+IFERROR(LARGE(AA23:AF23,14),0) | AA23: =IF((E23+F23+G23+H23+J23+K23+O23+P23+R23+S23+T23+U23+V23+W23+X23)>0,0,'aq1_morgado'!AA21) | AB23: =IF((E23+F23+G23+H23+J23+K23+O23+P23+R23+S23+T23+U23+V23+W23+X23)>0,0,'aq1_morgado'!AW21) | AC23: =IF((E23+F23+G23+H23+J23+K23+O23+P23+R23+S23+T23+U23+V23+W23+X23)>0,0,'aq2_qtaperu'!AA35) | AD23: =IF((E23+F23+G23+H23+J23+K23+O23+P23+R23+S23+T23+U23+V23+W23+X23)>0,0,'aq2_qtaperu'!AW35) | AE23: ='pja_aroeira_masters'!AA21 | AF23: ='pja_aroeira_masters'!AW21
A24: =RANK(Z24,$Z$6:$Z$30) | B24: João Maria Ivo de Carvalho | C24: 38334 | D24: Sub 23 | E24: 0 | F24: 0 | G24: 0 | H24: 0 | I24: =IF((E24+F24+G24+H24+J24+K24+O24+P24+R24+S24+T24+U24+V24+W24+X24)>0,0,'aq1_morgado'!AX29) | J24: 0 | K24: 0 | L24: ='gg_main'!BT19 | M24: 0 | N24: 0 | O24: 0 | P24: 0 | Q24: 0 | R24: 0 | S24: 0 | T24: 0 | U24: 0 | V24: 0 | W24: ='dt4_tejo_lisbon'!AB14 | X24: 0 | Y24: ='pja_aroeira_masters'!AX18 | Z24: =IFERROR(LARGE(AA24:AG24,1),0)+IFERROR(LARGE(AA24:AG24,2),0)+IFERROR(LARGE(AA24:AG24,3),0)+IFERROR(LARGE(AA24:AG24,4),0)+IFERROR(LARGE(AA24:AG24,5),0)+IFERROR(LARGE(AA24:AG24,6),0)+IFERROR(LARGE(AA24:AG24,7),0)+IFERROR(LARGE(AA24:AG24,8),0)+IFERROR(LARGE(AA24:AG24,9),0)+IFERROR(LARGE(AA24:AG24,10),0)+IFERROR(LARGE(AA24:AG24,11),0)+IFERROR(LARGE(AA24:AG24,12),0)+IFERROR(LARGE(AA24:AG24,13),0)+IFERROR(LARGE(AA24:AG24,14),0) | AA24: =IF((E24+F24+G24+H24+J24+K24+O24+P24+R24+S24+T24+U24+V24+W24+X24)>0,0,'aq1_morgado'!AA29) | AB24: =IF((E24+F24+G24+H24+J24+K24+O24+P24+R24+S24+T24+U24+V24+W24+X24)>0,0,'aq1_morgado'!AW29) | AC24: ='gg_main'!AW19 | AD24: ='gg_main'!BS19 | AE24: ='dt4_tejo_lisbon'!AA14 | AF24: ='pja_aroeira_masters'!AA18 | AG24: ='pja_aroeira_masters'!AW18
A25: =RANK(Z25,$Z$6:$Z$30) | B25: Salvador Ivo de Carvalho | C25: 43968 | D25: Sub 14 | E25: 0 | F25: 0 | G25: 0 | H25: 0 | I25: =IF((E25+F25+G25+H25+J25+K25+O25+P25+R25+S25+T25+U25+V25+W25+X25)>0,0,'aq1_morgado'!AX77) | J25: 0 | K25: 0 | L25: 0 | M25: ='gg_u14'!AX17 | N25: 0 | O25: 0 | P25: 0 | Q25: =IF((E25+F25+G25+H25+J25+K25+O25+P25+R25+S25+T25+U25+V25+W25+X25)>0,0,'aq2_qtaperu'!AX67) | R25: 0 | S25: ='dt3_tejo_se'!AX28 | T25: 0 | U25: 0 | V25: 0 | W25: ='dt4_tejo_lisbon'!AB16 | X25: 0 | Y25: ='pja_aroeira_masters'!AX17 | Z25: =IFERROR(LARGE(AA25:AK25,1),0)+IFERROR(LARGE(AA25:AK25,2),0)+IFERROR(LARGE(AA25:AK25,3),0)+IFERROR(LARGE(AA25:AK25,4),0)+IFERROR(LARGE(AA25:AK25,5),0)+IFERROR(LARGE(AA25:AK25,6),0)+IFERROR(LARGE(AA25:AK25,7),0)+IFERROR(LARGE(AA25:AK25,8),0)+IFERROR(LARGE(AA25:AK25,9),0)+IFERROR(LARGE(AA25:AK25,10),0)+IFERROR(LARGE(AA25:AK25,11),0)+IFERROR(LARGE(AA25:AK25,12),0)+IFERROR(LARGE(AA25:AK25,13),0)+IFERROR(LARGE(AA25:AK25,14),0) | AA25: =IF((E25+F25+G25+H25+J25+K25+O25+P25+R25+S25+T25+U25+V25+W25+X25)>0,0,'aq1_morgado'!AA77) | AB25: =IF((E25+F25+G25+H25+J25+K25+O25+P25+R25+S25+T25+U25+V25+W25+X25)>0,0,'aq1_morgado'!AW77) | AC25: ='gg_u14'!AA17 | AD25: ='gg_u14'!AW17 | AE25: =IF((E25+F25+G25+H25+J25+K25+O25+P25+R25+S25+T25+U25+V25+W25+X25)>0,0,'aq2_qtaperu'!AA67) | AF25: =IF((E25+F25+G25+H25+J25+K25+O25+P25+R25+S25+T25+U25+V25+W25+X25)>0,0,'aq2_qtaperu'!AW67) | AG25: ='dt3_tejo_se'!AA28 | AH25: ='dt3_tejo_se'!AW28 | AI25: ='dt4_tejo_lisbon'!AA16 | AJ25: ='pja_aroeira_masters'!AA17 | AK25: ='pja_aroeira_masters'!AW17
A26: =RANK(Z26,$Z$6:$Z$30) | B26: David Filip Jun. | C26: 51949 | D26: Sub 14 | E26: 0 | F26: 0 | G26: 0 | H26: 0 | I26: 0 | J26: 0 | K26: 0 | L26: 0 | M26: ='gg_u14'!AX25 | N26: 0 | O26: 0 | P26: 0 | Q26: 0 | R26: 0 | S26: ='dt3_tejo_se'!AX24 | T26: 0 | U26: 0 | V26: 0 | W26: ='dt4_tejo_lisbon'!AB17 | X26: 0 | Y26: ='pja_aroeira_masters'!AX31 | Z26: =IFERROR(LARGE(AA26:AG26,1),0)+IFERROR(LARGE(AA26:AG26,2),0)+IFERROR(LARGE(AA26:AG26,3),0)+IFERROR(LARGE(AA26:AG26,4),0)+IFERROR(LARGE(AA26:AG26,5),0)+IFERROR(LARGE(AA26:AG26,6),0)+IFERROR(LARGE(AA26:AG26,7),0)+IFERROR(LARGE(AA26:AG26,8),0)+IFERROR(LARGE(AA26:AG26,9),0)+IFERROR(LARGE(AA26:AG26,10),0)+IFERROR(LARGE(AA26:AG26,11),0)+IFERROR(LARGE(AA26:AG26,12),0)+IFERROR(LARGE(AA26:AG26,13),0)+IFERROR(LARGE(AA26:AG26,14),0) | AA26: ='gg_u14'!AA25 | AB26: ='gg_u14'!AW25 | AC26: ='dt3_tejo_se'!AA24 | AD26: ='dt3_tejo_se'!AW24 | AE26: ='dt4_tejo_lisbon'!AA17 | AF26: ='pja_aroeira_masters'!AA31 | AG26: ='pja_aroeira_masters'!AW31
A27: =RANK(Z27,$Z$6:$Z$30) | B27: Guo Ziyang | C27: 57904 | D27: Sub 12 | E27: 0 | F27: 0 | G27: 0 | H27: 0 | I27: 0 | J27: 0 | K27: 0 | L27: 0 | M27: 0 | N27: ='gg_u12'!AX15 | O27: 0 | P27: 0 | Q27: 0 | R27: 0 | S27: 0 | T27: 0 | U27: 0 | V27: 0 | W27: ='dt4_tejo_lisbon'!AB20 | X27: 0 | Y27: ='pja_aroeira_masters'!AX15 | Z27: =IFERROR(LARGE(AA27:AE27,1),0)+IFERROR(LARGE(AA27:AE27,2),0)+IFERROR(LARGE(AA27:AE27,3),0)+IFERROR(LARGE(AA27:AE27,4),0)+IFERROR(LARGE(AA27:AE27,5),0)+IFERROR(LARGE(AA27:AE27,6),0)+IFERROR(LARGE(AA27:AE27,7),0)+IFERROR(LARGE(AA27:AE27,8),0)+IFERROR(LARGE(AA27:AE27,9),0)+IFERROR(LARGE(AA27:AE27,10),0)+IFERROR(LARGE(AA27:AE27,11),0)+IFERROR(LARGE(AA27:AE27,12),0)+IFERROR(LARGE(AA27:AE27,13),0)+IFERROR(LARGE(AA27:AE27,14),0) | AA27: ='gg_u12'!AA15 | AB27: ='gg_u12'!AW15 | AC27: ='dt4_tejo_lisbon'!AA20 | AD27: ='pja_aroeira_masters'!AA15 | AE27: ='pja_aroeira_masters'!AW15
A28: =RANK(Z28,$Z$6:$Z$30) | B28: Rafaela Pinto | C28: 40390 | D28: Sub 23 | E28: 0 | F28: 0 | G28: 0 | H28: 0 | I28: 0 | J28: 0 | K28: 0 | L28: 0 | M28: 0 | N28: 0 | O28: 0 | P28: 0 | Q28: =IF((E28+F28+G28+H28+J28+K28+O28+P28+R28+S28+T28+U28+V28+W28+X28)>0,0,'aq2_qtaperu'!AX89) | R28: 0 | S28: 0 | T28: 0 | U28: 0 | V28: 0 | W28: 0 | X28: 0 | Y28: 0 | Z28: =IFERROR(LARGE(AA28:AB28,1),0)+IFERROR(LARGE(AA28:AB28,2),0)+IFERROR(LARGE(AA28:AB28,3),0)+IFERROR(LARGE(AA28:AB28,4),0)+IFERROR(LARGE(AA28:AB28,5),0)+IFERROR(LARGE(AA28:AB28,6),0)+IFERROR(LARGE(AA28:AB28,7),0)+IFERROR(LARGE(AA28:AB28,8),0)+IFERROR(LARGE(AA28:AB28,9),0)+IFERROR(LARGE(AA28:AB28,10),0)+IFERROR(LARGE(AA28:AB28,11),0)+IFERROR(LARGE(AA28:AB28,12),0)+IFERROR(LARGE(AA28:AB28,13),0)+IFERROR(LARGE(AA28:AB28,14),0) | AA28: =IF((E28+F28+G28+H28+J28+K28+O28+P28+R28+S28+T28+U28+V28+W28+X28)>0,0,'aq2_qtaperu'!AA89) | AB28: =IF((E28+F28+G28+H28+J28+K28+O28+P28+R28+S28+T28+U28+V28+W28+X28)>0,0,'aq2_qtaperu'!AW89)
A29: =RANK(Z29,$Z$6:$Z$30) | B29: Francisco Vilardell Carvalho | C29: 52856 | D29: Sub 14 | E29: 0 | F29: 0 | G29: 0 | H29: 0 | I29: 0 | J29: 0 | K29: 0 | L29: 0 | M29: 0 | N29: 0 | O29: 0 | P29: 0 | Q29: 0 | R29: 0 | S29: 0 | T29: 0 | U29: 0 | V29: 0 | W29: 0 | X29: 0 | Y29: ='pja_aroeira_masters'!AX30 | Z29: =IFERROR(LARGE(AA29:AB29,1),0)+IFERROR(LARGE(AA29:AB29,2),0)+IFERROR(LARGE(AA29:AB29,3),0)+IFERROR(LARGE(AA29:AB29,4),0)+IFERROR(LARGE(AA29:AB29,5),0)+IFERROR(LARGE(AA29:AB29,6),0)+IFERROR(LARGE(AA29:AB29,7),0)+IFERROR(LARGE(AA29:AB29,8),0)+IFERROR(LARGE(AA29:AB29,9),0)+IFERROR(LARGE(AA29:AB29,10),0)+IFERROR(LARGE(AA29:AB29,11),0)+IFERROR(LARGE(AA29:AB29,12),0)+IFERROR(LARGE(AA29:AB29,13),0)+IFERROR(LARGE(AA29:AB29,14),0) | AA29: ='pja_aroeira_masters'!AA30 | AB29: ='pja_aroeira_masters'!AW30
A30: =RANK(Z30,$Z$6:$Z$30) | B30: Martim Moreira | C30: 42985 | D30: Sub 14 | E30: 0 | F30: 0 | G30: 0 | H30: 0 | I30: 0 | J30: 0 | K30: 0 | L30: 0 | M30: 0 | N30: 0 | O30: 0 | P30: 0 | Q30: 0 | R30: 0 | S30: 0 | T30: 0 | U30: 0 | V30: 0 | W30: 0 | X30: 0 | Y30: ='pja_aroeira_masters'!AX33 | Z30: =IFERROR(LARGE(AA30:AB30,1),0)+IFERROR(LARGE(AA30:AB30,2),0)+IFERROR(LARGE(AA30:AB30,3),0)+IFERROR(LARGE(AA30:AB30,4),0)+IFERROR(LARGE(AA30:AB30,5),0)+IFERROR(LARGE(AA30:AB30,6),0)+IFERROR(LARGE(AA30:AB30,7),0)+IFERROR(LARGE(AA30:AB30,8),0)+IFERROR(LARGE(AA30:AB30,9),0)+IFERROR(LARGE(AA30:AB30,10),0)+IFERROR(LARGE(AA30:AB30,11),0)+IFERROR(LARGE(AA30:AB30,12),0)+IFERROR(LARGE(AA30:AB30,13),0)+IFERROR(LARGE(AA30:AB30,14),0) | AA30: ='pja_aroeira_masters'!AA33 | AB30: ='pja_aroeira_masters'!AW33

Sheet Sub 12
A1: PJA TOUR 2026 — Ranking Sub 12
A2: Sub-ranking automático filtrado por escalão Sub 12. Totais referenciados directamente do Ranking principal — actualizam dinamicamente.
A4: Pos | B4: Jogador | C4: FedCode | D4: Escalão | E4: TOTAL
A5: =RANK(E5,$E$5:$E$8) | B5: Ricardo Castro Ferreira | C5: 49085 | D5: Sub 12 | E5: =IFERROR(VLOOKUP("49085",Ranking!$C:$Z,24,FALSE),0)
A6: =RANK(E6,$E$5:$E$8) | B6: Manuel Goulartt Medeiros | C6: 52884 | D6: Sub 12 | E6: =IFERROR(VLOOKUP("52884",Ranking!$C:$Z,24,FALSE),0)
A7: =RANK(E7,$E$5:$E$8) | B7: Guo Ziyang | C7: 57904 | D7: Sub 12 | E7: =IFERROR(VLOOKUP("57904",Ranking!$C:$Z,24,FALSE),0)
A8: =RANK(E8,$E$5:$E$8) | B8: Sabrina Ribeiro Crisóstomo | C8: 48971 | D8: Sub 12 | E8: =IFERROR(VLOOKUP("48971",Ranking!$C:$Z,24,FALSE),0)

Sheet Sub 14
A1: PJA TOUR 2026 — Ranking Sub 14
A2: Sub-ranking automático filtrado por escalão Sub 14. Totais referenciados directamente do Ranking principal — actualizam dinamicamente.
A4: Pos | B4: Jogador | C4: FedCode | D4: Escalão | E4: TOTAL
A5: =RANK(E5,$E$5:$E$13) | B5: Nuno Palmares Jr. | C5: 49124 | D5: Sub 14 | E5: =IFERROR(VLOOKUP("49124",Ranking!$C:$Z,24,FALSE),0)
A6: =RANK(E6,$E$5:$E$13) | B6: João Rocha | C6: 48297 | D6: Sub 14 | E6: =IFERROR(VLOOKUP("48297",Ranking!$C:$Z,24,FALSE),0)
A7: =RANK(E7,$E$5:$E$13) | B7: Santiago Dias | C7: 42908 | D7: Sub 14 | E7: =IFERROR(VLOOKUP("42908",Ranking!$C:$Z,24,FALSE),0)
A8: =RANK(E8,$E$5:$E$13) | B8: William Gao | C8: 51524 | D8: Sub 14 | E8: =IFERROR(VLOOKUP("51524",Ranking!$C:$Z,24,FALSE),0)
A9: =RANK(E9,$E$5:$E$13) | B9: Salvador Ivo de Carvalho | C9: 43968 | D9: Sub 14 | E9: =IFERROR(VLOOKUP("43968",Ranking!$C:$Z,24,FALSE),0)
A10: =RANK(E10,$E$5:$E$13) | B10: David Filip Jun. | C10: 51949 | D10: Sub 14 | E10: =IFERROR(VLOOKUP("51949",Ranking!$C:$Z,24,FALSE),0)
A11: =RANK(E11,$E$5:$E$13) | B11: Tomás Lima Pinto | C11: 46037 | D11: Sub 14 | E11: =IFERROR(VLOOKUP("46037",Ranking!$C:$Z,24,FALSE),0)
A12: =RANK(E12,$E$5:$E$13) | B12: Francisco Vilardell Carvalho | C12: 52856 | D12: Sub 14 | E12: =IFERROR(VLOOKUP("52856",Ranking!$C:$Z,24,FALSE),0)
A13: =RANK(E13,$E$5:$E$13) | B13: Martim Moreira | C13: 42985 | D13: Sub 14 | E13: =IFERROR(VLOOKUP("42985",Ranking!$C:$Z,24,FALSE),0)

Sheet Sub 16
A1: PJA TOUR 2026 — Ranking Sub 16
A2: Sub-ranking automático filtrado por escalão Sub 16. Totais referenciados directamente do Ranking principal — actualizam dinamicamente.
A4: Pos | B4: Jogador | C4: FedCode | D4: Escalão | E4: TOTAL
A5: =RANK(E5,$E$5:$E$12) | B5: Pedro Costa Alemão | C5: 46706 | D5: Sub 16 | E5: =IFERROR(VLOOKUP("46706",Ranking!$C:$Z,24,FALSE),0)
A6: =RANK(E6,$E$5:$E$12) | B6: Rodrigo Sousa Correia | C6: 44934 | D6: Sub 16 | E6: =IFERROR(VLOOKUP("44934",Ranking!$C:$Z,24,FALSE),0)
A7: =RANK(E7,$E$5:$E$12) | B7: Angelina Gao | C7: 51523 | D7: Sub 16 | E7: =IFERROR(VLOOKUP("51523",Ranking!$C:$Z,24,FALSE),0)
A8: =RANK(E8,$E$5:$E$12) | B8: Madalena Figueiredo | C8: 52011 | D8: Sub 16 | E8: =IFERROR(VLOOKUP("52011",Ranking!$C:$Z,24,FALSE),0)
A9: =RANK(E9,$E$5:$E$12) | B9: Ryan Dantas | C9: 45439 | D9: Sub 16 | E9: =IFERROR(VLOOKUP("45439",Ranking!$C:$Z,24,FALSE),0)
A10: =RANK(E10,$E$5:$E$12) | B10: Diogo Sequeira | C10: 56654 | D10: Sub 16 | E10: =IFERROR(VLOOKUP("56654",Ranking!$C:$Z,24,FALSE),0)
A11: =RANK(E11,$E$5:$E$12) | B11: Rafael Gonçales Benesi | C11: 54774 | D11: Sub 16 | E11: =IFERROR(VLOOKUP("54774",Ranking!$C:$Z,24,FALSE),0)
A12: =RANK(E12,$E$5:$E$12) | B12: Clara Trindade | C12: 45812 | D12: Sub 16 | E12: =IFERROR(VLOOKUP("45812",Ranking!$C:$Z,24,FALSE),0)

Sheet Sub 23
A1: PJA TOUR 2026 — Ranking Sub 23
A2: Sub-ranking automático filtrado por escalão Sub 23. Totais referenciados directamente do Ranking principal — actualizam dinamicamente.
A4: Pos | B4: Jogador | C4: FedCode | D4: Escalão | E4: TOTAL
A5: =RANK(E5,$E$5:$E$8) | B5: Rodrigo Faria Constantino | C5: 45278 | D5: Sub 23 | E5: =IFERROR(VLOOKUP("45278",Ranking!$C:$Z,24,FALSE),0)
A6: =RANK(E6,$E$5:$E$8) | B6: João Maria Ivo de Carvalho | C6: 38334 | D6: Sub 23 | E6: =IFERROR(VLOOKUP("38334",Ranking!$C:$Z,24,FALSE),0)
A7: =RANK(E7,$E$5:$E$8) | B7: Martim Sousa de Morais | C7: 41609 | D7: Sub 23 | E7: =IFERROR(VLOOKUP("41609",Ranking!$C:$Z,24,FALSE),0)
A8: =RANK(E8,$E$5:$E$8) | B8: Rafaela Pinto | C8: 40390 | D8: Sub 23 | E8: =IFERROR(VLOOKUP("40390",Ranking!$C:$Z,24,FALSE),0)

Sheet dt1_madeira_palheiro
A1: 1º Drive Tour Madeira — Palheiro
A2: Data: | B2: 2026-01-03
A3: Campo: | B3: Palheiro Golf
A4: ccode/tcode: | B4: 982/10198
A5: Link FPG: | B5: https://scoring.datagolf.pt/pt/Classifications.aspx?ccode=982&tcode=10198
A6: Multiplicador: | B6: 1
A7: Tipo: | B7: DT
A10: Pos | B10: Nome | C10: FedCode | D10: Clube | E10: HCP | F10: R1 h1 | G10: h2 | H10: h3 | I10: h4 | J10: h5 | K10: h6 | L10: h7 | M10: h8 | N10: h9 | O10: h10 | P10: h11 | Q10: h12 | R10: h13 | S10: h14 | T10: h15 | U10: h16 | V10: h17 | W10: h18 | X10: R1 Gross | Y10: R1 Par | Z10: R1 ToPar | AA10: R1 Pts | AB10: Total Pts
A11: —Par— | F11: 4 | G11: 4 | H11: 3 | I11: 4 | J11: 3 | K11: 5 | L11: 3 | M11: 4 | N11: 4 | O11: 5 | P11: 3 | Q11: 5 | R11: 3 | S11: 4 | T11: 5 | U11: 4 | V11: 4 | W11: 5 | Y11: =SUM(F11:W11)
A12: —SI— | F12: 2 | G12: 16 | H12: 8 | I12: 12 | J12: 18 | K12: 4 | L12: 10 | M12: 6 | N12: 14 | O12: 9 | P12: 17 | Q12: 3 | R12: 15 | S12: 7 | T12: 13 | U12: 5 | V12: 1 | W12: 11
A13: 1 | B13: Salvador Rodrigues | C13: 39465 | D13: Palheiro | E13: 6.3 | F13: 6 | G13: 5 | H13: 5 | I13: 4 | J13: 3 | K13: 5 | L13: 3 | M13: 6 | N13: 4 | O13: 5 | P13: 3 | Q13: 6 | R13: 4 | S13: 3 | T13: 5 | U13: 3 | V13: 4 | W13: 5 | X13: =SUM(F13:W13) | Y13: =Y11 | Z13: =X13-Y13 | AA13: =MAX(0,25-Z13)*1.0 | AB13: =AA13
A14: 2 | B14: André Gonçalves | C14: 41121 | D14: Palheiro | E14: 6.1 | F14: 5 | G14: 5 | H14: 4 | I14: 4 | J14: 4 | K14: 5 | L14: 4 | M14: 4 | N14: 4 | O14: 5 | P14: 3 | Q14: 5 | R14: 4 | S14: 6 | T14: 5 | U14: 4 | V14: 4 | W14: 5 | X14: =SUM(F14:W14) | Y14: =Y11 | Z14: =X14-Y14 | AA14: =MAX(0,25-Z14)*1.0 | AB14: =AA14
A15: 3 | B15: Manuel Goulartt Medeiros | C15: 52884 | D15: Santo da Serra | E15: 12.3 | F15: 6 | G15: 5 | H15: 3 | I15: 4 | J15: 3 | K15: 5 | L15: 4 | M15: 5 | N15: 5 | O15: 4 | P15: 4 | Q15: 6 | R15: 3 | S15: 5 | T15: 5 | U15: 4 | V15: 6 | W15: 6 | X15: =SUM(F15:W15) | Y15: =Y11 | Z15: =X15-Y15 | AA15: =MAX(0,25-Z15)*1.0 | AB15: =AA15
A16: 4 | B16: José Pedro Miranda | C16: 38976 | D16: Palheiro | E16: 6.9 | F16: 5 | G16: 4 | H16: 4 | I16: 4 | J16: 2 | K16: 6 | L16: 6 | M16: 5 | N16: 5 | O16: 7 | P16: 4 | Q16: 5 | R16: 4 | S16: 5 | T16: 5 | U16: 4 | V16: 4 | W16: 5 | X16: =SUM(F16:W16) | Y16: =Y11 | Z16: =X16-Y16 | AA16: =MAX(0,25-Z16)*1.0 | AB16: =AA16
A17: 5 | B17: Marcelo Gaspar | C17: 38006 | D17: Santo da Serra | E17: 7.2 | F17: 5 | G17: 6 | H17: 6 | I17: 4 | J17: 4 | K17: 6 | L17: 4 | M17: 7 | N17: 5 | O17: 6 | P17: 2 | Q17: 6 | R17: 3 | S17: 5 | T17: 6 | U17: 5 | V17: 5 | W17: 5 | X17: =SUM(F17:W17) | Y17: =Y11 | Z17: =X17-Y17 | AA17: =MAX(0,25-Z17)*1.0 | AB17: =AA17
A18: 6 | B18: Rodrigo Abreu | C18: 42684 | D18: Palheiro | E18: 9.3 | F18: 6 | G18: 6 | H18: 5 | I18: 5 | J18: 6 | K18: 6 | L18: 2 | M18: 4 | N18: 5 | O18: 5 | P18: 2 | Q18: 6 | R18: 4 | S18: 6 | T18: 6 | U18: 4 | V18: 5 | W18: 7 | X18: =SUM(F18:W18) | Y18: =Y11 | Z18: =X18-Y18 | AA18: =MAX(0,25-Z18)*1.0 | AB18: =AA18
A19: 7 | B19: Mateus Penucho | C19: 52393 | D19: Santo da Serra | E19: 16.8 | F19: 5 | G19: 5 | H19: 3 | I19: 3 | J19: 5 | K19: 7 | L19: 4 | M19: 5 | N19: 6 | O19: 5 | P19: 4 | Q19: 6 | R19: 3 | S19: 5 | T19: 6 | U19: 5 | V19: 7 | W19: 6 | X19: =SUM(F19:W19) | Y19: =Y11 | Z19: =X19-Y19 | AA19: =MAX(0,25-Z19)*1.0 | AB19: =AA19
A20: NS | B20: Manuel Gouveia | D20: Santo da Serra | E20: 22.1 | AA20: 0 | AB20: =AA20

Sheet dt1_tejo_montado
A1: 1º Drive Tour Tejo — Montado
A2: Data: | B2: 2026-01-04
A3: Campo: | B3: Montado
A4: ccode/tcode: | B4: 985/10202
A5: Link FPG: | B5: https://scoring.datagolf.pt/pt/Classifications.aspx?ccode=985&tcode=10202
A6: Multiplicador: | B6: 1
A7: Tipo: | B7: DT
A10: Pos | B10: Nome | C10: FedCode | D10: Clube | E10: HCP | F10: R1 h1 | G10: h2 | H10: h3 | I10: h4 | J10: h5 | K10: h6 | L10: h7 | M10: h8 | N10: h9 | O10: h10 | P10: h11 | Q10: h12 | R10: h13 | S10: h14 | T10: h15 | U10: h16 | V10: h17 | W10: h18 | X10: R1 Gross | Y10: R1 Par | Z10: R1 ToPar | AA10: R1 Pts | AB10: Total Pts
A11: —Par— | F11: 4 | G11: 5 | H11: 3 | I11: 4 | J11: 4 | K11: 4 | L11: 5 | M11: 3 | N11: 4 | O11: 4 | P11: 4 | Q11: 3 | R11: 4 | S11: 4 | T11: 5 | U11: 4 | V11: 5 | W11: 3 | Y11: =SUM(F11:W11)
A12: —SI— | F12: 16 | G12: 6 | H12: 18 | I12: 12 | J12: 10 | K12: 8 | L12: 4 | M12: 14 | N12: 2 | O12: 17 | P12: 1 | Q12: 15 | R12: 3 | S12: 7 | T12: 5 | U12: 13 | V12: 9 | W12: 11
A13: 1 | B13: Ruiqi Li | C13: 49076 | D13: Estoril | E13: 4.7 | F13: 4 | G13: 5 | H13: 3 | I13: 3 | J13: 5 | K13: 6 | L13: 5 | M13: 3 | N13: 4 | O13: 4 | P13: 5 | Q13: 3 | R13: 4 | S13: 5 | T13: 4 | U13: 4 | V13: 4 | W13: 3 | X13: =SUM(F13:W13) | Y13: =Y11 | Z13: =X13-Y13 | AA13: =MAX(0,25-Z13)*1.0 | AB13: =AA13
A14: 2 | B14: Ricardo Castro Ferreira | C14: 49085 | D14: Estoril | E14: 7.7 | F14: 4 | G14: 5 | H14: 3 | I14: 4 | J14: 3 | K14: 5 | L14: 4 | M14: 3 | N14: 4 | O14: 4 | P14: 4 | Q14: 4 | R14: 4 | S14: 7 | T14: 5 | U14: 5 | V14: 5 | W14: 3 | X14: =SUM(F14:W14) | Y14: =Y11 | Z14: =X14-Y14 | AA14: =MAX(0,25-Z14)*1.0 | AB14: =AA14
A15: 3 | B15: Nuno Palmares Jr. | C15: 49124 | D15: Estoril | E15: 4.1 | F15: 5 | G15: 5 | H15: 4 | I15: 4 | J15: 4 | K15: 5 | L15: 6 | M15: 3 | N15: 4 | O15: 4 | P15: 5 | Q15: 3 | R15: 3 | S15: 4 | T15: 6 | U15: 4 | V15: 5 | W15: 3 | X15: =SUM(F15:W15) | Y15: =Y11 | Z15: =X15-Y15 | AA15: =MAX(0,25-Z15)*1.0 | AB15: =AA15
A16: 4 | B16: Francisca Salgado | C16: 43832 | D16: Vale de Janelas | E16: 0.5 | F16: 5 | G16: 5 | H16: 3 | I16: 4 | J16: 4 | K16: 5 | L16: 5 | M16: 2 | N16: 5 | O16: 4 | P16: 4 | Q16: 3 | R16: 5 | S16: 5 | T16: 6 | U16: 5 | V16: 5 | W16: 3 | X16: =SUM(F16:W16) | Y16: =Y11 | Z16: =X16-Y16 | AA16: =MAX(0,25-Z16)*1.0 | AB16: =AA16
A17: 5 | B17: João Rocha | C17: 48297 | D17: Estoril | E17: 3.9 | F17: 4 | G17: 5 | H17: 3 | I17: 5 | J17: 4 | K17: 5 | L17: 6 | M17: 4 | N17: 5 | O17: 3 | P17: 5 | Q17: 3 | R17: 4 | S17: 5 | T17: 6 | U17: 4 | V17: 5 | W17: 3 | X17: =SUM(F17:W17) | Y17: =Y11 | Z17: =X17-Y17 | AA17: =MAX(0,25-Z17)*1.0 | AB17: =AA17
A18: 6 | B18: Pedro Costa Alemão | C18: 46706 | D18: Estoril | E18: 4 | F18: 4 | G18: 5 | H18: 4 | I18: 4 | J18: 6 | K18: 4 | L18: 6 | M18: 3 | N18: 4 | O18: 4 | P18: 4 | Q18: 3 | R18: 4 | S18: 6 | T18: 5 | U18: 6 | V18: 5 | W18: 4 | X18: =SUM(F18:W18) | Y18: =Y11 | Z18: =X18-Y18 | AA18: =MAX(0,25-Z18)*1.0 | AB18: =AA18
A19: 7 | B19: Diogo Sequeira | C19: 56654 | D19: Quinta do Peru | E19: 5.6 | F19: 5 | G19: 5 | H19: 5 | I19: 4 | J19: 4 | K19: 4 | L19: 6 | M19: 5 | N19: 5 | O19: 4 | P19: 5 | Q19: 3 | R19: 4 | S19: 4 | T19: 6 | U19: 4 | V19: 6 | W19: 3 | X19: =SUM(F19:W19) | Y19: =Y11 | Z19: =X19-Y19 | AA19: =MAX(0,25-Z19)*1.0 | AB19: =AA19
A20: 8 | B20: Angelina Gao | C20: 51523 | D20: Quinta do Peru | E20: 3.9 | F20: 5 | G20: 5 | H20: 4 | I20: 5 | J20: 5 | K20: 5 | L20: 7 | M20: 3 | N20: 6 | O20: 5 | P20: 4 | Q20: 3 | R20: 5 | S20: 4 | T20: 6 | U20: 5 | V20: 5 | W20: 3 | X20: =SUM(F20:W20) | Y20: =Y11 | Z20: =X20-Y20 | AA20: =MAX(0,25-Z20)*1.0 | AB20: =AA20
A21: 9 | B21: William Gao | C21: 51524 | D21: Quinta do Peru | E21: 8.7 | F21: 5 | G21: 6 | H21: 3 | I21: 5 | J21: 5 | K21: 6 | L21: 6 | M21: 3 | N21: 6 | O21: 5 | P21: 5 | Q21: 4 | R21: 5 | S21: 5 | T21: 6 | U21: 3 | V21: 5 | W21: 3 | X21: =SUM(F21:W21) | Y21: =Y11 | Z21: =X21-Y21 | AA21: =MAX(0,25-Z21)*1.0 | AB21: =AA21
A22: 10 | B22: João Gomes | C22: 53715 | D22: Lisbon SC | E22: 10.7 | F22: 5 | G22: 5 | H22: 3 | I22: 5 | J22: 5 | K22: 5 | L22: 5 | M22: 4 | N22: 6 | O22: 5 | P22: 5 | Q22: 5 | R22: 5 | S22: 5 | T22: 5 | U22: 4 | V22: 6 | W22: 3 | X22: =SUM(F22:W22) | Y22: =Y11 | Z22: =X22-Y22 | AA22: =MAX(0,25-Z22)*1.0 | AB22: =AA22
A23: 11 | B23: Madalena Figueiredo | C23: 52011 | D23: Belas | E23: 9.4 | F23: 5 | G23: 6 | H23: 3 | I23: 6 | J23: 4 | K23: 5 | L23: 5 | M23: 6 | N23: 5 | O23: 4 | P23: 4 | Q23: 4 | R23: 5 | S23: 5 | T23: 6 | U23: 5 | V23: 6 | W23: 3 | X23: =SUM(F23:W23) | Y23: =Y11 | Z23: =X23-Y23 | AA23: =MAX(0,25-Z23)*1.0 | AB23: =AA23
A24: 12 | B24: Duarte Soares Franco | C24: 48531 | D24: Estoril | E24: 8.8 | F24: 5 | G24: 4 | H24: 5 | I24: 4 | J24: 5 | K24: 4 | L24: 5 | M24: 3 | N24: 5 | O24: 6 | P24: 5 | Q24: 5 | R24: 6 | S24: 4 | T24: 6 | U24: 4 | V24: 5 | W24: 6 | X24: =SUM(F24:W24) | Y24: =Y11 | Z24: =X24-Y24 | AA24: =MAX(0,25-Z24)*1.0 | AB24: =AA24
A25: 13 | B25: Martim Sousa de Morais | C25: 41609 | D25: Belas | E25: 4.5 | F25: 4 | G25: 5 | H25: 3 | I25: 4 | J25: 4 | K25: 4 | L25: 6 | M25: 3 | N25: 5 | O25: 5 | P25: 5 | Q25: 4 | R25: 4 | S25: 5 | T25: 7 | U25: 6 | V25: 7 | W25: 6 | X25: =SUM(F25:W25) | Y25: =Y11 | Z25: =X25-Y25 | AA25: =MAX(0,25-Z25)*1.0 | AB25: =AA25
A26: 14 | B26: Tomás Valério | C26: 50011 | D26: Vilamoura, C. G | E26: 26.7 | F26: 6 | G26: 6 | H26: 4 | I26: 6 | J26: 4 | K26: 6 | L26: 4 | M26: 4 | N26: 6 | O26: 6 | P26: 4 | Q26: 4 | R26: 5 | S26: 4 | T26: 6 | U26: 5 | V26: 5 | W26: 3 | X26: =SUM(F26:W26) | Y26: =Y11 | Z26: =X26-Y26 | AA26: =MAX(0,25-Z26)*1.0 | AB26: =AA26
A27: 15 | B27: Clara Trindade | C27: 45812 | D27: Belas | E27: 7.4 | F27: 6 | G27: 5 | H27: 4 | I27: 5 | J27: 5 | K27: 3 | L27: 7 | M27: 3 | N27: 5 | O27: 5 | P27: 4 | Q27: 5 | R27: 8 | S27: 5 | T27: 6 | U27: 4 | V27: 5 | W27: 5 | X27: =SUM(F27:W27) | Y27: =Y11 | Z27: =X27-Y27 | AA27: =MAX(0,25-Z27)*1.0 | AB27: =AA27
A28: 16 | B28: Joaquim Gomes | C28: 53714 | D28: Lisbon SC | E28: 11.1 | F28: 5 | G28: 6 | H28: 4 | I28: 5 | J28: 6 | K28: 5 | L28: 5 | M28: 4 | N28: 5 | O28: 6 | P28: 6 | Q28: 3 | R28: 5 | S28: 5 | T28: 6 | U28: 5 | V28: 6 | W28: 4 | X28: =SUM(F28:W28) | Y28: =Y11 | Z28: =X28-Y28 | AA28: =MAX(0,25-Z28)*1.0 | AB28: =AA28
A29: 17 | B29: Rafael Gonçales Benesi | C29: 54774 | D29: Estoril | E29: 6.4 | F29: 6 | G29: 5 | H29: 3 | I29: 5 | J29: 4 | K29: 4 | L29: 7 | M29: 3 | N29: 8 | O29: 5 | P29: 6 | Q29: 3 | R29: 4 | S29: 8 | T29: 5 | U29: 5 | V29: 7 | W29: 3 | X29: =SUM(F29:W29) | Y29: =Y11 | Z29: =X29-Y29 | AA29: =MAX(0,25-Z29)*1.0 | AB29: =AA29
A30: 18 | B30: Miguel Santos Pereira | C30: 48946 | D30: Vilamoura, C. G | E30: 21.3 | F30: 5 | G30: 6 | H30: 4 | I30: 5 | J30: 4 | K30: 7 | L30: 7 | M30: 4 | N30: 5 | O30: 5 | P30: 6 | Q30: 3 | R30: 6 | S30: 5 | T30: 7 | U30: 5 | V30: 5 | W30: 3 | X30: =SUM(F30:W30) | Y30: =Y11 | Z30: =X30-Y30 | AA30: =MAX(0,25-Z30)*1.0 | AB30: =AA30
A31: 19 | B31: Gabriel Costa | C31: 53838 | D31: Amendoeira | E31: 21.5 | F31: 7 | G31: 5 | H31: 4 | I31: 5 | J31: 4 | K31: 5 | L31: 7 | M31: 4 | N31: 7 | O31: 4 | P31: 7 | Q31: 3 | R31: 6 | S31: 4 | T31: 6 | U31: 5 | V31: 7 | W31: 4 | X31: =SUM(F31:W31) | Y31: =Y11 | Z31: =X31-Y31 | AA31: =MAX(0,25-Z31)*1.0 | AB31: =AA31
A32: 20 | B32: Francisca Vilela | C32: 36700 | D32: Lisbon SC | E32: 15.8 | F32: 7 | G32: 6 | H32: 4 | I32: 5 | J32: 7 | K32: 5 | L32: 6 | M32: 3 | N32: 7 | O32: 4 | P32: 6 | Q32: 3 | R32: 6 | S32: 6 | T32: 7 | U32: 4 | V32: 6 | W32: 3 | X32: =SUM(F32:W32) | Y32: =Y11 | Z32: =X32-Y32 | AA32: =MAX(0,25-Z32)*1.0 | AB32: =AA32
A33: 21 | B33: Tiago Lúcio | C33: 44844 | D33: Jamor C.G. | E33: 21.7 | F33: 5 | G33: 6 | H33: 4 | I33: 6 | J33: 4 | K33: 5 | L33: 6 | M33: 4 | N33: 6 | O33: 5 | P33: 6 | Q33: 6 | R33: 5 | S33: 5 | T33: 8 | U33: 5 | V33: 7 | W33: 4 | X33: =SUM(F33:W33) | Y33: =Y11 | Z33: =X33-Y33 | AA33: =MAX(0,25-Z33)*1.0 | AB33: =AA33
A34: 22 | B34: Marek Pejas | C34: 52069 | D34: Vilamoura, C. G | E34: 20.1 | F34: 6 | G34: 6 | H34: 6 | I34: 7 | J34: 7 | K34: 6 | L34: 8 | M34: 3 | N34: 6 | O34: 5 | P34: 4 | Q34: 3 | R34: 5 | S34: 6 | T34: 7 | U34: 4 | V34: 5 | W34: 4 | X34: =SUM(F34:W34) | Y34: =Y11 | Z34: =X34-Y34 | AA34: =MAX(0,25-Z34)*1.0 | AB34: =AA34
A35: 23 | B35: Manuel Vaz Pinto | C35: 51430 | D35: Lisbon SC | E35: 20.9 | F35: 7 | G35: 5 | H35: 4 | I35: 4 | J35: 4 | K35: 5 | L35: 7 | M35: 4 | N35: 8 | O35: 5 | P35: 6 | Q35: 4 | R35: 7 | S35: 7 | T35: 6 | U35: 4 | V35: 5 | W35: 7 | X35: =SUM(F35:W35) | Y35: =Y11 | Z35: =X35-Y35 | AA35: =MAX(0,25-Z35)*1.0 | AB35: =AA35
A36: 24 | B36: Catarina Valério | C36: 46873 | D36: Vilamoura, C. G | E36: 17.9 | F36: 6 | G36: 8 | H36: 3 | I36: 6 | J36: 5 | K36: 8 | L36: 6 | M36: 4 | N36: 5 | O36: 5 | P36: 6 | Q36: 5 | R36: 6 | S36: 7 | T36: 8 | U36: 5 | V36: 6 | W36: 4 | X36: =SUM(F36:W36) | Y36: =Y11 | Z36: =X36-Y36 | AA36: =MAX(0,25-Z36)*1.0 | AB36: =AA36
A37: 25 | B37: Ryan Dantas | C37: 45439 | D37: Belas | E37: 6.4 | F37: 8 | G37: 5 | H37: 3 | I37: 6 | J37: 5 | K37: 7 | L37: 6 | M37: 3 | N37: 10 | O37: 10 | P37: 7 | Q37: 3 | R37: 4 | S37: 6 | T37: 5 | U37: 6 | V37: 6 | W37: 4 | X37: =SUM(F37:W37) | Y37: =Y11 | Z37: =X37-Y37 | AA37: =MAX(0,25-Z37)*1.0 | AB37: =AA37
A38: 26 | B38: Alfie Kelley | C38: 58043 | D38: Belas | E38: 17.8 | F38: 6 | G38: 4 | H38: 4 | I38: 6 | J38: 5 | K38: 7 | L38: 6 | M38: 3 | N38: 6 | O38: 5 | P38: 6 | Q38: 7 | R38: 4 | S38: 10 | T38: 8 | U38: 5 | V38: 6 | W38: 8 | X38: =SUM(F38:W38) | Y38: =Y11 | Z38: =X38-Y38 | AA38: =MAX(0,25-Z38)*1.0 | AB38: =AA38
A39: 27 | B39: Tomás de Morais | C39: 55466 | D39: Estoril | E39: 21.8 | F39: 7 | G39: 8 | H39: 6 | I39: 8 | J39: 9 | K39: 5 | L39: 10 | M39: 8 | N39: 6 | O39: 6 | P39: 7 | Q39: 4 | R39: 6 | S39: 10 | T39: 9 | U39: 7 | V39: 6 | W39: 4 | X39: =SUM(F39:W39) | Y39: =Y11 | Z39: =X39-Y39 | AA39: =MAX(0,25-Z39)*1.0 | AB39: =AA39
A40: NS | B40: Sara Filipa Bastos | D40: ACP Golfe | E40: 18.2 | AA40: 0 | AB40: =AA40

Sheet dt1_norte_estela
A1: 1º Drive Tour Norte — Estela
A2: Data: | B2: 2026-01-04
A3: Campo: | B3: Estela GC
A4: ccode/tcode: | B4: 987/10206
A5: Link FPG: | B5: https://scoring.datagolf.pt/pt/Classifications.aspx?ccode=987&tcode=10206
A6: Multiplicador: | B6: 1
A7: Tipo: | B7: DT
A10: Pos | B10: Nome | C10: FedCode | D10: Clube | E10: HCP | F10: R1 h1 | G10: h2 | H10: h3 | I10: h4 | J10: h5 | K10: h6 | L10: h7 | M10: h8 | N10: h9 | O10: h10 | P10: h11 | Q10: h12 | R10: h13 | S10: h14 | T10: h15 | U10: h16 | V10: h17 | W10: h18 | X10: R1 Gross | Y10: R1 Par | Z10: R1 ToPar | AA10: R1 Pts | AB10: Total Pts
A11: —Par— | F11: 5 | G11: 3 | H11: 4 | I11: 3 | J11: 4 | K11: 4 | L11: 5 | M11: 4 | N11: 4 | O11: 4 | P11: 4 | Q11: 3 | R11: 5 | S11: 4 | T11: 5 | U11: 4 | V11: 3 | W11: 4 | Y11: =SUM(F11:W11)
A12: —SI— | F12: 13 | G12: 17 | H12: 1 | I12: 7 | J12: 4 | K12: 2 | L12: 11 | M12: 15 | N12: 12 | O12: 5 | P12: 16 | Q12: 10 | R12: 14 | S12: 9 | T12: 3 | U12: 8 | V12: 18 | W12: 6
A13: 1 | B13: Francisca Ferreira da Costa | C13: 40981 | D13: Miramar | E13: 0.5 | F13: 4 | G13: 3 | H13: 4 | I13: 2 | J13: 4 | K13: 4 | L13: 4 | M13: 4 | N13: 4 | O13: 5 | P13: 5 | Q13: 3 | R13: 5 | S13: 3 | T13: 5 | U13: 4 | V13: 3 | W13: 4 | X13: =SUM(F13:W13) | Y13: =Y11 | Z13: =X13-Y13 | AA13: =MAX(0,25-Z13)*1.0 | AB13: =AA13
A14: 2 | B14: Santiago Dias | C14: 42908 | D14: Oporto | E14: 1.5 | F14: 5 | G14: 3 | H14: 4 | I14: 3 | J14: 3 | K14: 5 | L14: 5 | M14: 4 | N14: 3 | O14: 7 | P14: 4 | Q14: 3 | R14: 4 | S14: 4 | T14: 4 | U14: 4 | V14: 3 | W14: 4 | X14: =SUM(F14:W14) | Y14: =Y11 | Z14: =X14-Y14 | AA14: =MAX(0,25-Z14)*1.0 | AB14: =AA14
A15: 3 | B15: Francisco Nunes (jr) | C15: 46299 | D15: Miramar | E15: 6.8 | F15: 5 | G15: 2 | H15: 5 | I15: 3 | J15: 4 | K15: 5 | L15: 5 | M15: 6 | N15: 3 | O15: 4 | P15: 4 | Q15: 2 | R15: 4 | S15: 4 | T15: 4 | U15: 5 | V15: 4 | W15: 4 | X15: =SUM(F15:W15) | Y15: =Y11 | Z15: =X15-Y15 | AA15: =MAX(0,25-Z15)*1.0 | AB15: =AA15
A16: 4 | B16: Pedro Ferreira | C16: 43810 | D16: Oporto | E16: 0.7 | F16: 5 | G16: 3 | H16: 4 | I16: 3 | J16: 5 | K16: 4 | L16: 6 | M16: 4 | N16: 4 | O16: 3 | P16: 5 | Q16: 3 | R16: 4 | S16: 5 | T16: 5 | U16: 4 | V16: 4 | W16: 4 | X16: =SUM(F16:W16) | Y16: =Y11 | Z16: =X16-Y16 | AA16: =MAX(0,25-Z16)*1.0 | AB16: =AA16
A17: 5 | B17: Francisco Saraiva | C17: 39097 | D17: Oporto | E17: 8.3 | F17: 4 | G17: 3 | H17: 5 | I17: 3 | J17: 4 | K17: 5 | L17: 7 | M17: 4 | N17: 4 | O17: 5 | P17: 5 | Q17: 3 | R17: 5 | S17: 4 | T17: 6 | U17: 3 | V17: 2 | W17: 4 | X17: =SUM(F17:W17) | Y17: =Y11 | Z17: =X17-Y17 | AA17: =MAX(0,25-Z17)*1.0 | AB17: =AA17
A18: 6 | B18: Guilherme Grabner Moreira | C18: 42205 | D18: Oporto | E18: 0 | F18: 5 | G18: 3 | H18: 7 | I18: 3 | J18: 5 | K18: 5 | L18: 4 | M18: 4 | N18: 3 | O18: 3 | P18: 4 | Q18: 3 | R18: 5 | S18: 4 | T18: 5 | U18: 4 | V18: 3 | W18: 6 | X18: =SUM(F18:W18) | Y18: =Y11 | Z18: =X18-Y18 | AA18: =MAX(0,25-Z18)*1.0 | AB18: =AA18
A19: 7 | B19: Francisco Costa Mendes | C19: 40318 | D19: Citynorte | E19: 6.3 | F19: 5 | G19: 4 | H19: 6 | I19: 3 | J19: 5 | K19: 4 | L19: 6 | M19: 3 | N19: 3 | O19: 4 | P19: 4 | Q19: 4 | R19: 5 | S19: 4 | T19: 5 | U19: 4 | V19: 4 | W19: 4 | X19: =SUM(F19:W19) | Y19: =Y11 | Z19: =X19-Y19 | AA19: =MAX(0,25-Z19)*1.0 | AB19: =AA19
A20: 8 | B20: Camila Pazos | C20: 46297 | D20: Miramar | E20: 2.6 | F20: 6 | G20: 3 | H20: 4 | I20: 4 | J20: 6 | K20: 4 | L20: 5 | M20: 4 | N20: 4 | O20: 4 | P20: 4 | Q20: 3 | R20: 6 | S20: 4 | T20: 6 | U20: 4 | V20: 3 | W20: 5 | X20: =SUM(F20:W20) | Y20: =Y11 | Z20: =X20-Y20 | AA20: =MAX(0,25-Z20)*1.0 | AB20: =AA20
A21: 9 | B21: Eva Silva | C21: 46437 | D21: Oporto | E21: 0.5 | F21: 5 | G21: 3 | H21: 4 | I21: 3 | J21: 6 | K21: 6 | L21: 5 | M21: 5 | N21: 4 | O21: 5 | P21: 4 | Q21: 3 | R21: 5 | S21: 4 | T21: 5 | U21: 5 | V21: 3 | W21: 5 | X21: =SUM(F21:W21) | Y21: =Y11 | Z21: =X21-Y21 | AA21: =MAX(0,25-Z21)*1.0 | AB21: =AA21
A22: 10 | B22: Gaspard Maes | C22: 51074 | D22: Miramar | E22: 0.8 | F22: 4 | G22: 3 | H22: 6 | I22: 4 | J22: 4 | K22: 7 | L22: 4 | M22: 4 | N22: 3 | O22: 4 | P22: 4 | Q22: 4 | R22: 5 | S22: 6 | T22: 5 | U22: 4 | V22: 3 | W22: 6 | X22: =SUM(F22:W22) | Y22: =Y11 | Z22: =X22-Y22 | AA22: =MAX(0,25-Z22)*1.0 | AB22: =AA22
A23: 11 | B23: João Balixa | C23: 46038 | D23: Miramar | E23: 10.4 | F23: 4 | G23: 3 | H23: 7 | I23: 4 | J23: 4 | K23: 5 | L23: 5 | M23: 5 | N23: 4 | O23: 4 | P23: 4 | Q23: 4 | R23: 6 | S23: 5 | T23: 6 | U23: 3 | V23: 3 | W23: 5 | X23: =SUM(F23:W23) | Y23: =Y11 | Z23: =X23-Y23 | AA23: =MAX(0,25-Z23)*1.0 | AB23: =AA23
A24: 12 | B24: Maria Francisca Santos | C24: 46853 | D24: Oporto | E24: 4.9 | F24: 5 | G24: 4 | H24: 5 | I24: 3 | J24: 4 | K24: 6 | L24: 5 | M24: 5 | N24: 4 | O24: 4 | P24: 4 | Q24: 3 | R24: 5 | S24: 5 | T24: 7 | U24: 4 | V24: 3 | W24: 5 | X24: =SUM(F24:W24) | Y24: =Y11 | Z24: =X24-Y24 | AA24: =MAX(0,25-Z24)*1.0 | AB24: =AA24
A25: 13 | B25: Afonso Silva Pinto | C25: 46309 | D25: Miramar | E25: 5.6 | F25: 5 | G25: 3 | H25: 5 | I25: 5 | J25: 5 | K25: 5 | L25: 6 | M25: 4 | N25: 5 | O25: 4 | P25: 5 | Q25: 4 | R25: 4 | S25: 5 | T25: 5 | U25: 3 | V25: 3 | W25: 6 | X25: =SUM(F25:W25) | Y25: =Y11 | Z25: =X25-Y25 | AA25: =MAX(0,25-Z25)*1.0 | AB25: =AA25
A26: 14 | B26: Maria Loureiro | C26: 46489 | D26: Oporto | E26: 6.8 | F26: 5 | G26: 2 | H26: 5 | I26: 4 | J26: 4 | K26: 5 | L26: 6 | M26: 4 | N26: 4 | O26: 6 | P26: 4 | Q26: 2 | R26: 5 | S26: 6 | T26: 7 | U26: 4 | V26: 4 | W26: 5 | X26: =SUM(F26:W26) | Y26: =Y11 | Z26: =X26-Y26 | AA26: =MAX(0,25-Z26)*1.0 | AB26: =AA26
A27: 15 | B27: Jorge Xavier Graça Silva | C27: 48705 | D27: Miramar | E27: 7.3 | F27: 5 | G27: 4 | H27: 7 | I27: 3 | J27: 5 | K27: 7 | L27: 5 | M27: 3 | N27: 5 | O27: 4 | P27: 4 | Q27: 3 | R27: 6 | S27: 4 | T27: 5 | U27: 4 | V27: 3 | W27: 6 | X27: =SUM(F27:W27) | Y27: =Y11 | Z27: =X27-Y27 | AA27: =MAX(0,25-Z27)*1.0 | AB27: =AA27
A28: 16 | B28: Ricardo Rocha Ferreira | C28: 51180 | D28: Miramar | E28: 21.1 | F28: 4 | G28: 2 | H28: 5 | I28: 3 | J28: 4 | K28: 10 | L28: 6 | M28: 4 | N28: 5 | O28: 5 | P28: 4 | Q28: 4 | R28: 5 | S28: 5 | T28: 5 | U28: 5 | V28: 3 | W28: 4 | X28: =SUM(F28:W28) | Y28: =Y11 | Z28: =X28-Y28 | AA28: =MAX(0,25-Z28)*1.0 | AB28: =AA28
A29: 17 | B29: Gabriel Marques Guerreiro | C29: 43053 | D29: Estela | E29: 4.5 | F29: 8 | G29: 3 | H29: 5 | I29: 4 | J29: 7 | K29: 4 | L29: 5 | M29: 3 | N29: 4 | O29: 6 | P29: 4 | Q29: 3 | R29: 5 | S29: 4 | T29: 6 | U29: 4 | V29: 3 | W29: 5 | X29: =SUM(F29:W29) | Y29: =Y11 | Z29: =X29-Y29 | AA29: =MAX(0,25-Z29)*1.0 | AB29: =AA29
A30: 18 | B30: Sebastiao Sardinha Saraiva | C30: 46195 | D30: Oporto | E30: 5.7 | F30: 5 | G30: 4 | H30: 6 | I30: 4 | J30: 5 | K30: 5 | L30: 5 | M30: 5 | N30: 4 | O30: 4 | P30: 4 | Q30: 4 | R30: 7 | S30: 4 | T30: 5 | U30: 4 | V30: 3 | W30: 5 | X30: =SUM(F30:W30) | Y30: =Y11 | Z30: =X30-Y30 | AA30: =MAX(0,25-Z30)*1.0 | AB30: =AA30
A31: 19 | B31: João Araújo | C31: 49012 | D31: Citynorte | E31: 5.9 | F31: 5 | G31: 3 | H31: 5 | I31: 4 | J31: 5 | K31: 6 | L31: 5 | M31: 4 | N31: 5 | O31: 4 | P31: 4 | Q31: 4 | R31: 6 | S31: 4 | T31: 7 | U31: 4 | V31: 3 | W31: 5 | X31: =SUM(F31:W31) | Y31: =Y11 | Z31: =X31-Y31 | AA31: =MAX(0,25-Z31)*1.0 | AB31: =AA31
A32: 20 | B32: Tomás Rente | C32: 46311 | D32: Miramar | E32: 5.5 | F32: 5 | G32: 4 | H32: 5 | I32: 3 | J32: 4 | K32: 7 | L32: 7 | M32: 6 | N32: 4 | O32: 6 | P32: 5 | Q32: 4 | R32: 5 | S32: 4 | T32: 5 | U32: 4 | V32: 3 | W32: 4 | X32: =SUM(F32:W32) | Y32: =Y11 | Z32: =X32-Y32 | AA32: =MAX(0,25-Z32)*1.0 | AB32: =AA32
A33: 21 | B33: Tomás Sarmento de Beires | C33: 48046 | D33: Citynorte | E33: 17.2 | F33: 5 | G33: 3 | H33: 5 | I33: 4 | J33: 4 | K33: 8 | L33: 7 | M33: 4 | N33: 4 | O33: 5 | P33: 4 | Q33: 3 | R33: 5 | S33: 5 | T33: 7 | U33: 5 | V33: 3 | W33: 5 | X33: =SUM(F33:W33) | Y33: =Y11 | Z33: =X33-Y33 | AA33: =MAX(0,25-Z33)*1.0 | AB33: =AA33
A34: 22 | B34: Diogo Lima | C34: 49717 | D34: Citynorte | E34: 12.8 | F34: 6 | G34: 4 | H34: 4 | I34: 4 | J34: 5 | K34: 5 | L34: 5 | M34: 4 | N34: 6 | O34: 5 | P34: 5 | Q34: 3 | R34: 6 | S34: 5 | T34: 7 | U34: 4 | V34: 3 | W34: 5 | X34: =SUM(F34:W34) | Y34: =Y11 | Z34: =X34-Y34 | AA34: =MAX(0,25-Z34)*1.0 | AB34: =AA34
A35: 23 | B35: Pedro Aires | C35: 42068 | D35: Citynorte | E35: 8 | F35: 4 | G35: 3 | H35: 8 | I35: 3 | J35: 7 | K35: 5 | L35: 7 | M35: 6 | N35: 4 | O35: 3 | P35: 4 | Q35: 3 | R35: 4 | S35: 4 | T35: 5 | U35: 5 | V35: 4 | W35: 9 | X35: =SUM(F35:W35) | Y35: =Y11 | Z35: =X35-Y35 | AA35: =MAX(0,25-Z35)*1.0 | AB35: =AA35
A36: 24 | B36: Afonso de Sousa Pinto | C36: 46480 | D36: Oporto | E36: 10 | F36: 6 | G36: 3 | H36: 6 | I36: 4 | J36: 5 | K36: 5 | L36: 6 | M36: 4 | N36: 5 | O36: 5 | P36: 4 | Q36: 4 | R36: 4 | S36: 5 | T36: 7 | U36: 6 | V36: 4 | W36: 5 | X36: =SUM(F36:W36) | Y36: =Y11 | Z36: =X36-Y36 | AA36: =MAX(0,25-Z36)*1.0 | AB36: =AA36
