Workbook

Sheet Ranking
A1: PJA TOUR 2025 — Race to Dunas Ranking
A2: Fórmula por ronda: pts = MAX(0, 25 − toPar) × multiplicador (1.0 standard · 1.75 Royal Óbidos · 1.5 Grande Final)
A3: Regra 2025: Top-7 melhores torneios regulares contam + Grande Final adicionada separadamente. Vale Pisão D1+D2 contam como 1 torneio só.
E4: Royal Óbidos AT&T | F4: Aroeira Master by Details (Fev) | G4: Ribagolfe Oaks Masters | H4: Greatgolf Junior Open w/ Luis Figo Foundation | I4: PJA António Dantas Classic | J4: PJA TOUR Vale Pisão | K4: PJA Race to Dunas | L4: PJA Tour Troia | M4: PJA Masters by Details — Aroeira 2 | N4: Soma top 7 torneios | O4: Grande Final | P4: Top-7 + GF
A5: Pos | B5: Jogador | C5: FedCode | D5: Escalão | E5: royal_obidos | F5: aroeira_fev | G5: ribagolfe | H5: greatgolf | I5: antonio_dantas | J5: vale_pisao | K5: race_to_dunas | L5: troia | M5: aroeira_2 | N5: Top-7 | O5: GF ×1.5 | P5: TOTAL
A6: =RANK(P6,$P$6:$P$45) | B6: João Maria Ivo de Carvalho | C6: 38334 | D6: Sub 23 | E6: ='royal_obidos'!AB12 | F6: ='aroeira_fev'!AX14 | G6: ='ribagolfe'!AX12 | H6: 0 | I6: ='antonio_dantas'!AX15 | J6: 0 | K6: ='race_to_dunas'!AX18 | L6: 0 | M6: ='aroeira_2'!AX12 | N6: =IFERROR(LARGE(E6:M6,1),0)+IFERROR(LARGE(E6:M6,2),0)+IFERROR(LARGE(E6:M6,3),0)+IFERROR(LARGE(E6:M6,4),0)+IFERROR(LARGE(E6:M6,5),0)+IFERROR(LARGE(E6:M6,6),0)+IFERROR(LARGE(E6:M6,7),0) | O6: ='grande_final'!AX12 | P6: =N6+O6
A7: =RANK(P7,$P$6:$P$45) | B7: Santiago Dias | C7: 42908 | D7: Sub 14 | E7: ='royal_obidos'!AB13 | F7: 0 | G7: 0 | H7: ='greatgolf'!AX15 | I7: 0 | J7: 0 | K7: 0 | L7: ='troia'!AX13 | M7: 0 | N7: =IFERROR(LARGE(E7:M7,1),0)+IFERROR(LARGE(E7:M7,2),0)+IFERROR(LARGE(E7:M7,3),0)+IFERROR(LARGE(E7:M7,4),0)+IFERROR(LARGE(E7:M7,5),0)+IFERROR(LARGE(E7:M7,6),0)+IFERROR(LARGE(E7:M7,7),0) | O7: 0 | P7: =N7+O7
A8: =RANK(P8,$P$6:$P$45) | B8: João Setúbal | C8: 43732 | D8: Sub 14 | E8: ='royal_obidos'!AB14 | F8: 0 | G8: 0 | H8: ='greatgolf'!AX17 | I8: ='antonio_dantas'!AX13 | J8: 0 | K8: ='race_to_dunas'!AX12 | L8: ='troia'!AX12 | M8: 0 | N8: =IFERROR(LARGE(E8:M8,1),0)+IFERROR(LARGE(E8:M8,2),0)+IFERROR(LARGE(E8:M8,3),0)+IFERROR(LARGE(E8:M8,4),0)+IFERROR(LARGE(E8:M8,5),0)+IFERROR(LARGE(E8:M8,6),0)+IFERROR(LARGE(E8:M8,7),0) | O8: ='grande_final'!AX13 | P8: =N8+O8
A9: =RANK(P9,$P$6:$P$45) | B9: Clara Trindade | C9: 45812 | D9: Sub 14 | E9: ='royal_obidos'!AB15 | F9: ='aroeira_fev'!AX19 | G9: ='ribagolfe'!AX20 | H9: ='greatgolf'!AX41 | I9: 0 | J9: 0 | K9: ='race_to_dunas'!AX20 | L9: ='troia'!AX17 | M9: 0 | N9: =IFERROR(LARGE(E9:M9,1),0)+IFERROR(LARGE(E9:M9,2),0)+IFERROR(LARGE(E9:M9,3),0)+IFERROR(LARGE(E9:M9,4),0)+IFERROR(LARGE(E9:M9,5),0)+IFERROR(LARGE(E9:M9,6),0)+IFERROR(LARGE(E9:M9,7),0) | O9: ='grande_final'!AX23 | P9: =N9+O9
A10: =RANK(P10,$P$6:$P$45) | B10: Miguel Coelho Porfirio | C10: 44160 | D10: Sub 12 | E10: ='royal_obidos'!AB16 | F10: ='aroeira_fev'!AX17 | G10: 0 | H10: ='greatgolf'!AX28 | I10: ='antonio_dantas'!AX17 | J10: 0 | K10: 0 | L10: 0 | M10: 0 | N10: =IFERROR(LARGE(E10:M10,1),0)+IFERROR(LARGE(E10:M10,2),0)+IFERROR(LARGE(E10:M10,3),0)+IFERROR(LARGE(E10:M10,4),0)+IFERROR(LARGE(E10:M10,5),0)+IFERROR(LARGE(E10:M10,6),0)+IFERROR(LARGE(E10:M10,7),0) | O10: 0 | P10: =N10+O10
A11: =RANK(P11,$P$6:$P$45) | B11: Henrique Almeida da Silva | C11: 41612 | D11: Sub 16 | E11: ='royal_obidos'!AB17 | F11: 0 | G11: 0 | H11: 0 | I11: 0 | J11: 0 | K11: 0 | L11: 0 | M11: 0 | N11: =IFERROR(LARGE(E11:M11,1),0)+IFERROR(LARGE(E11:M11,2),0)+IFERROR(LARGE(E11:M11,3),0)+IFERROR(LARGE(E11:M11,4),0)+IFERROR(LARGE(E11:M11,5),0)+IFERROR(LARGE(E11:M11,6),0)+IFERROR(LARGE(E11:M11,7),0) | O11: 0 | P11: =N11+O11
A12: =RANK(P12,$P$6:$P$45) | B12: Ricardo Castro Ferreira | C12: 49085 | D12: Sub 12 | E12: ='royal_obidos'!AB18 | F12: ='aroeira_fev'!AX13 | G12: ='ribagolfe'!AX17 | H12: ='greatgolf'!AX22 | I12: ='antonio_dantas'!AX12 | J12: ='vale_pisao'!AX12 | K12: ='race_to_dunas'!AX14 | L12: ='troia'!AX25 | M12: ='aroeira_2'!AX13 | N12: =IFERROR(LARGE(E12:M12,1),0)+IFERROR(LARGE(E12:M12,2),0)+IFERROR(LARGE(E12:M12,3),0)+IFERROR(LARGE(E12:M12,4),0)+IFERROR(LARGE(E12:M12,5),0)+IFERROR(LARGE(E12:M12,6),0)+IFERROR(LARGE(E12:M12,7),0) | O12: ='grande_final'!AX17 | P12: =N12+O12
A13: =RANK(P13,$P$6:$P$45) | B13: Rafael Gonçales Benesi | C13: 54774 | D13: Sub 14 | E13: ='royal_obidos'!AB19 | F13: ='aroeira_fev'!AX16 | G13: ='ribagolfe'!AX13 | H13: 0 | I13: ='antonio_dantas'!AX23 | J13: 0 | K13: ='race_to_dunas'!AX26 | L13: ='troia'!AX27 | M13: ='aroeira_2'!AX20 | N13: =IFERROR(LARGE(E13:M13,1),0)+IFERROR(LARGE(E13:M13,2),0)+IFERROR(LARGE(E13:M13,3),0)+IFERROR(LARGE(E13:M13,4),0)+IFERROR(LARGE(E13:M13,5),0)+IFERROR(LARGE(E13:M13,6),0)+IFERROR(LARGE(E13:M13,7),0) | O13: 0 | P13: =N13+O13
A14: =RANK(P14,$P$6:$P$45) | B14: Pedro Costa Alemão | C14: 46706 | D14: Sub 14 | E14: ='royal_obidos'!AB20 | F14: ='aroeira_fev'!AX15 | G14: ='ribagolfe'!AX14 | H14: ='greatgolf'!AX13 | I14: ='antonio_dantas'!AX24 | J14: 0 | K14: ='race_to_dunas'!AX22 | L14: ='troia'!AX22 | M14: ='aroeira_2'!AX19 | N14: =IFERROR(LARGE(E14:M14,1),0)+IFERROR(LARGE(E14:M14,2),0)+IFERROR(LARGE(E14:M14,3),0)+IFERROR(LARGE(E14:M14,4),0)+IFERROR(LARGE(E14:M14,5),0)+IFERROR(LARGE(E14:M14,6),0)+IFERROR(LARGE(E14:M14,7),0) | O14: ='grande_final'!AX21 | P14: =N14+O14
A15: =RANK(P15,$P$6:$P$45) | B15: Nuno Palmares Jr. | C15: 49124 | D15: Sub 14 | E15: ='royal_obidos'!AB21 | F15: ='aroeira_fev'!AX18 | G15: 0 | H15: ='greatgolf'!AX24 | I15: ='antonio_dantas'!AX19 | J15: 0 | K15: ='race_to_dunas'!AX15 | L15: ='troia'!AX15 | M15: ='aroeira_2'!AX17 | N15: =IFERROR(LARGE(E15:M15,1),0)+IFERROR(LARGE(E15:M15,2),0)+IFERROR(LARGE(E15:M15,3),0)+IFERROR(LARGE(E15:M15,4),0)+IFERROR(LARGE(E15:M15,5),0)+IFERROR(LARGE(E15:M15,6),0)+IFERROR(LARGE(E15:M15,7),0) | O15: ='grande_final'!AX18 | P15: =N15+O15
A16: =RANK(P16,$P$6:$P$45) | B16: Filipe Pinheiro | C16: 46591 | D16: Sub 14 | E16: ='royal_obidos'!AB22 | F16: ='aroeira_fev'!AX22 | G16: ='ribagolfe'!AX18 | H16: ='greatgolf'!AX16 | I16: ='antonio_dantas'!AX16 | J16: 0 | K16: ='race_to_dunas'!AX17 | L16: 0 | M16: 0 | N16: =IFERROR(LARGE(E16:M16,1),0)+IFERROR(LARGE(E16:M16,2),0)+IFERROR(LARGE(E16:M16,3),0)+IFERROR(LARGE(E16:M16,4),0)+IFERROR(LARGE(E16:M16,5),0)+IFERROR(LARGE(E16:M16,6),0)+IFERROR(LARGE(E16:M16,7),0) | O16: 0 | P16: =N16+O16
A17: =RANK(P17,$P$6:$P$45) | B17: Salvador Ivo de Carvalho | C17: 43968 | D17: Sub 14 | E17: ='royal_obidos'!AB23 | F17: ='aroeira_fev'!AX24 | G17: ='ribagolfe'!AX21 | H17: 0 | I17: ='antonio_dantas'!AX21 | J17: 0 | K17: ='race_to_dunas'!AX25 | L17: ='troia'!AX24 | M17: ='aroeira_2'!AX21 | N17: =IFERROR(LARGE(E17:M17,1),0)+IFERROR(LARGE(E17:M17,2),0)+IFERROR(LARGE(E17:M17,3),0)+IFERROR(LARGE(E17:M17,4),0)+IFERROR(LARGE(E17:M17,5),0)+IFERROR(LARGE(E17:M17,6),0)+IFERROR(LARGE(E17:M17,7),0) | O17: ='grande_final'!AX16 | P17: =N17+O17
A18: =RANK(P18,$P$6:$P$45) | B18: Martim Sousa de Morais | C18: 41609 | D18: Sub 23 | E18: ='royal_obidos'!AB24 | F18: ='aroeira_fev'!AX25 | G18: ='ribagolfe'!AX23 | H18: 0 | I18: ='antonio_dantas'!AX30 | J18: 0 | K18: 0 | L18: ='troia'!AX26 | M18: ='aroeira_2'!AX25 | N18: =IFERROR(LARGE(E18:M18,1),0)+IFERROR(LARGE(E18:M18,2),0)+IFERROR(LARGE(E18:M18,3),0)+IFERROR(LARGE(E18:M18,4),0)+IFERROR(LARGE(E18:M18,5),0)+IFERROR(LARGE(E18:M18,6),0)+IFERROR(LARGE(E18:M18,7),0) | O18: ='grande_final'!AX29 | P18: =N18+O18
A19: =RANK(P19,$P$6:$P$45) | B19: Ryan Dantas | C19: 45439 | D19: Sub 14 | E19: ='royal_obidos'!AB25 | F19: ='aroeira_fev'!AX27 | G19: 0 | H19: ='greatgolf'!AX47 | I19: 0 | J19: 0 | K19: 0 | L19: ='troia'!AX32 | M19: ='aroeira_2'!AX28 | N19: =IFERROR(LARGE(E19:M19,1),0)+IFERROR(LARGE(E19:M19,2),0)+IFERROR(LARGE(E19:M19,3),0)+IFERROR(LARGE(E19:M19,4),0)+IFERROR(LARGE(E19:M19,5),0)+IFERROR(LARGE(E19:M19,6),0)+IFERROR(LARGE(E19:M19,7),0) | O19: 0 | P19: =N19+O19
A20: =RANK(P20,$P$6:$P$45) | B20: Rodrigo Faria Constantino | C20: 45278 | D20: Sub 23 | E20: ='royal_obidos'!AB26 | F20: ='aroeira_fev'!AX23 | G20: ='ribagolfe'!AX16 | H20: 0 | I20: ='antonio_dantas'!AX31 | J20: 0 | K20: ='race_to_dunas'!AX19 | L20: ='troia'!AX21 | M20: ='aroeira_2'!AX16 | N20: =IFERROR(LARGE(E20:M20,1),0)+IFERROR(LARGE(E20:M20,2),0)+IFERROR(LARGE(E20:M20,3),0)+IFERROR(LARGE(E20:M20,4),0)+IFERROR(LARGE(E20:M20,5),0)+IFERROR(LARGE(E20:M20,6),0)+IFERROR(LARGE(E20:M20,7),0) | O20: ='grande_final'!AX19 | P20: =N20+O20
A21: =RANK(P21,$P$6:$P$45) | B21: João Rocha | C21: 48297 | D21: Sub 14 | E21: ='royal_obidos'!AB27 | F21: ='aroeira_fev'!AX20 | G21: ='ribagolfe'!AX19 | H21: ='greatgolf'!AX29 | I21: ='antonio_dantas'!AX28 | J21: 0 | K21: ='race_to_dunas'!AX23 | L21: ='troia'!AX19 | M21: 0 | N21: =IFERROR(LARGE(E21:M21,1),0)+IFERROR(LARGE(E21:M21,2),0)+IFERROR(LARGE(E21:M21,3),0)+IFERROR(LARGE(E21:M21,4),0)+IFERROR(LARGE(E21:M21,5),0)+IFERROR(LARGE(E21:M21,6),0)+IFERROR(LARGE(E21:M21,7),0) | O21: ='grande_final'!AX28 | P21: =N21+O21
A22: =RANK(P22,$P$6:$P$45) | B22: Frederico Almeida da Silva | C22: 41613 | D22: Sub 14 | E22: ='royal_obidos'!AB28 | F22: ='aroeira_fev'!AX21 | G22: 0 | H22: 0 | I22: 0 | J22: 0 | K22: 0 | L22: 0 | M22: 0 | N22: =IFERROR(LARGE(E22:M22,1),0)+IFERROR(LARGE(E22:M22,2),0)+IFERROR(LARGE(E22:M22,3),0)+IFERROR(LARGE(E22:M22,4),0)+IFERROR(LARGE(E22:M22,5),0)+IFERROR(LARGE(E22:M22,6),0)+IFERROR(LARGE(E22:M22,7),0) | O22: 0 | P22: =N22+O22
A23: =RANK(P23,$P$6:$P$45) | B23: Manuel Goulartt Medeiros | C23: 52884 | D23: Sub 12 | E23: ='royal_obidos'!AB29 | F23: ='aroeira_fev'!AX26 | G23: ='ribagolfe'!AX24 | H23: ='greatgolf'!AX39 | I23: 0 | J23: ='vale_pisao'!AX18 | K23: ='race_to_dunas'!AX27 | L23: ='troia'!AX20 | M23: ='aroeira_2'!AX26 | N23: =IFERROR(LARGE(E23:M23,1),0)+IFERROR(LARGE(E23:M23,2),0)+IFERROR(LARGE(E23:M23,3),0)+IFERROR(LARGE(E23:M23,4),0)+IFERROR(LARGE(E23:M23,5),0)+IFERROR(LARGE(E23:M23,6),0)+IFERROR(LARGE(E23:M23,7),0) | O23: ='grande_final'!AX26 | P23: =N23+O23
A24: =RANK(P24,$P$6:$P$45) | B24: Luís Pinheiro Jr. | C24: 46590 | D24: Sub 16 | E24: ='royal_obidos'!AB30 | F24: 0 | G24: 0 | H24: ='greatgolf'!AX48 | I24: 0 | J24: 0 | K24: ='race_to_dunas'!AX30 | L24: 0 | M24: 0 | N24: =IFERROR(LARGE(E24:M24,1),0)+IFERROR(LARGE(E24:M24,2),0)+IFERROR(LARGE(E24:M24,3),0)+IFERROR(LARGE(E24:M24,4),0)+IFERROR(LARGE(E24:M24,5),0)+IFERROR(LARGE(E24:M24,6),0)+IFERROR(LARGE(E24:M24,7),0) | O24: 0 | P24: =N24+O24
A25: =RANK(P25,$P$6:$P$45) | B25: Rafaela Pinto | C25: 40390 | D25: Sub 23 | E25: 0 | F25: ='aroeira_fev'!AX12 | G25: ='ribagolfe'!AX15 | H25: ='greatgolf'!AX23 | I25: ='antonio_dantas'!AX29 | J25: 0 | K25: 0 | L25: 0 | M25: ='aroeira_2'!AX24 | N25: =IFERROR(LARGE(E25:M25,1),0)+IFERROR(LARGE(E25:M25,2),0)+IFERROR(LARGE(E25:M25,3),0)+IFERROR(LARGE(E25:M25,4),0)+IFERROR(LARGE(E25:M25,5),0)+IFERROR(LARGE(E25:M25,6),0)+IFERROR(LARGE(E25:M25,7),0) | O25: ='grande_final'!AX15 | P25: =N25+O25
A26: =RANK(P26,$P$6:$P$45) | B26: Tomás Rente | C26: 46311 | D26: Sub 14 | E26: 0 | F26: 0 | G26: 0 | H26: ='greatgolf'!AX25 | I26: 0 | J26: ='vale_pisao'!AX16 | K26: 0 | L26: 0 | M26: 0 | N26: =IFERROR(LARGE(E26:M26,1),0)+IFERROR(LARGE(E26:M26,2),0)+IFERROR(LARGE(E26:M26,3),0)+IFERROR(LARGE(E26:M26,4),0)+IFERROR(LARGE(E26:M26,5),0)+IFERROR(LARGE(E26:M26,6),0)+IFERROR(LARGE(E26:M26,7),0) | O26: 0 | P26: =N26+O26
A27: =RANK(P27,$P$6:$P$45) | B27: David Filip | C27: 51949 | D27: Sub 12 | E27: 0 | F27: 0 | G27: 0 | H27: ='greatgolf'!AX27 | I27: ='antonio_dantas'!AX22 | J27: 0 | K27: 0 | L27: ='troia'!AX23 | M27: ='aroeira_2'!AX18 | N27: =IFERROR(LARGE(E27:M27,1),0)+IFERROR(LARGE(E27:M27,2),0)+IFERROR(LARGE(E27:M27,3),0)+IFERROR(LARGE(E27:M27,4),0)+IFERROR(LARGE(E27:M27,5),0)+IFERROR(LARGE(E27:M27,6),0)+IFERROR(LARGE(E27:M27,7),0) | O27: ='grande_final'!AX14 | P27: =N27+O27
A28: =RANK(P28,$P$6:$P$45) | B28: Tomás Lima Pinto | C28: 46037 | D28: Sub 14 | E28: 0 | F28: 0 | G28: 0 | H28: ='greatgolf'!AX30 | I28: ='antonio_dantas'!AX34 | J28: 0 | K28: 0 | L28: ='troia'!AX30 | M28: 0 | N28: =IFERROR(LARGE(E28:M28,1),0)+IFERROR(LARGE(E28:M28,2),0)+IFERROR(LARGE(E28:M28,3),0)+IFERROR(LARGE(E28:M28,4),0)+IFERROR(LARGE(E28:M28,5),0)+IFERROR(LARGE(E28:M28,6),0)+IFERROR(LARGE(E28:M28,7),0) | O28: ='grande_final'!AX24 | P28: =N28+O28
A29: =RANK(P29,$P$6:$P$45) | B29: Rodrigo Sousa Correia | C29: 44934 | D29: Sub 14 | E29: 0 | F29: 0 | G29: 0 | H29: ='greatgolf'!AX32 | I29: ='antonio_dantas'!AX26 | J29: 0 | K29: ='race_to_dunas'!AX16 | L29: ='troia'!AX16 | M29: 0 | N29: =IFERROR(LARGE(E29:M29,1),0)+IFERROR(LARGE(E29:M29,2),0)+IFERROR(LARGE(E29:M29,3),0)+IFERROR(LARGE(E29:M29,4),0)+IFERROR(LARGE(E29:M29,5),0)+IFERROR(LARGE(E29:M29,6),0)+IFERROR(LARGE(E29:M29,7),0) | O29: ='grande_final'!AX20 | P29: =N29+O29
A30: =RANK(P30,$P$6:$P$45) | B30: Sabrina Ribeiro Crisóstomo | C30: 48971 | D30: Sub 12 | E30: 0 | F30: 0 | G30: 0 | H30: ='greatgolf'!AX33 | I30: ='antonio_dantas'!AX18 | J30: 0 | K30: 0 | L30: 0 | M30: 0 | N30: =IFERROR(LARGE(E30:M30,1),0)+IFERROR(LARGE(E30:M30,2),0)+IFERROR(LARGE(E30:M30,3),0)+IFERROR(LARGE(E30:M30,4),0)+IFERROR(LARGE(E30:M30,5),0)+IFERROR(LARGE(E30:M30,6),0)+IFERROR(LARGE(E30:M30,7),0) | O30: 0 | P30: =N30+O30
A31: =RANK(P31,$P$6:$P$45) | B31: Carlota Braz Gil | C31: 47374 | D31: Sub 14 | E31: 0 | F31: 0 | G31: 0 | H31: ='greatgolf'!AX42 | I31: 0 | J31: 0 | K31: 0 | L31: 0 | M31: 0 | N31: =IFERROR(LARGE(E31:M31,1),0)+IFERROR(LARGE(E31:M31,2),0)+IFERROR(LARGE(E31:M31,3),0)+IFERROR(LARGE(E31:M31,4),0)+IFERROR(LARGE(E31:M31,5),0)+IFERROR(LARGE(E31:M31,6),0)+IFERROR(LARGE(E31:M31,7),0) | O31: 0 | P31: =N31+O31
A32: =RANK(P32,$P$6:$P$45) | B32: Ricardo Serpa | C32: 28845 | D32: Sub 23 | E32: 0 | F32: 0 | G32: 0 | H32: 0 | I32: ='antonio_dantas'!AX14 | J32: 0 | K32: 0 | L32: 0 | M32: 0 | N32: =IFERROR(LARGE(E32:M32,1),0)+IFERROR(LARGE(E32:M32,2),0)+IFERROR(LARGE(E32:M32,3),0)+IFERROR(LARGE(E32:M32,4),0)+IFERROR(LARGE(E32:M32,5),0)+IFERROR(LARGE(E32:M32,6),0)+IFERROR(LARGE(E32:M32,7),0) | O32: 0 | P32: =N32+O32
A33: =RANK(P33,$P$6:$P$45) | B33: Gabriel Fantasia Leite | C33: 33811 | D33: Sub 23 | E33: 0 | F33: 0 | G33: 0 | H33: 0 | I33: ='antonio_dantas'!AX20 | J33: 0 | K33: 0 | L33: 0 | M33: 0 | N33: =IFERROR(LARGE(E33:M33,1),0)+IFERROR(LARGE(E33:M33,2),0)+IFERROR(LARGE(E33:M33,3),0)+IFERROR(LARGE(E33:M33,4),0)+IFERROR(LARGE(E33:M33,5),0)+IFERROR(LARGE(E33:M33,6),0)+IFERROR(LARGE(E33:M33,7),0) | O33: 0 | P33: =N33+O33
A34: =RANK(P34,$P$6:$P$45) | B34: Angelina Gao | C34: 51523 | D34: Sub 14 | E34: 0 | F34: 0 | G34: 0 | H34: 0 | I34: ='antonio_dantas'!AX25 | J34: 0 | K34: ='race_to_dunas'!AX13 | L34: ='troia'!AX28 | M34: 0 | N34: =IFERROR(LARGE(E34:M34,1),0)+IFERROR(LARGE(E34:M34,2),0)+IFERROR(LARGE(E34:M34,3),0)+IFERROR(LARGE(E34:M34,4),0)+IFERROR(LARGE(E34:M34,5),0)+IFERROR(LARGE(E34:M34,6),0)+IFERROR(LARGE(E34:M34,7),0) | O34: 0 | P34: =N34+O34
A35: =RANK(P35,$P$6:$P$45) | B35: Guo Ziyang | C35: 57904 | D35: Sub 12 | E35: 0 | F35: 0 | G35: 0 | H35: 0 | I35: ='antonio_dantas'!AX27 | J35: ='vale_pisao'!AX13 | K35: ='race_to_dunas'!AX21 | L35: ='troia'!AX18 | M35: ='aroeira_2'!AX23 | N35: =IFERROR(LARGE(E35:M35,1),0)+IFERROR(LARGE(E35:M35,2),0)+IFERROR(LARGE(E35:M35,3),0)+IFERROR(LARGE(E35:M35,4),0)+IFERROR(LARGE(E35:M35,5),0)+IFERROR(LARGE(E35:M35,6),0)+IFERROR(LARGE(E35:M35,7),0) | O35: ='grande_final'!AX27 | P35: =N35+O35
A36: =RANK(P36,$P$6:$P$45) | B36: Diogo Sequeira | C36: 56654 | D36: Sub 14 | E36: 0 | F36: 0 | G36: 0 | H36: 0 | I36: ='antonio_dantas'!AX32 | J36: 0 | K36: ='race_to_dunas'!AX28 | L36: ='troia'!AX31 | M36: ='aroeira_2'!AX22 | N36: =IFERROR(LARGE(E36:M36,1),0)+IFERROR(LARGE(E36:M36,2),0)+IFERROR(LARGE(E36:M36,3),0)+IFERROR(LARGE(E36:M36,4),0)+IFERROR(LARGE(E36:M36,5),0)+IFERROR(LARGE(E36:M36,6),0)+IFERROR(LARGE(E36:M36,7),0) | O36: 0 | P36: =N36+O36
A37: =RANK(P37,$P$6:$P$45) | B37: William Gao | C37: 51524 | D37: Sub 14 | E37: 0 | F37: 0 | G37: 0 | H37: 0 | I37: ='antonio_dantas'!AX33 | J37: 0 | K37: ='race_to_dunas'!AX29 | L37: ='troia'!AX33 | M37: 0 | N37: =IFERROR(LARGE(E37:M37,1),0)+IFERROR(LARGE(E37:M37,2),0)+IFERROR(LARGE(E37:M37,3),0)+IFERROR(LARGE(E37:M37,4),0)+IFERROR(LARGE(E37:M37,5),0)+IFERROR(LARGE(E37:M37,6),0)+IFERROR(LARGE(E37:M37,7),0) | O37: 0 | P37: =N37+O37
A38: =RANK(P38,$P$6:$P$45) | B38: Francisco Carvalho | C38: 52856 | D38: Sub 12 | E38: 0 | F38: 0 | G38: 0 | H38: 0 | I38: 0 | J38: ='vale_pisao'!AX14 | K38: ='race_to_dunas'!AX24 | L38: 0 | M38: 0 | N38: =IFERROR(LARGE(E38:M38,1),0)+IFERROR(LARGE(E38:M38,2),0)+IFERROR(LARGE(E38:M38,3),0)+IFERROR(LARGE(E38:M38,4),0)+IFERROR(LARGE(E38:M38,5),0)+IFERROR(LARGE(E38:M38,6),0)+IFERROR(LARGE(E38:M38,7),0) | O38: ='grande_final'!AX22 | P38: =N38+O38
A39: =RANK(P39,$P$6:$P$45) | B39: André Castro Mendes | C39: 55056 | D39: Sub 23 | E39: 0 | F39: 0 | G39: 0 | H39: 0 | I39: 0 | J39: 0 | K39: 0 | L39: ='troia'!AX14 | M39: ='aroeira_2'!AX27 | N39: =IFERROR(LARGE(E39:M39,1),0)+IFERROR(LARGE(E39:M39,2),0)+IFERROR(LARGE(E39:M39,3),0)+IFERROR(LARGE(E39:M39,4),0)+IFERROR(LARGE(E39:M39,5),0)+IFERROR(LARGE(E39:M39,6),0)+IFERROR(LARGE(E39:M39,7),0) | O39: ='grande_final'!AX25 | P39: =N39+O39
A40: =RANK(P40,$P$6:$P$45) | B40: Madalena Figueiredo | C40: 52011 | D40: Sub 16 | E40: 0 | F40: 0 | G40: 0 | H40: 0 | I40: 0 | J40: 0 | K40: 0 | L40: ='troia'!AX29 | M40: 0 | N40: =IFERROR(LARGE(E40:M40,1),0)+IFERROR(LARGE(E40:M40,2),0)+IFERROR(LARGE(E40:M40,3),0)+IFERROR(LARGE(E40:M40,4),0)+IFERROR(LARGE(E40:M40,5),0)+IFERROR(LARGE(E40:M40,6),0)+IFERROR(LARGE(E40:M40,7),0) | O40: 0 | P40: =N40+O40
...

Sheet Sub 12
A1: PJA TOUR 2025 — Ranking Sub 12
A2: Sub-ranking automático filtrado por escalão Sub 12. Totais referenciados directamente do Ranking principal — actualizam dinamicamente.
A4: Pos | B4: Jogador | C4: FedCode | D4: Escalão | E4: TOTAL
A5: =RANK(E5,$E$5:$E$12) | B5: Ricardo Castro Ferreira | C5: 49085 | D5: Sub 12 | E5: =IFERROR(VLOOKUP("49085",Ranking!$C:$P,14,FALSE),0)
A6: =RANK(E6,$E$5:$E$12) | B6: Manuel Goulartt Medeiros | C6: 52884 | D6: Sub 12 | E6: =IFERROR(VLOOKUP("52884",Ranking!$C:$P,14,FALSE),0)
A7: =RANK(E7,$E$5:$E$12) | B7: Guo Ziyang | C7: 57904 | D7: Sub 12 | E7: =IFERROR(VLOOKUP("57904",Ranking!$C:$P,14,FALSE),0)
A8: =RANK(E8,$E$5:$E$12) | B8: David Filip | C8: 51949 | D8: Sub 12 | E8: =IFERROR(VLOOKUP("51949",Ranking!$C:$P,14,FALSE),0)
A9: =RANK(E9,$E$5:$E$12) | B9: Francisco Carvalho | C9: 52856 | D9: Sub 12 | E9: =IFERROR(VLOOKUP("52856",Ranking!$C:$P,14,FALSE),0)
A10: =RANK(E10,$E$5:$E$12) | B10: Miguel Coelho Porfirio | C10: 44160 | D10: Sub 12 | E10: =IFERROR(VLOOKUP("44160",Ranking!$C:$P,14,FALSE),0)
A11: =RANK(E11,$E$5:$E$12) | B11: Sabrina Ribeiro Crisóstomo | C11: 48971 | D11: Sub 12 | E11: =IFERROR(VLOOKUP("48971",Ranking!$C:$P,14,FALSE),0)
A12: =RANK(E12,$E$5:$E$12) | B12: Margarida Silva Pinto | C12: 46310 | D12: Sub 12 | E12: =IFERROR(VLOOKUP("46310",Ranking!$C:$P,14,FALSE),0)

Sheet Sub 14
A1: PJA TOUR 2025 — Ranking Sub 14
A2: Sub-ranking automático filtrado por escalão Sub 14. Totais referenciados directamente do Ranking principal — actualizam dinamicamente.
A4: Pos | B4: Jogador | C4: FedCode | D4: Escalão | E4: TOTAL
A5: =RANK(E5,$E$5:$E$24) | B5: Pedro Costa Alemão | C5: 46706 | D5: Sub 14 | E5: =IFERROR(VLOOKUP("46706",Ranking!$C:$P,14,FALSE),0)
A6: =RANK(E6,$E$5:$E$24) | B6: Nuno Palmares Jr. | C6: 49124 | D6: Sub 14 | E6: =IFERROR(VLOOKUP("49124",Ranking!$C:$P,14,FALSE),0)
A7: =RANK(E7,$E$5:$E$24) | B7: João Setúbal | C7: 43732 | D7: Sub 14 | E7: =IFERROR(VLOOKUP("43732",Ranking!$C:$P,14,FALSE),0)
A8: =RANK(E8,$E$5:$E$24) | B8: João Rocha | C8: 48297 | D8: Sub 14 | E8: =IFERROR(VLOOKUP("48297",Ranking!$C:$P,14,FALSE),0)
A9: =RANK(E9,$E$5:$E$24) | B9: Rafael Gonçales Benesi | C9: 54774 | D9: Sub 14 | E9: =IFERROR(VLOOKUP("54774",Ranking!$C:$P,14,FALSE),0)
A10: =RANK(E10,$E$5:$E$24) | B10: Clara Trindade | C10: 45812 | D10: Sub 14 | E10: =IFERROR(VLOOKUP("45812",Ranking!$C:$P,14,FALSE),0)
A11: =RANK(E11,$E$5:$E$24) | B11: Rodrigo Sousa Correia | C11: 44934 | D11: Sub 14 | E11: =IFERROR(VLOOKUP("44934",Ranking!$C:$P,14,FALSE),0)
A12: =RANK(E12,$E$5:$E$24) | B12: Salvador Ivo de Carvalho | C12: 43968 | D12: Sub 14 | E12: =IFERROR(VLOOKUP("43968",Ranking!$C:$P,14,FALSE),0)
A13: =RANK(E13,$E$5:$E$24) | B13: Filipe Pinheiro | C13: 46591 | D13: Sub 14 | E13: =IFERROR(VLOOKUP("46591",Ranking!$C:$P,14,FALSE),0)
A14: =RANK(E14,$E$5:$E$24) | B14: Santiago Dias | C14: 42908 | D14: Sub 14 | E14: =IFERROR(VLOOKUP("42908",Ranking!$C:$P,14,FALSE),0)
A15: =RANK(E15,$E$5:$E$24) | B15: Tomás Lima Pinto | C15: 46037 | D15: Sub 14 | E15: =IFERROR(VLOOKUP("46037",Ranking!$C:$P,14,FALSE),0)
A16: =RANK(E16,$E$5:$E$24) | B16: Angelina Gao | C16: 51523 | D16: Sub 14 | E16: =IFERROR(VLOOKUP("51523",Ranking!$C:$P,14,FALSE),0)
A17: =RANK(E17,$E$5:$E$24) | B17: Diogo Sequeira | C17: 56654 | D17: Sub 14 | E17: =IFERROR(VLOOKUP("56654",Ranking!$C:$P,14,FALSE),0)
A18: =RANK(E18,$E$5:$E$24) | B18: Tomás Rente | C18: 46311 | D18: Sub 14 | E18: =IFERROR(VLOOKUP("46311",Ranking!$C:$P,14,FALSE),0)
A19: =RANK(E19,$E$5:$E$24) | B19: William Gao | C19: 51524 | D19: Sub 14 | E19: =IFERROR(VLOOKUP("51524",Ranking!$C:$P,14,FALSE),0)
A20: =RANK(E20,$E$5:$E$24) | B20: Ryan Dantas | C20: 45439 | D20: Sub 14 | E20: =IFERROR(VLOOKUP("45439",Ranking!$C:$P,14,FALSE),0)
A21: =RANK(E21,$E$5:$E$24) | B21: Carlota Braz Gil | C21: 47374 | D21: Sub 14 | E21: =IFERROR(VLOOKUP("47374",Ranking!$C:$P,14,FALSE),0)
A22: =RANK(E22,$E$5:$E$24) | B22: Frederico Almeida da Silva | C22: 41613 | D22: Sub 14 | E22: =IFERROR(VLOOKUP("41613",Ranking!$C:$P,14,FALSE),0)
A23: =RANK(E23,$E$5:$E$24) | B23: Francisco Saraiva | C23: 39097 | D23: Sub 14 | E23: =IFERROR(VLOOKUP("39097",Ranking!$C:$P,14,FALSE),0)
A24: =RANK(E24,$E$5:$E$24) | B24: Afonso Silva Pinto | C24: 46309 | D24: Sub 14 | E24: =IFERROR(VLOOKUP("46309",Ranking!$C:$P,14,FALSE),0)

Sheet Sub 16
A1: PJA TOUR 2025 — Ranking Sub 16
A2: Sub-ranking automático filtrado por escalão Sub 16. Totais referenciados directamente do Ranking principal — actualizam dinamicamente.
A4: Pos | B4: Jogador | C4: FedCode | D4: Escalão | E4: TOTAL
A5: =RANK(E5,$E$5:$E$8) | B5: Henrique Almeida da Silva | C5: 41612 | D5: Sub 16 | E5: =IFERROR(VLOOKUP("41612",Ranking!$C:$P,14,FALSE),0)
A6: =RANK(E6,$E$5:$E$8) | B6: Madalena Figueiredo | C6: 52011 | D6: Sub 16 | E6: =IFERROR(VLOOKUP("52011",Ranking!$C:$P,14,FALSE),0)
A7: =RANK(E7,$E$5:$E$8) | B7: Luís Pinheiro Jr. | C7: 46590 | D7: Sub 16 | E7: =IFERROR(VLOOKUP("46590",Ranking!$C:$P,14,FALSE),0)
A8: =RANK(E8,$E$5:$E$8) | B8: Francisca Ferreira da Costa | C8: 40981 | D8: Sub 16 | E8: =IFERROR(VLOOKUP("40981",Ranking!$C:$P,14,FALSE),0)

Sheet Sub 23
A1: PJA TOUR 2025 — Ranking Sub 23
A2: Sub-ranking automático filtrado por escalão Sub 23. Totais referenciados directamente do Ranking principal — actualizam dinamicamente.
A4: Pos | B4: Jogador | C4: FedCode | D4: Escalão | E4: TOTAL
A5: =RANK(E5,$E$5:$E$12) | B5: João Maria Ivo de Carvalho | C5: 38334 | D5: Sub 23 | E5: =IFERROR(VLOOKUP("38334",Ranking!$C:$P,14,FALSE),0)
A6: =RANK(E6,$E$5:$E$12) | B6: Rodrigo Faria Constantino | C6: 45278 | D6: Sub 23 | E6: =IFERROR(VLOOKUP("45278",Ranking!$C:$P,14,FALSE),0)
A7: =RANK(E7,$E$5:$E$12) | B7: Rafaela Pinto | C7: 40390 | D7: Sub 23 | E7: =IFERROR(VLOOKUP("40390",Ranking!$C:$P,14,FALSE),0)
A8: =RANK(E8,$E$5:$E$12) | B8: Martim Sousa de Morais | C8: 41609 | D8: Sub 23 | E8: =IFERROR(VLOOKUP("41609",Ranking!$C:$P,14,FALSE),0)
A9: =RANK(E9,$E$5:$E$12) | B9: André Castro Mendes | C9: 55056 | D9: Sub 23 | E9: =IFERROR(VLOOKUP("55056",Ranking!$C:$P,14,FALSE),0)
A10: =RANK(E10,$E$5:$E$12) | B10: Ricardo Serpa | C10: 28845 | D10: Sub 23 | E10: =IFERROR(VLOOKUP("28845",Ranking!$C:$P,14,FALSE),0)
A11: =RANK(E11,$E$5:$E$12) | B11: Gabriel Fantasia Leite | C11: 33811 | D11: Sub 23 | E11: =IFERROR(VLOOKUP("33811",Ranking!$C:$P,14,FALSE),0)
A12: =RANK(E12,$E$5:$E$12) | B12: Henrique Cunha | C12: 36844 | D12: Sub 23 | E12: =IFERROR(VLOOKUP("36844",Ranking!$C:$P,14,FALSE),0)

Sheet royal_obidos
A1: Royal Óbidos AT&T
A2: Data: | B2: 2025-02-01
A3: Campo: | B3: Royal Óbidos
A4: ccode/tcode: | B4: 152/10444
A5: Link FPG: | B5: https://scoring.datagolf.pt/pt/Classifications.aspx?ccode=152&tcode=10444
A6: Multiplicador: | B6: 1.75
A7: Nota: | B7: Multiplicador especial ×1.75 (torneio anterior cancelado — decidido pela comissão técnica PJA)
A9: Pos | B9: Nome | C9: FedCode | D9: Clube | E9: HCP | F9: R1 h1 | G9: h2 | H9: h3 | I9: h4 | J9: h5 | K9: h6 | L9: h7 | M9: h8 | N9: h9 | O9: h10 | P9: h11 | Q9: h12 | R9: h13 | S9: h14 | T9: h15 | U9: h16 | V9: h17 | W9: h18 | X9: R1 Gross | Y9: R1 Par | Z9: R1 ToPar | AA9: R1 Pts | AB9: Total Pts
A10: —Par— | F10: 4 | G10: 5 | H10: 3 | I10: 4 | J10: 5 | K10: 3 | L10: 5 | M10: 3 | N10: 4 | O10: 4 | P10: 5 | Q10: 4 | R10: 3 | S10: 4 | T10: 3 | U10: 4 | V10: 4 | W10: 5 | Y10: =SUM(F10:W10)
A11: —SI— | F11: 7 | G11: 3 | H11: 13 | I11: 1 | J11: 9 | K11: 15 | L11: 5 | M11: 17 | N11: 11 | O11: 8 | P11: 10 | Q11: 2 | R11: 18 | S11: 6 | T11: 14 | U11: 16 | V11: 12 | W11: 4
A12: 1 | B12: João Maria Ivo de Carvalho | C12: 38334 | D12: Vilamoura, C. G | E12: 2.3 | F12: 5 | G12: 6 | H12: 3 | I12: 5 | J12: 4 | K12: 3 | L12: 5 | M12: 3 | N12: 4 | O12: 5 | P12: 5 | Q12: 4 | R12: 3 | S12: 3 | T12: 2 | U12: 4 | V12: 4 | W12: 4 | X12: =SUM(F12:W12) | Y12: =Y10 | Z12: =X12-Y12 | AA12: =MAX(0,25-Z12)*1.75 | AB12: =AA12
A13: 2 | B13: Santiago Dias | C13: 42908 | D13: Miramar | E13: 2.7 | F13: 5 | G13: 5 | H13: 4 | I13: 4 | J13: 5 | K13: 3 | L13: 5 | M13: 3 | N13: 5 | O13: 6 | P13: 5 | Q13: 4 | R13: 2 | S13: 5 | T13: 3 | U13: 4 | V13: 4 | W13: 5 | X13: =SUM(F13:W13) | Y13: =Y10 | Z13: =X13-Y13 | AA13: =MAX(0,25-Z13)*1.75 | AB13: =AA13
A14: 3 | B14: João Setúbal | C14: 43732 | D14: Vilamoura, C. G | E14: 4.8 | F14: 4 | G14: 5 | H14: 4 | I14: 6 | J14: 5 | K14: 3 | L14: 5 | M14: 3 | N14: 4 | O14: 5 | P14: 5 | Q14: 4 | R14: 3 | S14: 4 | T14: 4 | U14: 4 | V14: 4 | W14: 5 | X14: =SUM(F14:W14) | Y14: =Y10 | Z14: =X14-Y14 | AA14: =MAX(0,25-Z14)*1.75 | AB14: =AA14
A15: 4 | B15: Clara Trindade | C15: 45812 | D15: Belas | E15: 12 | F15: 4 | G15: 5 | H15: 4 | I15: 4 | J15: 5 | K15: 3 | L15: 6 | M15: 4 | N15: 4 | O15: 4 | P15: 5 | Q15: 5 | R15: 3 | S15: 4 | T15: 3 | U15: 7 | V15: 5 | W15: 5 | X15: =SUM(F15:W15) | Y15: =Y10 | Z15: =X15-Y15 | AA15: =MAX(0,25-Z15)*1.75 | AB15: =AA15
A16: 5 | B16: Miguel Coelho Porfirio | C16: 44160 | D16: Miramar | E16: 12 | F16: 5 | G16: 5 | H16: 3 | I16: 5 | J16: 5 | K16: 3 | L16: 5 | M16: 4 | N16: 5 | O16: 5 | P16: 5 | Q16: 5 | R16: 3 | S16: 5 | T16: 3 | U16: 4 | V16: 5 | W16: 6 | X16: =SUM(F16:W16) | Y16: =Y10 | Z16: =X16-Y16 | AA16: =MAX(0,25-Z16)*1.75 | AB16: =AA16
A17: 6 | B17: Henrique Almeida da Silva | C17: 41612 | D17: Belas | E17: 5.8 | F17: 4 | G17: 4 | H17: 3 | I17: 5 | J17: 5 | K17: 3 | L17: 6 | M17: 3 | N17: 5 | O17: 5 | P17: 6 | Q17: 5 | R17: 4 | S17: 7 | T17: 4 | U17: 4 | V17: 4 | W17: 5 | X17: =SUM(F17:W17) | Y17: =Y10 | Z17: =X17-Y17 | AA17: =MAX(0,25-Z17)*1.75 | AB17: =AA17
A18: 7 | B18: Ricardo Castro Ferreira | C18: 49085 | D18: Estoril | E18: 12 | F18: 5 | G18: 7 | H18: 4 | I18: 4 | J18: 5 | K18: 4 | L18: 5 | M18: 4 | N18: 5 | O18: 4 | P18: 5 | Q18: 5 | R18: 3 | S18: 5 | T18: 3 | U18: 4 | V18: 5 | W18: 6 | X18: =SUM(F18:W18) | Y18: =Y10 | Z18: =X18-Y18 | AA18: =MAX(0,25-Z18)*1.75 | AB18: =AA18
A19: 8 | B19: Rafael Gonçales Benesi | C19: 54774 | D19: Estoril | E19: 9.9 | F19: 5 | G19: 5 | H19: 3 | I19: 5 | J19: 6 | K19: 3 | L19: 5 | M19: 4 | N19: 5 | O19: 5 | P19: 5 | Q19: 4 | R19: 2 | S19: 5 | T19: 5 | U19: 4 | V19: 5 | W19: 7 | X19: =SUM(F19:W19) | Y19: =Y10 | Z19: =X19-Y19 | AA19: =MAX(0,25-Z19)*1.75 | AB19: =AA19
A20: 9 | B20: Pedro Costa Alemão | C20: 46706 | D20: Estoril | E20: 8 | F20: 3 | G20: 7 | H20: 3 | I20: 5 | J20: 4 | K20: 3 | L20: 6 | M20: 5 | N20: 6 | O20: 6 | P20: 5 | Q20: 4 | R20: 3 | S20: 6 | T20: 5 | U20: 3 | V20: 4 | W20: 6 | X20: =SUM(F20:W20) | Y20: =Y10 | Z20: =X20-Y20 | AA20: =MAX(0,25-Z20)*1.75 | AB20: =AA20
A21: 10 | B21: Nuno Palmares Jr. | C21: 49124 | D21: Estoril | E21: 7.8 | F21: 6 | G21: 6 | H21: 3 | I21: 6 | J21: 6 | K21: 3 | L21: 5 | M21: 3 | N21: 5 | O21: 5 | P21: 5 | Q21: 5 | R21: 3 | S21: 7 | T21: 3 | U21: 4 | V21: 5 | W21: 7 | X21: =SUM(F21:W21) | Y21: =Y10 | Z21: =X21-Y21 | AA21: =MAX(0,25-Z21)*1.75 | AB21: =AA21
A22: 11 | B22: Filipe Pinheiro | C22: 46591 | D22: Belas | E22: 7.2 | F22: 5 | G22: 6 | H22: 3 | I22: 5 | J22: 6 | K22: 3 | L22: 5 | M22: 4 | N22: 4 | O22: 4 | P22: 6 | Q22: 7 | R22: 4 | S22: 6 | T22: 3 | U22: 5 | V22: 5 | W22: 6 | X22: =SUM(F22:W22) | Y22: =Y10 | Z22: =X22-Y22 | AA22: =MAX(0,25-Z22)*1.75 | AB22: =AA22
A23: 12 | B23: Salvador Ivo de Carvalho | C23: 43968 | D23: Vilamoura, C. G | E23: 9.4 | F23: 5 | G23: 7 | H23: 5 | I23: 5 | J23: 5 | K23: 4 | L23: 5 | M23: 4 | N23: 5 | O23: 4 | P23: 6 | Q23: 5 | R23: 3 | S23: 5 | T23: 3 | U23: 5 | V23: 5 | W23: 7 | X23: =SUM(F23:W23) | Y23: =Y10 | Z23: =X23-Y23 | AA23: =MAX(0,25-Z23)*1.75 | AB23: =AA23
A24: 13 | B24: Martim Sousa de Morais | C24: 41609 | D24: Belas | E24: 7.4 | F24: 4 | G24: 7 | H24: 4 | I24: 5 | J24: 6 | K24: 3 | L24: 7 | M24: 4 | N24: 5 | O24: 6 | P24: 5 | Q24: 6 | R24: 4 | S24: 5 | T24: 5 | U24: 4 | V24: 5 | W24: 8 | X24: =SUM(F24:W24) | Y24: =Y10 | Z24: =X24-Y24 | AA24: =MAX(0,25-Z24)*1.75 | AB24: =AA24
A25: 14 | B25: Ryan Dantas | C25: 45439 | D25: Clube Benfica | E25: 13.4 | F25: 6 | G25: 6 | H25: 3 | I25: 7 | J25: 5 | K25: 4 | L25: 10 | M25: 3 | N25: 5 | O25: 5 | P25: 5 | Q25: 7 | R25: 5 | S25: 4 | T25: 3 | U25: 5 | V25: 6 | W25: 5 | X25: =SUM(F25:W25) | Y25: =Y10 | Z25: =X25-Y25 | AA25: =MAX(0,25-Z25)*1.75 | AB25: =AA25
A26: 15 | B26: Rodrigo Faria Constantino | C26: 45278 | D26: Belas | E26: 5.6 | F26: 5 | G26: 6 | H26: 3 | I26: 6 | J26: 5 | K26: 3 | L26: 6 | M26: 4 | N26: 10 | O26: 5 | P26: 5 | Q26: 4 | R26: 3 | S26: 5 | T26: 8 | U26: 5 | V26: 5 | W26: 6 | X26: =SUM(F26:W26) | Y26: =Y10 | Z26: =X26-Y26 | AA26: =MAX(0,25-Z26)*1.75 | AB26: =AA26
A27: 16 | B27: João Rocha | C27: 48297 | D27: Estoril | E27: 9.5 | F27: 6 | G27: 9 | H27: 4 | I27: 6 | J27: 4 | K27: 3 | L27: 6 | M27: 4 | N27: 7 | O27: 5 | P27: 5 | Q27: 6 | R27: 4 | S27: 5 | T27: 4 | U27: 5 | V27: 5 | W27: 7 | X27: =SUM(F27:W27) | Y27: =Y10 | Z27: =X27-Y27 | AA27: =MAX(0,25-Z27)*1.75 | AB27: =AA27
A28: 17 | B28: Frederico Almeida da Silva | C28: 41613 | D28: Belas | E28: 8.7 | F28: 4 | G28: 7 | H28: 5 | I28: 5 | J28: 6 | K28: 3 | L28: 5 | M28: 4 | N28: 5 | O28: 6 | P28: 8 | Q28: 10 | R28: 4 | S28: 5 | T28: 8 | U28: 4 | V28: 5 | W28: 9 | X28: =SUM(F28:W28) | Y28: =Y10 | Z28: =X28-Y28 | AA28: =MAX(0,25-Z28)*1.75 | AB28: =AA28
A29: 18 | B29: Manuel Goulartt Medeiros | C29: 52884 | D29: Santo da Serra | E29: 17.6 | F29: 5 | G29: 8 | H29: 3 | I29: 5 | J29: 7 | K29: 5 | L29: 7 | M29: 5 | N29: 6 | O29: 6 | P29: 4 | Q29: 8 | R29: 5 | S29: 5 | T29: 6 | U29: 7 | V29: 5 | W29: 7 | X29: =SUM(F29:W29) | Y29: =Y10 | Z29: =X29-Y29 | AA29: =MAX(0,25-Z29)*1.75 | AB29: =AA29
A30: 19 | B30: Luís Pinheiro Jr. | C30: 46590 | D30: Belas | E30: 19.3 | F30: 5 | G30: 7 | H30: 5 | I30: 7 | J30: 6 | K30: 4 | L30: 7 | M30: 3 | N30: 7 | O30: 4 | P30: 6 | Q30: 4 | R30: 7 | S30: 6 | T30: 7 | U30: 6 | V30: 6 | W30: 9 | X30: =SUM(F30:W30) | Y30: =Y10 | Z30: =X30-Y30 | AA30: =MAX(0,25-Z30)*1.75 | AB30: =AA30
A31: NS | B31: Francisca Ferreira da Costa | D31: Miramar | E31: 2 | AA31: 0 | AB31: =AA31
A32: NS | B32: Carlota Braz Gil | D32: Santo da Serra | E32: 12.5 | AA32: 0 | AB32: =AA32

Sheet aroeira_fev
A1: Aroeira Master by Details (Fev)
A2: Data: | B2: 2025-02-15
A3: Campo: | B3: PGA Aroeira No.2
A4: ccode/tcode: | B4: 029/10492
A5: Link FPG: | B5: https://scoring.datagolf.pt/pt/Classifications.aspx?ccode=029&tcode=10492
A6: Multiplicador: | B6: 1
A9: Pos | B9: Nome | C9: FedCode | D9: Clube | E9: HCP | F9: R1 h1 | G9: h2 | H9: h3 | I9: h4 | J9: h5 | K9: h6 | L9: h7 | M9: h8 | N9: h9 | O9: h10 | P9: h11 | Q9: h12 | R9: h13 | S9: h14 | T9: h15 | U9: h16 | V9: h17 | W9: h18 | X9: R1 Gross | Y9: R1 Par | Z9: R1 ToPar | AA9: R1 Pts | AB9: R2 h1 | AC9: h2 | AD9: h3 | AE9: h4 | AF9: h5 | AG9: h6 | AH9: h7 | AI9: h8 | AJ9: h9 | AK9: h10 | AL9: h11 | AM9: h12 | AN9: h13 | AO9: h14 | AP9: h15 | AQ9: h16 | AR9: h17 | AS9: h18 | AT9: R2 Gross | AU9: R2 Par | AV9: R2 ToPar | AW9: R2 Pts | AX9: Total Pts
A10: —Par— | F10: 4 | G10: 5 | H10: 4 | I10: 5 | J10: 3 | K10: 4 | L10: 4 | M10: 3 | N10: 4 | O10: 4 | P10: 5 | Q10: 3 | R10: 4 | S10: 3 | T10: 4 | U10: 4 | V10: 4 | W10: 5 | Y10: =SUM(F10:W10) | AB10: 5 | AC10: 4 | AD10: 4 | AE10: 3 | AF10: 4 | AG10: 4 | AH10: 4 | AI10: 3 | AJ10: 5 | AK10: 5 | AL10: 4 | AM10: 4 | AN10: 4 | AO10: 3 | AP10: 5 | AQ10: 3 | AR10: 4 | AS10: 4 | AU10: =SUM(AB10:AS10)
A11: —SI— | F11: 11 | G11: 3 | H11: 15 | I11: 1 | J11: 13 | K11: 7 | L11: 5 | M11: 17 | N11: 9 | O11: 10 | P11: 6 | Q11: 14 | R11: 16 | S11: 4 | T11: 18 | U11: 8 | V11: 2 | W11: 12 | AB11: 11 | AC11: 1 | AD11: 5 | AE11: 17 | AF11: 9 | AG11: 15 | AH11: 7 | AI11: 3 | AJ11: 13 | AK11: 4 | AL11: 2 | AM11: 12 | AN11: 6 | AO11: 18 | AP11: 14 | AQ11: 16 | AR11: 10 | AS11: 8
A12: 1 | B12: Rafaela Pinto | C12: 40390 | D12: Arquitectos | E12: 1.4 | F12: 4 | G12: 5 | H12: 4 | I12: 4 | J12: 3 | K12: 5 | L12: 4 | M12: 3 | N12: 4 | O12: 6 | P12: 4 | Q12: 2 | R12: 4 | S12: 2 | T12: 4 | U12: 4 | V12: 5 | W12: 4 | X12: =SUM(F12:W12) | Y12: =Y10 | Z12: =X12-Y12 | AA12: =MAX(0,25-Z12)*1.0 | AB12: 5 | AC12: 4 | AD12: 4 | AE12: 5 | AF12: 4 | AG12: 5 | AH12: 4 | AI12: 3 | AJ12: 5 | AK12: 5 | AL12: 4 | AM12: 5 | AN12: 4 | AO12: 3 | AP12: 6 | AQ12: 5 | AR12: 4 | AS12: 5 | AT12: =SUM(AB12:AS12) | AU12: =AU10 | AV12: =AT12-AU12 | AW12: =MAX(0,25-AV12)*1.0 | AX12: =AA12+AW12
A13: 2 | B13: Ricardo Castro Ferreira | C13: 49085 | D13: Estoril | E13: 11.9 | F13: 4 | G13: 5 | H13: 4 | I13: 5 | J13: 3 | K13: 4 | L13: 4 | M13: 2 | N13: 4 | O13: 4 | P13: 5 | Q13: 3 | R13: 4 | S13: 2 | T13: 6 | U13: 4 | V13: 6 | W13: 5 | X13: =SUM(F13:W13) | Y13: =Y10 | Z13: =X13-Y13 | AA13: =MAX(0,25-Z13)*1.0 | AB13: 6 | AC13: 5 | AD13: 5 | AE13: 3 | AF13: 4 | AG13: 4 | AH13: 5 | AI13: 3 | AJ13: 6 | AK13: 5 | AL13: 6 | AM13: 5 | AN13: 5 | AO13: 3 | AP13: 7 | AQ13: 3 | AR13: 4 | AS13: 4 | AT13: =SUM(AB13:AS13) | AU13: =AU10 | AV13: =AT13-AU13 | AW13: =MAX(0,25-AV13)*1.0 | AX13: =AA13+AW13
A14: 3 | B14: João Maria Ivo de Carvalho | C14: 38334 | D14: Vilamoura, C. G | E14: 1.8 | F14: 4 | G14: 5 | H14: 4 | I14: 5 | J14: 4 | K14: 3 | L14: 5 | M14: 5 | N14: 6 | O14: 4 | P14: 6 | Q14: 3 | R14: 3 | S14: 3 | T14: 5 | U14: 5 | V14: 4 | W14: 5 | X14: =SUM(F14:W14) | Y14: =Y10 | Z14: =X14-Y14 | AA14: =MAX(0,25-Z14)*1.0 | AB14: 4 | AC14: 4 | AD14: 4 | AE14: 3 | AF14: 4 | AG14: 4 | AH14: 4 | AI14: 3 | AJ14: 5 | AK14: 5 | AL14: 4 | AM14: 4 | AN14: 3 | AO14: 3 | AP14: 4 | AQ14: 3 | AR14: 4 | AS14: 4 | AT14: =SUM(AB14:AS14) | AU14: =AU10 | AV14: =AT14-AU14 | AW14: =MAX(0,25-AV14)*1.0 | AX14: =AA14+AW14
A15: 4 | B15: Pedro Costa Alemão | C15: 46706 | D15: Estoril | E15: 8 | F15: 6 | G15: 7 | H15: 4 | I15: 5 | J15: 3 | K15: 4 | L15: 5 | M15: 4 | N15: 5 | O15: 5 | P15: 6 | Q15: 3 | R15: 4 | S15: 4 | T15: 4 | U15: 3 | V15: 4 | W15: 5 | X15: =SUM(F15:W15) | Y15: =Y10 | Z15: =X15-Y15 | AA15: =MAX(0,25-Z15)*1.0 | AB15: 5 | AC15: 5 | AD15: 7 | AE15: 3 | AF15: 5 | AG15: 4 | AH15: 6 | AI15: 3 | AJ15: 5 | AK15: 5 | AL15: 5 | AM15: 4 | AN15: 4 | AO15: 3 | AP15: 5 | AQ15: 3 | AR15: 4 | AS15: 5 | AT15: =SUM(AB15:AS15) | AU15: =AU10 | AV15: =AT15-AU15 | AW15: =MAX(0,25-AV15)*1.0 | AX15: =AA15+AW15
A16: 5 | B16: Rafael Gonçales Benesi | C16: 54774 | D16: Estoril | E16: 9.4 | F16: 5 | G16: 5 | H16: 5 | I16: 5 | J16: 3 | K16: 4 | L16: 6 | M16: 3 | N16: 4 | O16: 4 | P16: 6 | Q16: 4 | R16: 4 | S16: 6 | T16: 4 | U16: 4 | V16: 4 | W16: 6 | X16: =SUM(F16:W16) | Y16: =Y10 | Z16: =X16-Y16 | AA16: =MAX(0,25-Z16)*1.0 | AB16: 5 | AC16: 6 | AD16: 5 | AE16: 4 | AF16: 4 | AG16: 5 | AH16: 5 | AI16: 4 | AJ16: 6 | AK16: 5 | AL16: 6 | AM16: 4 | AN16: 4 | AO16: 4 | AP16: 6 | AQ16: 3 | AR16: 5 | AS16: 4 | AT16: =SUM(AB16:AS16) | AU16: =AU10 | AV16: =AT16-AU16 | AW16: =MAX(0,25-AV16)*1.0 | AX16: =AA16+AW16
A17: 6 | B17: Miguel Coelho Porfirio | C17: 44160 | D17: Miramar | E17: 11.9 | F17: 5 | G17: 6 | H17: 5 | I17: 6 | J17: 3 | K17: 5 | L17: 4 | M17: 4 | N17: 4 | O17: 4 | P17: 6 | Q17: 3 | R17: 5 | S17: 3 | T17: 5 | U17: 5 | V17: 5 | W17: 5 | X17: =SUM(F17:W17) | Y17: =Y10 | Z17: =X17-Y17 | AA17: =MAX(0,25-Z17)*1.0 | AB17: 6 | AC17: 5 | AD17: 4 | AE17: 3 | AF17: 5 | AG17: 3 | AH17: 6 | AI17: 4 | AJ17: 6 | AK17: 4 | AL17: 4 | AM17: 5 | AN17: 4 | AO17: 3 | AP17: 5 | AQ17: 3 | AR17: 4 | AS17: 4 | AT17: =SUM(AB17:AS17) | AU17: =AU10 | AV17: =AT17-AU17 | AW17: =MAX(0,25-AV17)*1.0 | AX17: =AA17+AW17
A18: 7 | B18: Nuno Palmares Jr. | C18: 49124 | D18: Estoril | E18: 7.8 | F18: 5 | G18: 6 | H18: 4 | I18: 6 | J18: 3 | K18: 5 | L18: 5 | M18: 4 | N18: 9 | O18: 4 | P18: 6 | Q18: 3 | R18: 5 | S18: 2 | T18: 5 | U18: 4 | V18: 6 | W18: 5 | X18: =SUM(F18:W18) | Y18: =Y10 | Z18: =X18-Y18 | AA18: =MAX(0,25-Z18)*1.0 | AB18: 6 | AC18: 6 | AD18: 5 | AE18: 3 | AF18: 5 | AG18: 5 | AH18: 5 | AI18: 4 | AJ18: 6 | AK18: 5 | AL18: 4 | AM18: 4 | AN18: 4 | AO18: 4 | AP18: 5 | AQ18: 4 | AR18: 4 | AS18: 4 | AT18: =SUM(AB18:AS18) | AU18: =AU10 | AV18: =AT18-AU18 | AW18: =MAX(0,25-AV18)*1.0 | AX18: =AA18+AW18
A19: 8 | B19: Clara Trindade | C19: 45812 | D19: Belas | E19: 11.1 | F19: 4 | G19: 5 | H19: 5 | I19: 6 | J19: 3 | K19: 4 | L19: 5 | M19: 4 | N19: 7 | O19: 5 | P19: 8 | Q19: 2 | R19: 3 | S19: 5 | T19: 7 | U19: 4 | V19: 5 | W19: 5 | X19: =SUM(F19:W19) | Y19: =Y10 | Z19: =X19-Y19 | AA19: =MAX(0,25-Z19)*1.0 | AB19: 6 | AC19: 6 | AD19: 4 | AE19: 3 | AF19: 5 | AG19: 4 | AH19: 5 | AI19: 3 | AJ19: 6 | AK19: 6 | AL19: 6 | AM19: 6 | AN19: 4 | AO19: 3 | AP19: 5 | AQ19: 3 | AR19: 4 | AS19: 4 | AT19: =SUM(AB19:AS19) | AU19: =AU10 | AV19: =AT19-AU19 | AW19: =MAX(0,25-AV19)*1.0 | AX19: =AA19+AW19
A20: 9 | B20: João Rocha | C20: 48297 | D20: Estoril | E20: 9.5 | F20: 6 | G20: 7 | H20: 5 | I20: 7 | J20: 3 | K20: 5 | L20: 5 | M20: 4 | N20: 5 | O20: 5 | P20: 6 | Q20: 4 | R20: 4 | S20: 4 | T20: 4 | U20: 4 | V20: 5 | W20: 5 | X20: =SUM(F20:W20) | Y20: =Y10 | Z20: =X20-Y20 | AA20: =MAX(0,25-Z20)*1.0 | AB20: 5 | AC20: 5 | AD20: 5 | AE20: 5 | AF20: 5 | AG20: 4 | AH20: 5 | AI20: 4 | AJ20: 7 | AK20: 6 | AL20: 4 | AM20: 5 | AN20: 4 | AO20: 4 | AP20: 5 | AQ20: 3 | AR20: 4 | AS20: 5 | AT20: =SUM(AB20:AS20) | AU20: =AU10 | AV20: =AT20-AU20 | AW20: =MAX(0,25-AV20)*1.0 | AX20: =AA20+AW20
A21: 10 | B21: Frederico Almeida da Silva | C21: 41613 | D21: Belas | E21: 8.7 | F21: 5 | G21: 6 | H21: 4 | I21: 6 | J21: 3 | K21: 4 | L21: 4 | M21: 4 | N21: 7 | O21: 6 | P21: 6 | Q21: 2 | R21: 5 | S21: 4 | T21: 5 | U21: 5 | V21: 6 | W21: 6 | X21: =SUM(F21:W21) | Y21: =Y10 | Z21: =X21-Y21 | AA21: =MAX(0,25-Z21)*1.0 | AW21: 0 | AX21: =AA21+AW21
A22: 11 | B22: Filipe Pinheiro | C22: 46591 | D22: Belas | E22: 7.2 | F22: 6 | G22: 5 | H22: 5 | I22: 5 | J22: 4 | K22: 4 | L22: 4 | M22: 3 | N22: 5 | O22: 6 | P22: 7 | Q22: 5 | R22: 5 | S22: 5 | T22: 4 | U22: 5 | V22: 6 | W22: 6 | X22: =SUM(F22:W22) | Y22: =Y10 | Z22: =X22-Y22 | AA22: =MAX(0,25-Z22)*1.0 | AB22: 4 | AC22: 5 | AD22: 5 | AE22: 3 | AF22: 4 | AG22: 4 | AH22: 4 | AI22: 5 | AJ22: 5 | AK22: 6 | AL22: 6 | AM22: 5 | AN22: 4 | AO22: 4 | AP22: 6 | AQ22: 3 | AR22: 4 | AS22: 4 | AT22: =SUM(AB22:AS22) | AU22: =AU10 | AV22: =AT22-AU22 | AW22: =MAX(0,25-AV22)*1.0 | AX22: =AA22+AW22
A23: 12 | B23: Rodrigo Faria Constantino | C23: 45278 | D23: Belas | E23: 5.7 | F23: 4 | G23: 6 | H23: 6 | I23: 7 | J23: 5 | K23: 5 | L23: 7 | M23: 4 | N23: 4 | O23: 4 | P23: 6 | Q23: 6 | R23: 4 | S23: 4 | T23: 4 | U23: 6 | V23: 6 | W23: 5 | X23: =SUM(F23:W23) | Y23: =Y10 | Z23: =X23-Y23 | AA23: =MAX(0,25-Z23)*1.0 | AB23: 4 | AC23: 5 | AD23: 5 | AE23: 4 | AF23: 4 | AG23: 4 | AH23: 4 | AI23: 4 | AJ23: 5 | AK23: 8 | AL23: 4 | AM23: 7 | AN23: 4 | AO23: 3 | AP23: 4 | AQ23: 3 | AR23: 4 | AS23: 7 | AT23: =SUM(AB23:AS23) | AU23: =AU10 | AV23: =AT23-AU23 | AW23: =MAX(0,25-AV23)*1.0 | AX23: =AA23+AW23
A24: 13 | B24: Salvador Ivo de Carvalho | C24: 43968 | D24: Vilamoura, C. G | E24: 9.5 | F24: 6 | G24: 6 | H24: 4 | I24: 7 | J24: 2 | K24: 6 | L24: 5 | M24: 3 | N24: 5 | O24: 6 | P24: 7 | Q24: 4 | R24: 5 | S24: 4 | T24: 5 | U24: 6 | V24: 5 | W24: 7 | X24: =SUM(F24:W24) | Y24: =Y10 | Z24: =X24-Y24 | AA24: =MAX(0,25-Z24)*1.0 | AB24: 5 | AC24: 5 | AD24: 5 | AE24: 3 | AF24: 5 | AG24: 4 | AH24: 5 | AI24: 3 | AJ24: 7 | AK24: 6 | AL24: 4 | AM24: 5 | AN24: 5 | AO24: 4 | AP24: 6 | AQ24: 4 | AR24: 4 | AS24: 5 | AT24: =SUM(AB24:AS24) | AU24: =AU10 | AV24: =AT24-AU24 | AW24: =MAX(0,25-AV24)*1.0 | AX24: =AA24+AW24
A25: 14 | B25: Martim Sousa de Morais | C25: 41609 | D25: Belas | E25: 7.4 | F25: 5 | G25: 7 | H25: 5 | I25: 7 | J25: 5 | K25: 5 | L25: 6 | M25: 5 | N25: 4 | O25: 4 | P25: 6 | Q25: 5 | R25: 4 | S25: 5 | T25: 5 | U25: 5 | V25: 7 | W25: 6 | X25: =SUM(F25:W25) | Y25: =Y10 | Z25: =X25-Y25 | AA25: =MAX(0,25-Z25)*1.0 | AB25: 5 | AC25: 5 | AD25: 5 | AE25: 5 | AF25: 4 | AG25: 5 | AH25: 4 | AI25: 4 | AJ25: 6 | AK25: 5 | AL25: 4 | AM25: 3 | AN25: 4 | AO25: 3 | AP25: 5 | AQ25: 4 | AR25: 4 | AS25: 5 | AT25: =SUM(AB25:AS25) | AU25: =AU10 | AV25: =AT25-AU25 | AW25: =MAX(0,25-AV25)*1.0 | AX25: =AA25+AW25
A26: 15 | B26: Manuel Goulartt Medeiros | C26: 52884 | D26: Santo da Serra | E26: 18 | F26: 4 | G26: 8 | H26: 4 | I26: 6 | J26: 4 | K26: 6 | L26: 3 | M26: 6 | N26: 5 | O26: 6 | P26: 8 | Q26: 9 | R26: 4 | S26: 3 | T26: 5 | U26: 6 | V26: 5 | W26: 7 | X26: =SUM(F26:W26) | Y26: =Y10 | Z26: =X26-Y26 | AA26: =MAX(0,25-Z26)*1.0 | AB26: 7 | AC26: 7 | AD26: 6 | AE26: 4 | AF26: 5 | AG26: 6 | AH26: 6 | AI26: 3 | AJ26: 6 | AK26: 6 | AL26: 5 | AM26: 4 | AN26: 6 | AO26: 3 | AP26: 7 | AQ26: 6 | AR26: 5 | AS26: 6 | AT26: =SUM(AB26:AS26) | AU26: =AU10 | AV26: =AT26-AU26 | AW26: =MAX(0,25-AV26)*1.0 | AX26: =AA26+AW26
A27: ND | B27: Ryan Dantas | C27: 45439 | D27: Belas | E27: 13.4 | AA27: 0 | AW27: 0 | AX27: =AA27+AW27
A28: NS | B28: Henrique Almeida da Silva | D28: Belas | E28: 5.6 | AA28: 0 | AW28: 0 | AX28: =AA28+AW28

Sheet ribagolfe
A1: Ribagolfe Oaks Masters
A2: Data: | B2: 2025-02-22
A3: Campo: | B3: Ribagolfe Oaks
A4: ccode/tcode: | B4: 191/10036
A5: Link FPG: | B5: https://scoring.datagolf.pt/pt/Classifications.aspx?ccode=191&tcode=10036
A6: Multiplicador: | B6: 1
A9: Pos | B9: Nome | C9: FedCode | D9: Clube | E9: HCP | F9: R1 h1 | G9: h2 | H9: h3 | I9: h4 | J9: h5 | K9: h6 | L9: h7 | M9: h8 | N9: h9 | O9: h10 | P9: h11 | Q9: h12 | R9: h13 | S9: h14 | T9: h15 | U9: h16 | V9: h17 | W9: h18 | X9: R1 Gross | Y9: R1 Par | Z9: R1 ToPar | AA9: R1 Pts | AB9: R2 h1 | AC9: h2 | AD9: h3 | AE9: h4 | AF9: h5 | AG9: h6 | AH9: h7 | AI9: h8 | AJ9: h9 | AK9: h10 | AL9: h11 | AM9: h12 | AN9: h13 | AO9: h14 | AP9: h15 | AQ9: h16 | AR9: h17 | AS9: h18 | AT9: R2 Gross | AU9: R2 Par | AV9: R2 ToPar | AW9: R2 Pts | AX9: Total Pts
A10: —Par— | F10: 5 | G10: 4 | H10: 3 | I10: 4 | J10: 3 | K10: 4 | L10: 4 | M10: 5 | N10: 4 | O10: 4 | P10: 4 | Q10: 3 | R10: 5 | S10: 4 | T10: 3 | U10: 4 | V10: 4 | W10: 5 | Y10: =SUM(F10:W10) | AB10: 5 | AC10: 4 | AD10: 3 | AE10: 4 | AF10: 3 | AG10: 4 | AH10: 4 | AI10: 5 | AJ10: 4 | AK10: 4 | AL10: 4 | AM10: 3 | AN10: 5 | AO10: 4 | AP10: 3 | AQ10: 4 | AR10: 4 | AS10: 5 | AU10: =SUM(AB10:AS10)
A11: —SI— | F11: 13 | G11: 15 | H11: 7 | I11: 5 | J11: 17 | K11: 3 | L11: 1 | M11: 9 | N11: 11 | O11: 2 | P11: 10 | Q11: 16 | R11: 4 | S11: 18 | T11: 14 | U11: 6 | V11: 8 | W11: 12 | AB11: 13 | AC11: 15 | AD11: 7 | AE11: 5 | AF11: 17 | AG11: 3 | AH11: 1 | AI11: 9 | AJ11: 11 | AK11: 2 | AL11: 10 | AM11: 16 | AN11: 4 | AO11: 18 | AP11: 14 | AQ11: 6 | AR11: 8 | AS11: 12
A12: 1 | B12: João Maria Ivo de Carvalho | C12: 38334 | D12: Vilamoura, C. G | E12: 1.6 | F12: 5 | G12: 4 | H12: 4 | I12: 4 | J12: 3 | K12: 4 | L12: 5 | M12: 5 | N12: 4 | O12: 6 | P12: 4 | Q12: 3 | R12: 5 | S12: 4 | T12: 4 | U12: 5 | V12: 3 | W12: 4 | X12: =SUM(F12:W12) | Y12: =Y10 | Z12: =X12-Y12 | AA12: =MAX(0,25-Z12)*1.0 | AB12: 5 | AC12: 4 | AD12: 4 | AE12: 6 | AF12: 3 | AG12: 4 | AH12: 4 | AI12: 4 | AJ12: 4 | AK12: 4 | AL12: 3 | AM12: 5 | AN12: 6 | AO12: 4 | AP12: 3 | AQ12: 5 | AR12: 5 | AS12: 5 | AT12: =SUM(AB12:AS12) | AU12: =AU10 | AV12: =AT12-AU12 | AW12: =MAX(0,25-AV12)*1.0 | AX12: =AA12+AW12
A13: 2 | B13: Rafael Gonçales Benesi | C13: 54774 | D13: Estoril | E13: 9.5 | F13: 5 | G13: 4 | H13: 2 | I13: 4 | J13: 3 | K13: 4 | L13: 6 | M13: 5 | N13: 4 | O13: 3 | P13: 5 | Q13: 3 | R13: 6 | S13: 5 | T13: 3 | U13: 5 | V13: 4 | W13: 5 | X13: =SUM(F13:W13) | Y13: =Y10 | Z13: =X13-Y13 | AA13: =MAX(0,25-Z13)*1.0 | AB13: 5 | AC13: 4 | AD13: 3 | AE13: 4 | AF13: 3 | AG13: 4 | AH13: 5 | AI13: 5 | AJ13: 5 | AK13: 4 | AL13: 5 | AM13: 3 | AN13: 5 | AO13: 5 | AP13: 4 | AQ13: 4 | AR13: 5 | AS13: 5 | AT13: =SUM(AB13:AS13) | AU13: =AU10 | AV13: =AT13-AU13 | AW13: =MAX(0,25-AV13)*1.0 | AX13: =AA13+AW13
A14: 3 | B14: Pedro Costa Alemão | C14: 46706 | D14: Estoril | E14: 7.8 | F14: 5 | G14: 4 | H14: 3 | I14: 4 | J14: 3 | K14: 4 | L14: 4 | M14: 5 | N14: 4 | O14: 5 | P14: 4 | Q14: 3 | R14: 6 | S14: 4 | T14: 4 | U14: 5 | V14: 4 | W14: 6 | X14: =SUM(F14:W14) | Y14: =Y10 | Z14: =X14-Y14 | AA14: =MAX(0,25-Z14)*1.0 | AB14: 5 | AC14: 4 | AD14: 4 | AE14: 4 | AF14: 3 | AG14: 6 | AH14: 4 | AI14: 4 | AJ14: 5 | AK14: 5 | AL14: 4 | AM14: 3 | AN14: 7 | AO14: 4 | AP14: 4 | AQ14: 5 | AR14: 4 | AS14: 5 | AT14: =SUM(AB14:AS14) | AU14: =AU10 | AV14: =AT14-AU14 | AW14: =MAX(0,25-AV14)*1.0 | AX14: =AA14+AW14
A15: 4 | B15: Rafaela Pinto | C15: 40390 | D15: Arquitectos | E15: 1 | F15: 7 | G15: 5 | H15: 3 | I15: 4 | J15: 3 | K15: 5 | L15: 4 | M15: 5 | N15: 4 | O15: 4 | P15: 4 | Q15: 3 | R15: 6 | S15: 3 | T15: 3 | U15: 4 | V15: 5 | W15: 6 | X15: =SUM(F15:W15) | Y15: =Y10 | Z15: =X15-Y15 | AA15: =MAX(0,25-Z15)*1.0 | AB15: 5 | AC15: 4 | AD15: 4 | AE15: 4 | AF15: 3 | AG15: 4 | AH15: 5 | AI15: 5 | AJ15: 5 | AK15: 4 | AL15: 4 | AM15: 3 | AN15: 9 | AO15: 5 | AP15: 2 | AQ15: 6 | AR15: 4 | AS15: 5 | AT15: =SUM(AB15:AS15) | AU15: =AU10 | AV15: =AT15-AU15 | AW15: =MAX(0,25-AV15)*1.0 | AX15: =AA15+AW15
A16: 5 | B16: Rodrigo Faria Constantino | C16: 45278 | D16: Belas | E16: 5.7 | F16: 6 | G16: 4 | H16: 3 | I16: 5 | J16: 3 | K16: 4 | L16: 3 | M16: 5 | N16: 5 | O16: 3 | P16: 6 | Q16: 3 | R16: 7 | S16: 4 | T16: 4 | U16: 4 | V16: 5 | W16: 6 | X16: =SUM(F16:W16) | Y16: =Y10 | Z16: =X16-Y16 | AA16: =MAX(0,25-Z16)*1.0 | AB16: 6 | AC16: 4 | AD16: 3 | AE16: 4 | AF16: 4 | AG16: 5 | AH16: 5 | AI16: 5 | AJ16: 4 | AK16: 5 | AL16: 6 | AM16: 3 | AN16: 5 | AO16: 4 | AP16: 3 | AQ16: 6 | AR16: 4 | AS16: 6 | AT16: =SUM(AB16:AS16) | AU16: =AU10 | AV16: =AT16-AU16 | AW16: =MAX(0,25-AV16)*1.0 | AX16: =AA16+AW16
A17: 6 | B17: Ricardo Castro Ferreira | C17: 49085 | D17: Estoril | E17: 11.6 | F17: 5 | G17: 4 | H17: 4 | I17: 4 | J17: 3 | K17: 5 | L17: 4 | M17: 6 | N17: 5 | O17: 4 | P17: 4 | Q17: 4 | R17: 6 | S17: 4 | T17: 4 | U17: 5 | V17: 4 | W17: 6 | X17: =SUM(F17:W17) | Y17: =Y10 | Z17: =X17-Y17 | AA17: =MAX(0,25-Z17)*1.0 | AB17: 7 | AC17: 6 | AD17: 3 | AE17: 4 | AF17: 3 | AG17: 4 | AH17: 4 | AI17: 4 | AJ17: 5 | AK17: 5 | AL17: 5 | AM17: 4 | AN17: 6 | AO17: 4 | AP17: 2 | AQ17: 6 | AR17: 5 | AS17: 6 | AT17: =SUM(AB17:AS17) | AU17: =AU10 | AV17: =AT17-AU17 | AW17: =MAX(0,25-AV17)*1.0 | AX17: =AA17+AW17
A18: 7 | B18: Filipe Pinheiro | C18: 46591 | D18: Belas | E18: 7.2 | F18: 4 | G18: 4 | H18: 3 | I18: 6 | J18: 3 | K18: 5 | L18: 5 | M18: 5 | N18: 6 | O18: 5 | P18: 5 | Q18: 3 | R18: 6 | S18: 5 | T18: 3 | U18: 5 | V18: 4 | W18: 5 | X18: =SUM(F18:W18) | Y18: =Y10 | Z18: =X18-Y18 | AA18: =MAX(0,25-Z18)*1.0 | AB18: 6 | AC18: 3 | AD18: 5 | AE18: 5 | AF18: 3 | AG18: 6 | AH18: 5 | AI18: 6 | AJ18: 4 | AK18: 4 | AL18: 4 | AM18: 4 | AN18: 5 | AO18: 4 | AP18: 3 | AQ18: 5 | AR18: 4 | AS18: 7 | AT18: =SUM(AB18:AS18) | AU18: =AU10 | AV18: =AT18-AU18 | AW18: =MAX(0,25-AV18)*1.0 | AX18: =AA18+AW18
A19: 8 | B19: João Rocha | C19: 48297 | D19: Estoril | E19: 9.8 | F19: 7 | G19: 4 | H19: 5 | I19: 4 | J19: 3 | K19: 6 | L19: 5 | M19: 4 | N19: 5 | O19: 6 | P19: 5 | Q19: 3 | R19: 6 | S19: 4 | T19: 4 | U19: 6 | V19: 4 | W19: 6 | X19: =SUM(F19:W19) | Y19: =Y10 | Z19: =X19-Y19 | AA19: =MAX(0,25-Z19)*1.0 | AB19: 4 | AC19: 5 | AD19: 4 | AE19: 5 | AF19: 3 | AG19: 4 | AH19: 5 | AI19: 6 | AJ19: 5 | AK19: 6 | AL19: 6 | AM19: 3 | AN19: 7 | AO19: 3 | AP19: 4 | AQ19: 4 | AR19: 5 | AS19: 5 | AT19: =SUM(AB19:AS19) | AU19: =AU10 | AV19: =AT19-AU19 | AW19: =MAX(0,25-AV19)*1.0 | AX19: =AA19+AW19
A20: 9 | B20: Clara Trindade | C20: 45812 | D20: Belas | E20: 10.5 | F20: 7 | G20: 4 | H20: 3 | I20: 5 | J20: 3 | K20: 8 | L20: 6 | M20: 5 | N20: 5 | O20: 4 | P20: 5 | Q20: 3 | R20: 6 | S20: 6 | T20: 6 | U20: 5 | V20: 4 | W20: 5 | X20: =SUM(F20:W20) | Y20: =Y10 | Z20: =X20-Y20 | AA20: =MAX(0,25-Z20)*1.0 | AB20: 6 | AC20: 4 | AD20: 3 | AE20: 4 | AF20: 3 | AG20: 5 | AH20: 6 | AI20: 5 | AJ20: 5 | AK20: 5 | AL20: 4 | AM20: 3 | AN20: 8 | AO20: 4 | AP20: 4 | AQ20: 6 | AR20: 5 | AS20: 7 | AT20: =SUM(AB20:AS20) | AU20: =AU10 | AV20: =AT20-AU20 | AW20: =MAX(0,25-AV20)*1.0 | AX20: =AA20+AW20
A21: 10 | B21: Salvador Ivo de Carvalho | C21: 43968 | D21: Vilamoura, C. G | E21: 9.9 | F21: 5 | G21: 4 | H21: 4 | I21: 5 | J21: 3 | K21: 5 | L21: 5 | M21: 6 | N21: 6 | O21: 6 | P21: 5 | Q21: 3 | R21: 6 | S21: 4 | T21: 4 | U21: 6 | V21: 5 | W21: 6 | X21: =SUM(F21:W21) | Y21: =Y10 | Z21: =X21-Y21 | AA21: =MAX(0,25-Z21)*1.0 | AB21: 6 | AC21: 5 | AD21: 2 | AE21: 5 | AF21: 2 | AG21: 5 | AH21: 5 | AI21: 5 | AJ21: 5 | AK21: 7 | AL21: 5 | AM21: 4 | AN21: 5 | AO21: 4 | AP21: 4 | AQ21: 6 | AR21: 5 | AS21: 6 | AT21: =SUM(AB21:AS21) | AU21: =AU10 | AV21: =AT21-AU21 | AW21: =MAX(0,25-AV21)*1.0 | AX21: =AA21+AW21
A22: 11 | B22: Emile Cuanalo | D22: Internacional | E22: 36 | F22: 5 | G22: 4 | H22: 3 | I22: 5 | J22: 4 | K22: 7 | L22: 5 | M22: 6 | N22: 4 | O22: 6 | P22: 5 | Q22: 3 | R22: 6 | S22: 5 | T22: 3 | U22: 5 | V22: 5 | W22: 7 | X22: =SUM(F22:W22) | Y22: =Y10 | Z22: =X22-Y22 | AA22: =MAX(0,25-Z22)*1.0 | AW22: 0 | AX22: =AA22+AW22
A23: 12 | B23: Martim Sousa de Morais | C23: 41609 | D23: Belas | E23: 7.1 | F23: 7 | G23: 5 | H23: 3 | I23: 7 | J23: 4 | K23: 6 | L23: 4 | M23: 6 | N23: 5 | O23: 6 | P23: 4 | Q23: 3 | R23: 6 | S23: 6 | T23: 4 | U23: 5 | V23: 5 | W23: 5 | X23: =SUM(F23:W23) | Y23: =Y10 | Z23: =X23-Y23 | AA23: =MAX(0,25-Z23)*1.0 | AB23: 6 | AC23: 4 | AD23: 5 | AE23: 4 | AF23: 4 | AG23: 5 | AH23: 4 | AI23: 4 | AJ23: 5 | AK23: 4 | AL23: 4 | AM23: 4 | AN23: 5 | AO23: 3 | AP23: 4 | AQ23: 5 | AR23: 4 | AS23: 5 | AT23: =SUM(AB23:AS23) | AU23: =AU10 | AV23: =AT23-AU23 | AW23: =MAX(0,25-AV23)*1.0 | AX23: =AA23+AW23
A24: 13 | B24: Manuel Goulartt Medeiros | C24: 52884 | D24: Santo da Serra | E24: 18.3 | F24: 6 | G24: 7 | H24: 2 | I24: 5 | J24: 4 | K24: 6 | L24: 5 | M24: 6 | N24: 6 | O24: 7 | P24: 5 | Q24: 3 | R24: 7 | S24: 7 | T24: 4 | U24: 5 | V24: 6 | W24: 7 | X24: =SUM(F24:W24) | Y24: =Y10 | Z24: =X24-Y24 | AA24: =MAX(0,25-Z24)*1.0 | AB24: 5 | AC24: 6 | AD24: 4 | AE24: 4 | AF24: 2 | AG24: 4 | AH24: 5 | AI24: 7 | AJ24: 5 | AK24: 6 | AL24: 4 | AM24: 3 | AN24: 6 | AO24: 5 | AP24: 4 | AQ24: 5 | AR24: 5 | AS24: 9 | AT24: =SUM(AB24:AS24) | AU24: =AU10 | AV24: =AT24-AU24 | AW24: =MAX(0,25-AV24)*1.0 | AX24: =AA24+AW24
A25: NS | B25: Henrique Almeida da Silva | D25: Belas | E25: 5.6 | AA25: 0 | AW25: 0 | AX25: =AA25+AW25
A26: NS | B26: Frederico Almeida da Silva | D26: Belas | E26: 8.7 | AA26: 0 | AW26: 0 | AX26: =AA26+AW26

Sheet greatgolf
A1: Greatgolf Junior Open w/ Luis Figo Foundation
A2: Data: | B2: 2025-03-02
A3: Campo: | B3: Vilamoura — Millennium
A4: ccode/tcode: | B4: 935/10260
A5: Link FPG: | B5: https://scoring.datagolf.pt/pt/Classifications.aspx?ccode=935&tcode=10260
A6: Multiplicador: | B6: 1
A9: Pos | B9: Nome | C9: FedCode | D9: Clube | E9: HCP | F9: R1 h1 | G9: h2 | H9: h3 | I9: h4 | J9: h5 | K9: h6 | L9: h7 | M9: h8 | N9: h9 | O9: h10 | P9: h11 | Q9: h12 | R9: h13 | S9: h14 | T9: h15 | U9: h16 | V9: h17 | W9: h18 | X9: R1 Gross | Y9: R1 Par | Z9: R1 ToPar | AA9: R1 Pts | AB9: R2 h1 | AC9: h2 | AD9: h3 | AE9: h4 | AF9: h5 | AG9: h6 | AH9: h7 | AI9: h8 | AJ9: h9 | AK9: h10 | AL9: h11 | AM9: h12 | AN9: h13 | AO9: h14 | AP9: h15 | AQ9: h16 | AR9: h17 | AS9: h18 | AT9: R2 Gross | AU9: R2 Par | AV9: R2 ToPar | AW9: R2 Pts | AX9: Total Pts
A10: —Par— | F10: 4 | G10: 4 | H10: 3 | I10: 5 | J10: 4 | K10: 3 | L10: 4 | M10: 5 | N10: 4 | O10: 4 | P10: 5 | Q10: 4 | R10: 3 | S10: 4 | T10: 3 | U10: 4 | V10: 4 | W10: 5 | Y10: =SUM(F10:W10) | AB10: 4 | AC10: 4 | AD10: 3 | AE10: 5 | AF10: 4 | AG10: 3 | AH10: 4 | AI10: 5 | AJ10: 4 | AK10: 4 | AL10: 5 | AM10: 4 | AN10: 3 | AO10: 4 | AP10: 3 | AQ10: 4 | AR10: 4 | AS10: 5 | AU10: =SUM(AB10:AS10)
A11: —SI— | F11: 9 | G11: 7 | H11: 11 | I11: 3 | J11: 1 | K11: 13 | L11: 5 | M11: 17 | N11: 15 | O11: 8 | P11: 12 | Q11: 16 | R11: 14 | S11: 6 | T11: 18 | U11: 2 | V11: 10 | W11: 4 | AB11: 9 | AC11: 7 | AD11: 11 | AE11: 3 | AF11: 1 | AG11: 13 | AH11: 5 | AI11: 17 | AJ11: 15 | AK11: 8 | AL11: 12 | AM11: 16 | AN11: 14 | AO11: 6 | AP11: 18 | AQ11: 2 | AR11: 10 | AS11: 4
A12: 1 | B12: Martim Pinto Johansen | C12: 40115 | D12: Vilamoura, C. G | E12: -1.5 | F12: 4 | G12: 4 | H12: 4 | I12: 5 | J12: 4 | K12: 3 | L12: 4 | M12: 4 | N12: 4 | O12: 4 | P12: 4 | Q12: 4 | R12: 3 | S12: 4 | T12: 3 | U12: 4 | V12: 4 | W12: 5 | X12: =SUM(F12:W12) | Y12: =Y10 | Z12: =X12-Y12 | AA12: =MAX(0,25-Z12)*1.0 | AB12: 3 | AC12: 4 | AD12: 3 | AE12: 5 | AF12: 4 | AG12: 3 | AH12: 5 | AI12: 5 | AJ12: 3 | AK12: 4 | AL12: 4 | AM12: 4 | AN12: 3 | AO12: 3 | AP12: 3 | AQ12: 4 | AR12: 3 | AS12: 4 | AT12: =SUM(AB12:AS12) | AU12: =AU10 | AV12: =AT12-AU12 | AW12: =MAX(0,25-AV12)*1.0 | AX12: =AA12+AW12
A13: 2 | B13: Pedro Costa Alemão | C13: 46706 | D13: Estoril | E13: 7.2 | F13: 4 | G13: 5 | H13: 4 | I13: 5 | J13: 4 | K13: 3 | L13: 5 | M13: 5 | N13: 4 | O13: 4 | P13: 5 | Q13: 5 | R13: 3 | S13: 4 | T13: 2 | U13: 5 | V13: 4 | W13: 5 | X13: =SUM(F13:W13) | Y13: =Y10 | Z13: =X13-Y13 | AA13: =MAX(0,25-Z13)*1.0 | AB13: 5 | AC13: 5 | AD13: 6 | AE13: 5 | AF13: 5 | AG13: 3 | AH13: 6 | AI13: 6 | AJ13: 4 | AK13: 4 | AL13: 5 | AM13: 4 | AN13: 4 | AO13: 4 | AP13: 3 | AQ13: 4 | AR13: 5 | AS13: 5 | AT13: =SUM(AB13:AS13) | AU13: =AU10 | AV13: =AT13-AU13 | AW13: =MAX(0,25-AV13)*1.0 | AX13: =AA13+AW13
A14: 3 | B14: Ethan Prybys Orton | C14: 42374 | D14: Vila Sol | E14: 6.9 | F14: 5 | G14: 5 | H14: 3 | I14: 4 | J14: 4 | K14: 3 | L14: 4 | M14: 5 | N14: 5 | O14: 4 | P14: 5 | Q14: 4 | R14: 3 | S14: 6 | T14: 3 | U14: 4 | V14: 4 | W14: 5 | X14: =SUM(F14:W14) | Y14: =Y10 | Z14: =X14-Y14 | AA14: =MAX(0,25-Z14)*1.0 | AB14: 4 | AC14: 4 | AD14: 4 | AE14: 5 | AF14: 5 | AG14: 4 | AH14: 5 | AI14: 5 | AJ14: 5 | AK14: 5 | AL14: 4 | AM14: 4 | AN14: 4 | AO14: 4 | AP14: 3 | AQ14: 4 | AR14: 4 | AS14: 6 | AT14: =SUM(AB14:AS14) | AU14: =AU10 | AV14: =AT14-AU14 | AW14: =MAX(0,25-AV14)*1.0 | AX14: =AA14+AW14
A15: 4 | B15: Santiago Dias | C15: 42908 | D15: Miramar | E15: 2.7 | F15: 4 | G15: 4 | H15: 3 | I15: 5 | J15: 4 | K15: 4 | L15: 5 | M15: 5 | N15: 4 | O15: 4 | P15: 5 | Q15: 4 | R15: 3 | S15: 4 | T15: 4 | U15: 4 | V15: 4 | W15: 6 | X15: =SUM(F15:W15) | Y15: =Y10 | Z15: =X15-Y15 | AA15: =MAX(0,25-Z15)*1.0 | AB15: 4 | AC15: 5 | AD15: 4 | AE15: 5 | AF15: 8 | AG15: 3 | AH15: 5 | AI15: 5 | AJ15: 3 | AK15: 4 | AL15: 5 | AM15: 4 | AN15: 4 | AO15: 5 | AP15: 4 | AQ15: 4 | AR15: 5 | AS15: 7 | AT15: =SUM(AB15:AS15) | AU15: =AU10 | AV15: =AT15-AU15 | AW15: =MAX(0,25-AV15)*1.0 | AX15: =AA15+AW15
A16: 5 | B16: Filipe Pinheiro | C16: 46591 | D16: Belas | E16: 7.2 | F16: 4 | G16: 5 | H16: 3 | I16: 5 | J16: 4 | K16: 4 | L16: 5 | M16: 6 | N16: 5 | O16: 4 | P16: 5 | Q16: 3 | R16: 4 | S16: 4 | T16: 3 | U16: 4 | V16: 4 | W16: 5 | X16: =SUM(F16:W16) | Y16: =Y10 | Z16: =X16-Y16 | AA16: =MAX(0,25-Z16)*1.0 | AB16: 4 | AC16: 5 | AD16: 3 | AE16: 6 | AF16: 5 | AG16: 4 | AH16: 6 | AI16: 5 | AJ16: 4 | AK16: 4 | AL16: 6 | AM16: 5 | AN16: 3 | AO16: 4 | AP16: 3 | AQ16: 4 | AR16: 4 | AS16: 5 | AT16: =SUM(AB16:AS16) | AU16: =AU10 | AV16: =AT16-AU16 | AW16: =MAX(0,25-AV16)*1.0 | AX16: =AA16+AW16
A17: 6 | B17: João Setúbal | C17: 43732 | D17: Vilamoura, C. G | E17: 4.3 | F17: 4 | G17: 4 | H17: 5 | I17: 5 | J17: 5 | K17: 3 | L17: 4 | M17: 4 | N17: 5 | O17: 3 | P17: 4 | Q17: 5 | R17: 4 | S17: 4 | T17: 4 | U17: 5 | V17: 4 | W17: 5 | X17: =SUM(F17:W17) | Y17: =Y10 | Z17: =X17-Y17 | AA17: =MAX(0,25-Z17)*1.0 | AB17: 5 | AC17: 5 | AD17: 3 | AE17: 6 | AF17: 5 | AG17: 3 | AH17: 7 | AI17: 6 | AJ17: 4 | AK17: 4 | AL17: 6 | AM17: 4 | AN17: 3 | AO17: 4 | AP17: 3 | AQ17: 5 | AR17: 4 | AS17: 5 | AT17: =SUM(AB17:AS17) | AU17: =AU10 | AV17: =AT17-AU17 | AW17: =MAX(0,25-AV17)*1.0 | AX17: =AA17+AW17
A18: 7 | B18: Rodrigo Marques Santos | C18: 37152 | D18: Aroeira | E18: 0.4 | F18: 4 | G18: 5 | H18: 4 | I18: 6 | J18: 5 | K18: 4 | L18: 4 | M18: 4 | N18: 4 | O18: 4 | P18: 5 | Q18: 4 | R18: 4 | S18: 4 | T18: 4 | U18: 4 | V18: 2 | W18: 7 | X18: =SUM(F18:W18) | Y18: =Y10 | Z18: =X18-Y18 | AA18: =MAX(0,25-Z18)*1.0 | AB18: 5 | AC18: 4 | AD18: 3 | AE18: 5 | AF18: 4 | AG18: 3 | AH18: 5 | AI18: 4 | AJ18: 4 | AK18: 4 | AL18: 5 | AM18: 4 | AN18: 3 | AO18: 4 | AP18: 3 | AQ18: 4 | AR18: 3 | AS18: 6 | AT18: =SUM(AB18:AS18) | AU18: =AU10 | AV18: =AT18-AU18 | AW18: =MAX(0,25-AV18)*1.0 | AX18: =AA18+AW18
A19: 8 | B19: João Crasi Alves | C19: 39701 | D19: Vilamoura, C. G | E19: -1 | F19: 4 | G19: 3 | H19: 5 | I19: 4 | J19: 4 | K19: 4 | L19: 4 | M19: 4 | N19: 6 | O19: 6 | P19: 4 | Q19: 4 | R19: 3 | S19: 4 | T19: 3 | U19: 5 | V19: 4 | W19: 7 | X19: =SUM(F19:W19) | Y19: =Y10 | Z19: =X19-Y19 | AA19: =MAX(0,25-Z19)*1.0 | AB19: 5 | AC19: 5 | AD19: 3 | AE19: 5 | AF19: 5 | AG19: 3 | AH19: 5 | AI19: 4 | AJ19: 3 | AK19: 5 | AL19: 4 | AM19: 5 | AN19: 3 | AO19: 4 | AP19: 3 | AQ19: 4 | AR19: 4 | AS19: 4 | AT19: =SUM(AB19:AS19) | AU19: =AU10 | AV19: =AT19-AU19 | AW19: =MAX(0,25-AV19)*1.0 | AX19: =AA19+AW19
A20: 9 | B20: Amélia Gabin | C20: 38233 | D20: Assoc. Qta.Lago | E20: -2 | F20: 4 | G20: 4 | H20: 3 | I20: 5 | J20: 5 | K20: 3 | L20: 5 | M20: 4 | N20: 4 | O20: 4 | P20: 6 | Q20: 4 | R20: 4 | S20: 5 | T20: 3 | U20: 4 | V20: 5 | W20: 7 | X20: =SUM(F20:W20) | Y20: =Y10 | Z20: =X20-Y20 | AA20: =MAX(0,25-Z20)*1.0 | AB20: 4 | AC20: 4 | AD20: 3 | AE20: 5 | AF20: 6 | AG20: 3 | AH20: 5 | AI20: 5 | AJ20: 5 | AK20: 3 | AL20: 5 | AM20: 4 | AN20: 4 | AO20: 4 | AP20: 3 | AQ20: 5 | AR20: 4 | AS20: 5 | AT20: =SUM(AB20:AS20) | AU20: =AU10 | AV20: =AT20-AU20 | AW20: =MAX(0,25-AV20)*1.0 | AX20: =AA20+AW20
A21: 10 | B21: Tiago Abrantes | C21: 38315 | D21: Vilamoura, C. G | E21: 2.9 | F21: 5 | G21: 5 | H21: 4 | I21: 4 | J21: 4 | K21: 4 | L21: 4 | M21: 5 | N21: 4 | O21: 4 | P21: 7 | Q21: 5 | R21: 4 | S21: 6 | T21: 2 | U21: 4 | V21: 3 | W21: 6 | X21: =SUM(F21:W21) | Y21: =Y10 | Z21: =X21-Y21 | AA21: =MAX(0,25-Z21)*1.0 | AB21: 4 | AC21: 5 | AD21: 4 | AE21: 4 | AF21: 3 | AG21: 5 | AH21: 5 | AI21: 5 | AJ21: 5 | AK21: 4 | AL21: 7 | AM21: 5 | AN21: 4 | AO21: 4 | AP21: 3 | AQ21: 4 | AR21: 5 | AS21: 7 | AT21: =SUM(AB21:AS21) | AU21: =AU10 | AV21: =AT21-AU21 | AW21: =MAX(0,25-AV21)*1.0 | AX21: =AA21+AW21
A22: 11 | B22: Ricardo Castro Ferreira | C22: 49085 | D22: Estoril | E22: 11.6 | F22: 4 | G22: 5 | H22: 5 | I22: 5 | J22: 6 | K22: 3 | L22: 5 | M22: 6 | N22: 4 | O22: 5 | P22: 5 | Q22: 4 | R22: 2 | S22: 5 | T22: 4 | U22: 4 | V22: 4 | W22: 5 | X22: =SUM(F22:W22) | Y22: =Y10 | Z22: =X22-Y22 | AA22: =MAX(0,25-Z22)*1.0 | AB22: 4 | AC22: 6 | AD22: 3 | AE22: 7 | AF22: 5 | AG22: 3 | AH22: 4 | AI22: 5 | AJ22: 4 | AK22: 4 | AL22: 6 | AM22: 5 | AN22: 4 | AO22: 4 | AP22: 2 | AQ22: 5 | AR22: 4 | AS22: 5 | AT22: =SUM(AB22:AS22) | AU22: =AU10 | AV22: =AT22-AU22 | AW22: =MAX(0,25-AV22)*1.0 | AX22: =AA22+AW22
A23: 12 | B23: Rafaela Pinto | C23: 40390 | D23: Arquitectos | E23: 1 | F23: 4 | G23: 7 | H23: 3 | I23: 6 | J23: 5 | K23: 3 | L23: 5 | M23: 5 | N23: 4 | O23: 4 | P23: 7 | Q23: 4 | R23: 3 | S23: 4 | T23: 4 | U23: 4 | V23: 4 | W23: 5 | X23: =SUM(F23:W23) | Y23: =Y10 | Z23: =X23-Y23 | AA23: =MAX(0,25-Z23)*1.0 | AB23: 4 | AC23: 5 | AD23: 3 | AE23: 5 | AF23: 4 | AG23: 4 | AH23: 5 | AI23: 5 | AJ23: 5 | AK23: 5 | AL23: 7 | AM23: 4 | AN23: 4 | AO23: 5 | AP23: 2 | AQ23: 3 | AR23: 4 | AS23: 5 | AT23: =SUM(AB23:AS23) | AU23: =AU10 | AV23: =AT23-AU23 | AW23: =MAX(0,25-AV23)*1.0 | AX23: =AA23+AW23
